Workbook

Sheet Summary
A1: NET CASH FLOW -MEGP-ACCUMULATED
A2: Project | B2: Downpayment | C2: Total Without Downpayment | D2: Total With Downpayment | E2: Diff | F2: Diff %
A3: Green Square | B3: 200 | C3: ='Net Cash Flow -Without DP'!C52 -> 375.44753 | D3: ='Net Cash Flow -With DP'!C52 -> 375.44753 | E3: =D3-C3 -> 0 | F3: =E3/C3 -> 0 | G3: =SUM('Offers DP'!C9:C16) -> 800 | H3: =G3-800 -> 0 | I3: =H3/6 -> 0
A4: L'avenir | B4: 200 | C4: ='Net Cash Flow -Without DP'!C53 -> 595.29293 | D4: ='Net Cash Flow -With DP'!C53 -> 595.29293 | E4: =D4-C4 -> 0 | F4: =E4/C4 -> 0 | G4: =SUM('Offers DP'!D9:D16) -> 850 | H4: =G4-850 -> 0 | I4: =H4/6 -> 0
A5: NPV Total CASH-IN FLOW JALOUR | C5: =SUM(C3:C4) -> 970.74046 | D5: =SUM(D3:D4) -> 970.74046 | E5: =SUM(E3:E4) -> 0 | F5: =E5/C5 -> 0
A7: NPV NET CASH FLOW -MEGP-ACCUMULATED
A8: Project | B8: Downpayment | C8: Total Without Downpayment | D8: Total With Downpayment | E8: Diff | F8: Diff %
A9: Green Square | B9: =B3 -> 200 | C9: ='Net Cash Flow -Without DP'!C58 -> 241.24144 | D9: ='Net Cash Flow -With DP'!C58 -> 215.31139 | E9: =D9-C9 -> -25.930043 | F9: =E9/C9 -> -0.10748586
A10: L'avenir | B10: =B4 -> 200 | C10: ='Net Cash Flow -Without DP'!C59 -> 328.55309 | D10: ='Net Cash Flow -With DP'!C59 -> 307.53237 | E10: =D10-C10 -> -21.020716 | F10: =E10/C10 -> -0.063979665
A11: NPV Total CASH-IN FLOW JALOUR | C11: =SUM(C9:C10) -> 569.79452 | D11: =SUM(D9:D10) -> 522.84376 | E11: =SUM(E9:E10) -> -46.950759 | F11: =E11/C11 -> -0.082399457

Sheet Green Square Summary
A1: Green Square EL-Mostakbal City -Summary
A2: Land Area: | B2: m² | C2: 14470 | D2: Construction Start: | E2: 13 | F2: Month
A3: footprint % : | C3: =C4/C2 -> 0.3 | D3: Construction Duration : | E3: 36 | F3: Month
A4: footprint : | B4: m² | C4: 4341 | D4: Project Delivery : | E4: =E3+E2-1 -> 48 | F4: Month
A5: Height: | C5: G+2
A6: Retail: | B6: m² | C6: 4341 | D6: Sales Start: | E6: 7 | F6: Month
A7: Offices: | B7: m² | C7: 8682 | D7: Maximum Cash Shortage : | E7: =MIN(C49:AT49) -> -102.5 | F7: MEGP
A8: Total BUA: | B8: m² | C8: 13023
A9: RETAINED %: | C9: 0.2
A10: Downpayment | C10: =Summary!B3 -> 200
C11: MEGP | D11: NPV-With DP | E11: NPV-With DP
A12: CASH INFLOW JALOUR | C12: =SUM(C13:C14) -> 1267.3007 | D12: ='Net Cash Flow -With DP'!C22 -> 807.95087 | E12: ='Net Cash Flow -Without DP'!C22 -> 833.88091
A13: COMMERCIAL | C13: =C32-C36 -> 523.76878
A14: ADMIN | C14: =C33-C37 -> 743.53191
C16: MEGP | D16: NPV-With DP | E16: NPV-With DP
A17: CASH OUTFLOW JALOUR | C17: =SUM(C18:C20) -> -891.85316 | D17: =-'Net Cash Flow -With DP'!C34 -> -592.63947 | E17: =-'Net Cash Flow -Without DP'!C34 -> -592.63947
A18: Construction Cost | C18: =-'Cash Out Detail'!C28/1000000 -> -697.16
A19: Sales Commission | B19: 0.04 | C19: =-'Cash Out Detail'!C33/1000000 -> -90.11916
A20: SGA& Others Cost | B20: 0.15 | C20: =-'Cash Out Detail'!C38/1000000 -> -104.574
C22: MEGP | D22: NPV-With DP | E22: NPV-Without DP | F22: Diff
A23: NET CASH FLOW JALOUR -MEGP | C23: =C12+C17 -> 375.44753 | D23: =Summary!D9 -> 215.31139 | E23: =Summary!C9 -> 241.24144 | F23: =D23-E23 -> -25.930043
A27: Total Sales 100% | C27: =SUM(C28:C29) -> 2816.2238
A28: COMMERCIAL | C28: =C32*100/80 -> 1163.9306
A29: ADMIN | C29: =C33*100/80 -> 1652.2931
A31: Total Sales 80% | C31: =SUM(C32:C33) -> 2252.979
A32: COMMERCIAL | C32: ='Green Square'!D24/1000 -> 931.1445
A33: ADMIN | C33: ='Green Square'!D25/1000 -> 1321.8345
A35: ALAHLY - SABBOUR % | B35: 0.35 | C35: =SUM(C36:C37) -> 985.67831
A36: COMMERCIAL | C36: =C28*B35 -> 407.37572
A37: ADMIN | C37: =C29*B35 -> 578.30259
C44: ='Net Cash Flow -With DP'!D3 -> M 3 | D44: ='Net Cash Flow -With DP'!E3 -> M 6 | E44: ='Net Cash Flow -With DP'!F3 -> M 9 | F44: ='Net Cash Flow -With DP'!G3 -> M 12 | G44: ='Net Cash Flow -With DP'!H3 -> M 15 | H44: ='Net Cash Flow -With DP'!I3 -> M 18 | I44: ='Net Cash Flow -With DP'!J3 -> M 21 | J44: ='Net Cash Flow -With DP'!K3 -> M 24 | ... AT44: ='Net Cash Flow -With DP'!AU3 -> 0
A45: Total Collections MEGP | C45: ='Net Cash Flow -With DP'!D4 -> 0 | D45: ='Net Cash Flow -With DP'!E4 -> 0 | E45: ='Net Cash Flow -With DP'!F4 -> 15.139238 | F45: ='Net Cash Flow -With DP'!G4 -> 30.278475 | G45: ='Net Cash Flow -With DP'!H4 -> 46.512006 | H45: ='Net Cash Flow -With DP'!I4 -> 62.745537 | I45: ='Net Cash Flow -With DP'!J4 -> 62.3657 | J45: ='Net Cash Flow -With DP'!K4 -> 63.473559 | ... AT45: ='Net Cash Flow -With DP'!AU4 -> 0
A46: ALAHLY - SABBOUR Payments MEGP | C46: =-'Net Cash Flow -With DP'!D10 -> -91.25 | D46: =-'Net Cash Flow -With DP'!E10 -> -11.25 | E46: =-'Net Cash Flow -With DP'!F10 -> -11.25 | F46: =-'Net Cash Flow -With DP'!G10 -> -11.25 | G46: =-'Net Cash Flow -With DP'!H10 -> -22.5 | H46: =-'Net Cash Flow -With DP'!I10 -> -22.5 | I46: =-'Net Cash Flow -With DP'!J10 -> -22.5 | J46: =-'Net Cash Flow -With DP'!K10 -> -22.5 | ... AT46: =-'Net Cash Flow -With DP'!AU10 -> 0
A47: CASH OUT FLOW CAPEX -MEGP | C47: =-'Net Cash Flow -With DP'!D28 -> 0 | D47: =-'Net Cash Flow -With DP'!E28 -> 0 | E47: =-'Net Cash Flow -With DP'!F28 -> 0 | F47: =-'Net Cash Flow -With DP'!G28 -> 0 | G47: =-'Net Cash Flow -With DP'!H28 -> -23 | H47: =-'Net Cash Flow -With DP'!I28 -> -30.36 | I47: =-'Net Cash Flow -With DP'!J28 -> -58.11139 | J47: =-'Net Cash Flow -With DP'!K28 -> -42.47139 | ... AT47: =-'Net Cash Flow -With DP'!AU28 -> 0
A48: Net Cash Flow | C48: =SUM(C45:C47) -> -91.25 | D48: =SUM(D45:D47) -> -11.25 | E48: =SUM(E45:E47) -> 3.8892375 | F48: =SUM(F45:F47) -> 19.028475 | G48: =SUM(G45:G47) -> 1.0120062 | H48: =SUM(H45:H47) -> 9.8855375 | I48: =SUM(I45:I47) -> -18.24569 | J48: =SUM(J45:J47) -> -1.4978306 | ... AT48: =SUM(AT45:AT47) -> 0
A49: Net Cash Flow-Accum | C49: =C48 -> -91.25 | D49: =C49+D48 -> -102.5 | E49: =D49+E48 -> -98.610763 | F49: =E49+F48 -> -79.582288 | G49: =F49+G48 -> -78.570281 | H49: =G49+H48 -> -68.684744 | I49: =H49+I48 -> -86.930434 | J49: =I49+J48 -> -88.428264 | K49: =J49+K48 -> -81.730676 | ... AT49: =AS49+AT48 -> 375.44753

Sheet L'avenir Summary
A1: L'avenir EL-Mostakbal City -Summary
A2: Land Area: | B2: m² | C2: 14910 | D2: Construction Start: | E2: 19 | F2: Month
A3: footprint % : | C3: =C4/C2 -> 0.3 | D3: Construction Duration : | E3: 36 | F3: Month
A4: footprint : | B4: m² | C4: 4473 | D4: Project Delivery : | E4: =E3+E2-1 -> 54 | F4: Month
A5: Height: | C5: G+2
A6: Retail: | B6: m² | C6: =C4 -> 4473 | D6: Sales Start: | E6: 13 | F6: Month
A7: Offices: | B7: m² | C7: 8946 | D7: Maximum Cash Shortage : | E7: =MIN(C49:AT49) -> -102.01806 | F7: MEGP
A8: Total BUA: | B8: m² | C8: =C7+C6 -> 13419
A9: RETAINED %: | C9: 0.2
A10: Downpayment | C10: =Summary!B4 -> 200
C11: MEGP | D11: NPV-With DP | E11: NPV-With DP
A12: CASH INFLOW JALOUR | C12: =SUM(C13:C14) -> 1503.9764 | D12: ='Net Cash Flow -With DP'!C23 -> 872.63711 | E12: ='Net Cash Flow -Without DP'!C23 -> 893.65783
A13: COMMERCIAL | C13: =C32-C36 -> 605.74205
A14: ADMIN | C14: =C33-C37 -> 898.23431
C16: MEGP | D16: NPV-With DP | E16: NPV-With DP
A17: CASH OUTFLOW JALOUR | C17: =SUM(C18:C20) -> -862.28343 | D17: =-'Net Cash Flow -With DP'!C35 -> -565.10474 | E17: =-'Net Cash Flow -Without DP'!C35 -> -565.10474
A18: Construction Cost | C18: =-'Cash Out Detail'!C29/1000000 -> -650.76
A19: Sales Commission | B19: 0.04 | C19: =-'Cash Out Detail'!C34/1000000 -> -106.94943
A20: SGA& Others Cost | B20: 0.15 | C20: =-'Cash Out Detail'!C39/1000000 -> -104.574
C22: MEGP | D22: NPV-With DP | E22: NPV-Without DP | F22: Diff
A23: NET CASH FLOW JALOUR -MEGP | C23: =C12+C17 -> 641.69293 | D23: =Summary!D10 -> 307.53237 | E23: =Summary!C10 -> 328.55309 | F23: =D23-E23 -> -21.020716
A27: Total Sales 100% | C27: =SUM(C28:C29) -> 3342.1697
A28: COMMERCIAL | C28: =C32*100/80 -> 1346.0934
A29: ADMIN | C29: =C33*100/80 -> 1996.0763
A31: Total Sales 80% | C31: =SUM(C32:C33) -> 2673.7357
A32: COMMERCIAL | C32: ='L''avenir'!D24/1000 -> 1076.8747
A33: ADMIN | C33: ='L''avenir'!D25/1000 -> 1596.861
A35: ALAHLY - SABBOUR % | B35: 0.35 | C35: =SUM(C36:C37) -> 1169.7594
A36: COMMERCIAL | C36: =C28*B35 -> 471.1327
A37: ADMIN | C37: =C29*B35 -> 698.62669
C44: ='Net Cash Flow -With DP'!D3 -> M 3 | D44: ='Net Cash Flow -With DP'!E3 -> M 6 | E44: ='Net Cash Flow -With DP'!F3 -> M 9 | F44: ='Net Cash Flow -With DP'!G3 -> M 12 | G44: ='Net Cash Flow -With DP'!H3 -> M 15 | H44: ='Net Cash Flow -With DP'!I3 -> M 18 | I44: ='Net Cash Flow -With DP'!J3 -> M 21 | J44: ='Net Cash Flow -With DP'!K3 -> M 24 | ... AT44: ='Net Cash Flow -With DP'!AU3 -> 0
A45: Total Collections MEGP | C45: ='Net Cash Flow -With DP'!D5 -> 0 | D45: ='Net Cash Flow -With DP'!E5 -> 0 | E45: ='Net Cash Flow -With DP'!F5 -> 0 | F45: ='Net Cash Flow -With DP'!G5 -> 0 | G45: ='Net Cash Flow -With DP'!H5 -> 18.11565 | H45: ='Net Cash Flow -With DP'!I5 -> 36.2313 | I45: ='Net Cash Flow -With DP'!J5 -> 58.260825 | J45: ='Net Cash Flow -With DP'!K5 -> 69.01839 | ... AT45: ='Net Cash Flow -With DP'!AU5 -> 0
A46: ALAHLY - SABBOUR Payments MEGP | C46: =-'Net Cash Flow -With DP'!D11 -> 0 | D46: =-'Net Cash Flow -With DP'!E11 -> 0 | E46: =-'Net Cash Flow -With DP'!F11 -> 0 | F46: =-'Net Cash Flow -With DP'!G11 -> -85 | G46: =-'Net Cash Flow -With DP'!H11 -> -22.5 | H46: =-'Net Cash Flow -With DP'!I11 -> -22.5 | I46: =-'Net Cash Flow -With DP'!J11 -> -22.5 | J46: =-'Net Cash Flow -With DP'!K11 -> -22.5 | ... AT46: =-'Net Cash Flow -With DP'!AU11 -> 0
A47: CASH OUT FLOW CAPEX -MEGP | C47: =-'Net Cash Flow -With DP'!D29 -> 0 | D47: =-'Net Cash Flow -With DP'!E29 -> 0 | E47: =-'Net Cash Flow -With DP'!F29 -> 0 | F47: =-'Net Cash Flow -With DP'!G29 -> 0 | G47: =-'Net Cash Flow -With DP'!H29 -> 0 | H47: =-'Net Cash Flow -With DP'!I29 -> 0 | I47: =-'Net Cash Flow -With DP'!J29 -> -23 | J47: =-'Net Cash Flow -With DP'!K29 -> -30.36 | ... AT47: =-'Net Cash Flow -With DP'!AU29 -> 0
A48: Net Cash Flow | C48: =SUM(C45:C47) -> 0 | D48: =SUM(D45:D47) -> 0 | E48: =SUM(E45:E47) -> 0 | F48: =SUM(F45:F47) -> -85 | G48: =SUM(G45:G47) -> -4.38435 | H48: =SUM(H45:H47) -> 13.7313 | I48: =SUM(I45:I47) -> 12.760825 | J48: =SUM(J45:J47) -> 16.15839 | ... AT48: =SUM(AT45:AT47) -> 0
A49: Net Cash Flow-Accum | C49: =C48 -> 0 | D49: =C49+D48 -> 0 | E49: =D49+E48 -> 0 | F49: =E49+F48 -> -85 | G49: =F49+G48 -> -89.38435 | H49: =G49+H48 -> -75.65305 | I49: =H49+I48 -> -62.892225 | J49: =I49+J48 -> -46.733835 | K49: =J49+K48 -> -85.13881 | ... AT49: =AS49+AT48 -> 595.29293

Sheet Offers
C2: GREEN SQUARE | D2: L'AVENIR | E2: NOTES
B3: LANDLORD % | C3: 0.35 | D3: 0.35
B4: MIN. GUARANTEED | C4: 800 M | D4: 850 M
B5: PAYMENT PERIOD | C5: 6 | D5: 6
B6: YEAR 1 (M) | C6: 50 | D6: 0 | E6: OR 35% OF COLLECTIONS WHICHEVER HIGHER
B7: YEAR 2 (M) | C7: 100 | D7: 100 | E7: OR 35% OF COLLECTIONS WHICHEVER HIGHER
B8: YEAR 3 (M) | C8: 150 | D8: 200 | E8: OR 35% OF COLLECTIONS WHICHEVER HIGHER
B9: YEAR 4 (M) | C9: 200 | D9: 250 | E9: OR 35% OF COLLECTIONS WHICHEVER HIGHER
B10: YEAR 5 (M) | C10: 200 | D10: 200 | E10: OR 35% OF COLLECTIONS WHICHEVER HIGHER
B11: YEAR 6 (M) | C11: 100 | D11: 100 | E11: OR 35% OF COLLECTIONS WHICHEVER HIGHER
B12: YEAR 7 (M) | C12: 0 | D12: 0 | E12: OR 35% OF COLLECTIONS WHICHEVER HIGHER
B13: EXCESS AMOUNT (YRS) | C13: 8 | D13: 8
B14: PROJECT DELIVERY | C14: 48 MONTHS | D14: 54 MONTHS
B16: DEVELOPER % | C16: 0.65 | D16: 0.65
B17: DESIGN | C17: ☑ | D17: ☑
B18: PERMITS | C18: ☑ | D18: ☑
B19: CONSTRUCTION | C19: ☑ | D19: ☑
B20: FINISHING | C20: CORE & SHELL | D20: CORE & SHELL
B21: MARKETING | C21: ☑ | D21: ☑
B22: SALES | C22: ☑ | D22: ☑
B23: COLLECTION | C23: ☑ | D23: ☑
B24: PROJECT NAME | C24: UNDER: JALOUR | D24: UNDER: JALOUR
B25: OPERATION, MANAGEMENT, MAINT. | C25: UNDER: JALOUR | D25: UNDER: JALOUR | E25: OR FACILITY MANAGEMENT COMPANY ASSIGNED BY JALOUR

Sheet Offers DP
B1: NPV Diff with vs without downpayments | C1: =Summary!E9 -> -25.930043 | D1: =Summary!E10 -> -21.020716
B2: NPV with DP | C2: =Summary!D9 -> 215.31139 | D2: =Summary!D10 -> 307.53237
C3: =SUM(C9:C16) -> 800 | D3: =SUM(D9:D16) -> 850 | F3: =C3-800 -> 0 | G3: =D3-850 -> 0
B4: MEGP | C4: GREEN SQUARE | D4: L'AVENIR | E4: NOTES | F4: =F3/6 -> 0 | G4: =G3/6 -> 0
B5: Landlord Share of Collections | C5: 0.35 | D5: 0.35
B6: Minimum Guaranteed Amount | C6: 800 | D6: 850
B7: Payment Period | C7: 6 | D7: 6
B8: Downpayment % | C8: 0.1 | D8: 0.1
B9: Downpayment Amount (m) | C9: =C8*C6 -> 80 | D9: =D8*D6 -> 85
B10: Year 1 (m) | C10: 45 | D10: 0 | E10: OR 35% OF COLLECTIONS WHICHEVER HIGHER
B11: Year 2 (m) | C11: 90 | D11: 90 | E11: OR 35% OF COLLECTIONS WHICHEVER HIGHER
B12: Year 3 (m) | C12: 135 | D12: 180 | E12: OR 35% OF COLLECTIONS WHICHEVER HIGHER
B13: Year 4 (m) | C13: 180 | D13: 225 | E13: OR 35% OF COLLECTIONS WHICHEVER HIGHER
B14: Year 5 (m) | C14: 180 | D14: 180 | E14: OR 35% OF COLLECTIONS WHICHEVER HIGHER
B15: Year 6 (m) | C15: 90 | D15: 90 | E15: OR 35% OF COLLECTIONS WHICHEVER HIGHER
B16: Year 7 (m) | C16: 0 | D16: 0 | E16: OR 35% OF COLLECTIONS WHICHEVER HIGHER
B17: Settlement of excess over guarantee | C17: 8 | D17: 8
B18: PROJECT DELIVERY | C18: 48 MONTHS | D18: 54 MONTHS
C20: GREEN SQUARE | D20: L'AVENIR
B21: Developer Share of Collections | C21: 0.65 | D21: 0.65
B22: Design | C22: Jalour | D22: Jalour
B23: Permits & License | C23: Jalour | D23: Jalour
B24: Construction | C24: Jalour | D24: Jalour
B25: Finishing Standard | C25: CORE & SHELL | D25: CORE & SHELL
B26: Marketing, Sales and Collections | C26: Jalour | D26: Jalour
B27: Project Branding | C27: Jalour | D27: Jalour
B28: Operation, Management& Maintenance | C28: Jalour /FM co. | D28: Jalour /FM co.
B29: Project Delivery | C29: 48 MONTHS | D29: 54 MONTHS | E29: OR FACILITY MANAGEMENT COMPANY ASSIGNED BY JALOUR

Sheet Sheet2

Sheet Net Cash Flow -With DP
B1: Cash Available for Operation after - 20% RETAINED UNITS
B2: Total Collections MEGP
B3: Project | C3: Total Sales | D3: M 3 | E3: M 6 | F3: M 9 | G3: M 12 | H3: M 15 | I3: M 18 | J3: M 21 | K3: M 24 | L3: M 27 | M3: M 30 | N3: M 33 | O3: M 36 | P3: M 39 | Q3: M 42 | R3: M 45 | S3: M 48 | T3: M 51 | U3: M 54 | V3: M 57 | W3: M 60 | X3: M 63 | Y3: M 66 | Z3: M 69 | AA3: M 72 | AB3: M 75 | AC3: M 78 | AD3: M 81 | AE3: M 84 | AF3: M 87 | AG3: M 90 | AH3: M 93 | AI3: M 96 | AJ3: M 99 | AK3: M 102 | AL3: M 105 | AM3: M 108 | AN3: M 111 | AO3: M 114 | AP3: M 117 | AQ3: M 120 | AR3: M 123 | AS3: M 126 | AT3: M 129
B4: Green Square | C4: =SUM(D4:ZZ4) -> 2252.979 | D4: ='Cash In Flow Summary'!D4 -> 0 | E4: ='Cash In Flow Summary'!E4 -> 0 | F4: ='Cash In Flow Summary'!F4 -> 15.139238 | G4: ='Cash In Flow Summary'!G4 -> 30.278475 | H4: ='Cash In Flow Summary'!H4 -> 46.512006 | I4: ='Cash In Flow Summary'!I4 -> 62.745537 | J4: ='Cash In Flow Summary'!J4 -> 62.3657 | K4: ='Cash In Flow Summary'!K4 -> 63.473559 | ... AT4: ='Cash In Flow Summary'!AT4 -> 0
B5: L'avenir | C5: =SUM(D5:ZZ5) -> 2673.7357 | D5: ='Cash In Flow Summary'!D5 -> 0 | E5: ='Cash In Flow Summary'!E5 -> 0 | F5: ='Cash In Flow Summary'!F5 -> 0 | G5: ='Cash In Flow Summary'!G5 -> 0 | H5: ='Cash In Flow Summary'!H5 -> 18.11565 | I5: ='Cash In Flow Summary'!I5 -> 36.2313 | J5: ='Cash In Flow Summary'!J5 -> 58.260825 | K5: ='Cash In Flow Summary'!K5 -> 69.01839 | ... AT5: ='Cash In Flow Summary'!AT5 -> 0
C6: =SUM(C4:C5) -> 4926.7148 | D6: =SUM(D4:D5) -> 0 | E6: =SUM(E4:E5) -> 0 | F6: =SUM(F4:F5) -> 15.139238 | G6: =SUM(G4:G5) -> 30.278475 | H6: =SUM(H4:H5) -> 64.627656 | I6: =SUM(I4:I5) -> 98.976838 | J6: =SUM(J4:J5) -> 120.62653 | ... AT6: =SUM(AT4:AT5) -> 0
B8: ALAHLY - SABBOUR Payments MEGP
B9: Project | C9: Total Sales | D9: M 3 | E9: M 6 | F9: M 9 | G9: M 12 | H9: M 15 | I9: M 18 | J9: M 21 | K9: M 24 | L9: M 27 | M9: M 30 | N9: M 33 | O9: M 36 | P9: M 39 | Q9: M 42 | R9: M 45 | S9: M 48 | T9: M 51 | U9: M 54 | V9: M 57 | W9: M 60 | X9: M 63 | Y9: M 66 | Z9: M 69 | AA9: M 72 | AB9: M 75 | AC9: M 78 | AD9: M 81 | AE9: M 84 | AF9: M 87 | AG9: M 90 | AH9: M 93 | AI9: M 96 | AJ9: M 99 | AK9: M 102 | AL9: M 105 | AM9: M 108 | AN9: M 111 | AO9: M 114 | AP9: M 117 | AQ9: M 120 | AR9: M 123 | AS9: M 126 | AT9: M 129
B10: Green Square | C10: =SUM(D10:ZZ10) -> 985.67831 | D10: ='Offers DP'!$C$10/4+'Offers DP'!C9 -> 91.25 | E10: ='Offers DP'!$C$10/4 -> 11.25 | F10: ='Offers DP'!$C$10/4 -> 11.25 | G10: ='Offers DP'!$C$10/4 -> 11.25 | H10: ='Offers DP'!$C$11/4 -> 22.5 | I10: ='Offers DP'!$C$11/4 -> 22.5 | J10: ='Offers DP'!$C$11/4 -> 22.5 | K10: ='Offers DP'!$C$11/4 -> 22.5 | L10: ='Offers DP'!$C$12/4 -> 33.75 | M10: ='Offers DP'!$C$12/4 -> 33.75 | N10: ='Offers DP'!$C$12/4 -> 33.75 | O10: ='Offers DP'!$C$12/4 -> 33.75 | P10: ='Offers DP'!$C$13/4 -> 45 | Q10: ='Offers DP'!$C$13/4 -> 45 | R10: ='Offers DP'!$C$13/4 -> 45 | S10: ='Offers DP'!$C$13/4 -> 45 | T10: ='Offers DP'!$C$14/4 -> 45 | U10: ='Offers DP'!$C$14/4 -> 45 | V10: ='Offers DP'!$C$14/4 -> 45 | W10: ='Offers DP'!$C$14/4 -> 45 | X10: ='Offers DP'!$C$15/4 -> 22.5 | Y10: ='Offers DP'!$C$15/4 -> 22.5 | Z10: ='Offers DP'!$C$15/4 -> 22.5 | AA10: ='Offers DP'!$C$15/4 -> 22.5 | AB10: ='Offers DP'!$C$16/4 -> 0 | AC10: ='Offers DP'!$C$16/4 -> 0 | AD10: ='Offers DP'!$C$16/4 -> 0 | AE10: ='Offers DP'!$C$16/4 -> 0 | AF10: =-SUM(D10:AE10)+SUM('Cash In Flow Summary'!D37:AE37)+'Cash In Flow Summary'!AF37 -> 107.75821 | AG10: ='Cash In Flow Summary'!AG37 -> 10.976512 | AH10: ='Cash In Flow Summary'!AH37 -> 10.976512 | AI10: ='Cash In Flow Summary'!AI37 -> 10.976512 | AJ10: ='Cash In Flow Summary'!AJ37 -> 10.976512 | AK10: ='Cash In Flow Summary'!AK37 -> 10.020984 | AL10: ='Cash In Flow Summary'!AL37 -> 10.020984 | AM10: ='Cash In Flow Summary'!AM37 -> 8.198555 | AN10: ='Cash In Flow Summary'!AN37 -> 4.2114483 | ... AT10: ='Cash In Flow Summary'!AT37 -> 0
B11: L'avenir | C11: =SUM(D11:ZZ11) -> 1169.7594 | D11: ='Offers DP'!$D$10/4 -> 0 | E11: ='Offers DP'!$D$10/4 -> 0 | F11: ='Offers DP'!$D$10/4 -> 0 | G11: ='Offers DP'!$D$10/4++'Offers DP'!D9 -> 85 | H11: ='Offers DP'!$D$11/4 -> 22.5 | I11: ='Offers DP'!$D$11/4 -> 22.5 | J11: ='Offers DP'!$D$11/4 -> 22.5 | K11: ='Offers DP'!$D$11/4 -> 22.5 | L11: ='Offers DP'!$D$12/4 -> 45 | M11: ='Offers DP'!$D$12/4 -> 45 | N11: ='Offers DP'!$D$12/4 -> 45 | O11: ='Offers DP'!$D$12/4 -> 45 | P11: ='Offers DP'!$D$13/4 -> 56.25 | Q11: ='Offers DP'!$D$13/4 -> 56.25 | R11: ='Offers DP'!$D$13/4 -> 56.25 | S11: ='Offers DP'!$D$13/4 -> 56.25 | T11: ='Offers DP'!$D$14/4 -> 45 | U11: ='Offers DP'!$D$14/4 -> 45 | V11: ='Offers DP'!$D$14/4 -> 45 | W11: ='Offers DP'!$D$14/4 -> 45 | X11: ='Offers DP'!$D$15/4 -> 22.5 | Y11: ='Offers DP'!$D$15/4 -> 22.5 | Z11: ='Offers DP'!$D$15/4 -> 22.5 | AA11: ='Offers DP'!$D$15/4 -> 22.5 | AB11: ='Offers DP'!$D$16/4 -> 0 | AC11: ='Offers DP'!$D$16/4 -> 0 | AD11: ='Offers DP'!$D$16/4 -> 0 | AE11: ='Offers DP'!$D$16/4 -> 0 | AF11: =-SUM(D11:AE11)+SUM('Cash In Flow Summary'!D38:AE38)+'Cash In Flow Summary'!AF38 -> 241.19161 | AG11: ='Cash In Flow Summary'!AG38 -> 16.107226 | AH11: ='Cash In Flow Summary'!AH38 -> 14.419368 | AI11: ='Cash In Flow Summary'!AI38 -> 12.731509 | AJ11: ='Cash In Flow Summary'!AJ38 -> 10.011366 | AK11: ='Cash In Flow Summary'!AK38 -> 8.4360314 | AL11: ='Cash In Flow Summary'!AL38 -> 7.3515619 | AM11: ='Cash In Flow Summary'!AM38 -> 3.1702388 | AN11: ='Cash In Flow Summary'!AN38 -> 3.1702388 | ... AT11: ='Cash In Flow Summary'!AT38 -> 0
C12: =SUM(C10:C11) -> 2155.4377 | D12: =SUM(D10:D11) -> 91.25 | E12: =SUM(E10:E11) -> 11.25 | F12: =SUM(F10:F11) -> 11.25 | G12: =SUM(G10:G11) -> 96.25 | H12: =SUM(H10:H11) -> 45 | I12: =SUM(I10:I11) -> 45 | J12: =SUM(J10:J11) -> 45 | ... AT12: =SUM(AT10:AT11) -> 0
B14: Cash Available for Operation -MEGP
B15: Project | C15: Total Sales | D15: M 3 | E15: M 6 | F15: M 9 | G15: M 12 | H15: M 15 | I15: M 18 | J15: M 21 | K15: M 24 | L15: M 27 | M15: M 30 | N15: M 33 | O15: M 36 | P15: M 39 | Q15: M 42 | R15: M 45 | S15: M 48 | T15: M 51 | U15: M 54 | V15: M 57 | W15: M 60 | X15: M 63 | Y15: M 66 | Z15: M 69 | AA15: M 72 | AB15: M 75 | AC15: M 78 | AD15: M 81 | AE15: M 84 | AF15: M 87 | AG15: M 90 | AH15: M 93 | AI15: M 96 | AJ15: M 99 | AK15: M 102 | AL15: M 105 | AM15: M 108 | AN15: M 111 | AO15: M 114 | AP15: M 117 | AQ15: M 120 | AR15: M 123 | AS15: M 126 | AT15: M 129
B16: Green Square | C16: =SUM(D16:ZZ16) -> 1267.3007 | D16: =D4-D10 -> -91.25 | E16: =E4-E10 -> -11.25 | F16: =F4-F10 -> 3.8892375 | G16: =G4-G10 -> 19.028475 | H16: =H4-H10 -> 24.012006 | I16: =I4-I10 -> 40.245537 | J16: =J4-J10 -> 39.8657 | K16: =K4-K10 -> 40.973559 | ... AT16: =AT4-AT10 -> 0
B17: L'avenir | C17: =SUM(D17:ZZ17) -> 1503.9764 | D17: =D5-D11 -> 0 | E17: =E5-E11 -> 0 | F17: =F5-F11 -> 0 | G17: =G5-G11 -> -85 | H17: =H5-H11 -> -4.38435 | I17: =I5-I11 -> 13.7313 | J17: =J5-J11 -> 35.760825 | K17: =K5-K11 -> 46.51839 | ... AT17: =AT5-AT11 -> 0
B18: Total | C18: =SUM(C16:C17) -> 2771.277 | D18: =SUM(D16:D17) -> -91.25 | E18: =SUM(E16:E17) -> -11.25 | F18: =SUM(F16:F17) -> 3.8892375 | G18: =SUM(G16:G17) -> -65.971525 | H18: =SUM(H16:H17) -> 19.627656 | I18: =SUM(I16:I17) -> 53.976838 | J18: =SUM(J16:J17) -> 75.626525 | ... AT18: =SUM(AT16:AT17) -> 0
B20: NPV Cash Available for Operation -MEGP
B21: Project | C21: Total Sales | D21: M 3 | E21: M 6 | F21: M 9 | G21: M 12 | H21: M 15 | I21: M 18 | J21: M 21 | K21: M 24 | L21: M 27 | M21: M 30 | N21: M 33 | O21: M 36 | P21: M 39 | Q21: M 42 | R21: M 45 | S21: M 48 | T21: M 51 | U21: M 54 | V21: M 57 | W21: M 60 | X21: M 63 | Y21: M 66 | Z21: M 69 | AA21: M 72 | AB21: M 75 | AC21: M 78 | AD21: M 81 | AE21: M 84 | AF21: M 87 | AG21: M 90 | AH21: M 93 | AI21: M 96 | AJ21: M 99 | AK21: M 102 | AL21: M 105 | AM21: M 108 | AN21: M 111 | AO21: M 114 | AP21: M 117 | AQ21: M 120 | AR21: M 123 | AS21: M 126 | AT21: M 129
B22: Green Square | C22: =SUM(D22:AT22) -> 807.95087 | D22: =+D16/((1+'Green Square'!$C$72)^'Green Square'!E$73) -> -88.309344 | E22: =+E16/((1+'Green Square'!$C$72)^'Green Square'!F$73) -> -10.53659 | F22: =+F16/((1+'Green Square'!$C$72)^'Green Square'!G$73) -> 3.5252168 | G22: =+G16/((1+'Green Square'!$C$72)^'Green Square'!H$73) -> 16.691645 | H22: =+H16/((1+'Green Square'!$C$72)^'Green Square'!I$73) -> 20.384374 | I22: =+I16/((1+'Green Square'!$C$72)^'Green Square'!J$73) -> 33.064385 | J22: =+J16/((1+'Green Square'!$C$72)^'Green Square'!K$73) -> 31.696835 | K22: =+K16/((1+'Green Square'!$C$72)^'Green Square'!L$73) -> 31.527823 | ... AT22: =+AT16/((1+'Green Square'!$C$72)^'Green Square'!AU$73) -> 0
B23: L'avenir | C23: =SUM(D23:AT23) -> 872.63711 | D23: =+D17/((1+'Green Square'!$C$72)^'Green Square'!E$73) -> 0 | E23: =+E17/((1+'Green Square'!$C$72)^'Green Square'!F$73) -> 0 | F23: =+F17/((1+'Green Square'!$C$72)^'Green Square'!G$73) -> 0 | G23: =+G17/((1+'Green Square'!$C$72)^'Green Square'!H$73) -> -74.561404 | H23: =+H17/((1+'Green Square'!$C$72)^'Green Square'!I$73) -> -3.721981 | I23: =+I17/((1+'Green Square'!$C$72)^'Green Square'!J$73) -> 11.281176 | J23: =+J17/((1+'Green Square'!$C$72)^'Green Square'!K$73) -> 28.433089 | K23: =+K17/((1+'Green Square'!$C$72)^'Green Square'!L$73) -> 35.794391 | ... AT23: =+AT17/((1+'Green Square'!$C$72)^'Green Square'!AU$73) -> 0
B24: Total | C24: =SUM(C22:C23) -> 1680.588 | D24: =SUM(D22:D23) -> -88.309344 | E24: =SUM(E22:E23) -> -10.53659 | F24: =SUM(F22:F23) -> 3.5252168 | G24: =SUM(G22:G23) -> -57.869759 | H24: =SUM(H22:H23) -> 16.662393 | I24: =SUM(I22:I23) -> 44.345562 | J24: =SUM(J22:J23) -> 60.129924 | ... AT24: =SUM(AT22:AT23) -> 0
B26: CASH OUT FLOW CAPEX -MEGP
B27: Project | C27: Total Sales | D27: M 3 | E27: M 6 | F27: M 9 | G27: M 12 | H27: M 15 | I27: M 18 | J27: M 21 | K27: M 24 | L27: M 27 | M27: M 30 | N27: M 33 | O27: M 36 | P27: M 39 | Q27: M 42 | R27: M 45 | S27: M 48 | T27: M 51 | U27: M 54 | V27: M 57 | W27: M 60 | X27: M 63 | Y27: M 66 | Z27: M 69 | AA27: M 72 | AB27: M 75 | AC27: M 78 | AD27: M 81 | AE27: M 84 | AF27: M 87 | AG27: M 90 | AH27: M 93 | AI27: M 96 | AJ27: M 99 | AK27: M 102 | AL27: M 105 | AM27: M 108 | AN27: M 111 | AO27: M 114 | AP27: M 117 | AQ27: M 120 | AR27: M 123 | AS27: M 126 | AT27: M 129
B28: Green Square | C28: =SUM(H28:AAD28) -> 891.85316 | H28: =SUM('Cash Out Detail'!P43:R43)/1000000 -> 23 | I28: =SUM('Cash Out Detail'!S43:U43)/1000000 -> 30.36 | J28: =SUM('Cash Out Detail'!V43:X43)/1000000 -> 58.11139 | K28: =SUM('Cash Out Detail'!Y43:AA43)/1000000 -> 42.47139 | L28: =SUM('Cash Out Detail'!AB43:AD43)/1000000 -> 39.88126 | M28: =SUM('Cash Out Detail'!AE43:AG43)/1000000 -> 39.88126 | N28: =SUM('Cash Out Detail'!AH43:AJ43)/1000000 -> 13.06101 | O28: =SUM('Cash Out Detail'!AK43:AM43)/1000000 -> 13.06101 | P28: =SUM('Cash Out Detail'!AN43:AP43)/1000000 -> 145.69804 | Q28: =SUM('Cash Out Detail'!AQ43:AS43)/1000000 -> 147.2608 | R28: =SUM('Cash Out Detail'!AT43:AV43)/1000000 -> 197.8608 | S28: =SUM('Cash Out Detail'!AW43:AY43)/1000000 -> 141.2062 | T28: =SUM('Cash Out Detail'!AZ43:BB43)/1000000 -> 0 | U28: =SUM('Cash Out Detail'!BC43:BE43)/1000000 -> 0 | V28: =SUM('Cash Out Detail'!BF43:BH43)/1000000 -> 0 | W28: =SUM('Cash Out Detail'!BI43:BK43)/1000000 -> 0 | X28: =SUM('Cash Out Detail'!BL43:BN43)/1000000 -> 0 | Y28: =SUM('Cash Out Detail'!BO43:BQ43)/1000000 -> 0
B29: L'avenir | C29: =SUM(H29:AAD29) -> 908.68343 | H29: =SUM('Cash Out Detail'!P44:R44)/1000000 -> 0 | I29: =SUM('Cash Out Detail'!S44:U44)/1000000 -> 0 | J29: =SUM('Cash Out Detail'!V44:X44)/1000000 -> 23 | K29: =SUM('Cash Out Detail'!Y44:AA44)/1000000 -> 30.36 | L29: =SUM('Cash Out Detail'!AB44:AD44)/1000000 -> 60.49252 | M29: =SUM('Cash Out Detail'!AE44:AG44)/1000000 -> 44.85252 | N29: =SUM('Cash Out Detail'!AH44:AJ44)/1000000 -> 42.79494 | O29: =SUM('Cash Out Detail'!AK44:AM44)/1000000 -> 37.56153 | P29: =SUM('Cash Out Detail'!AN44:AP44)/1000000 -> 14.00412 | Q29: =SUM('Cash Out Detail'!AQ44:AS44)/1000000 -> 13.46736 | R29: =SUM('Cash Out Detail'!AT44:AV44)/1000000 -> 145.54446 | S29: =SUM('Cash Out Detail'!AW44:AY44)/1000000 -> 145.54446 | T29: =SUM('Cash Out Detail'!AZ44:BB44)/1000000 -> 196.83032 | U29: =SUM('Cash Out Detail'!BC44:BE44)/1000000 -> 142.78032 | V29: =SUM('Cash Out Detail'!BF44:BH44)/1000000 -> 5.72544 | W29: =SUM('Cash Out Detail'!BI44:BK44)/1000000 -> 5.72544 | X29: =SUM('Cash Out Detail'!BL44:BN44)/1000000 -> 0 | Y29: =SUM('Cash Out Detail'!BO44:BQ44)/1000000 -> 0
B30: Total | C30: =SUM(C28:C29) -> 1800.5366 | D30: =SUM(H28:H29) -> 23 | E30: =SUM(I28:I29) -> 30.36 | F30: =SUM(J28:J29) -> 81.11139 | G30: =SUM(K28:K29) -> 72.83139 | H30: =SUM(L28:L29) -> 100.37378 | I30: =SUM(M28:M29) -> 84.73378 | J30: =SUM(N28:N29) -> 55.85595 | K30: =SUM(O28:O29) -> 50.62254 | ... AT30: =SUM(AX28:AX29) -> 0
B32: NPV CASH OUT FLOW CAPEX -MEGP | D32: 32.971612 | E32: 38.802329 | F32: 49.131115 | G32: 33.8285 | H32: 31.104567 | I32: 30.10218 | J32: 10.384684 | K32: 11.152308 | L32: 109.66076 | M32: 0.00010424973 | N32: 131.53864 | O32: 90.817418 | P32: 0 | Q32: 0 | R32: 0 | S32: 0 | T32: 0
B33: Project | C33: Total Sales | D33: M 3 | E33: M 6 | F33: M 9 | G33: M 12 | H33: M 15 | I33: M 18 | J33: M 21 | K33: M 24 | L33: M 27 | M33: M 30 | N33: M 33 | O33: M 36 | P33: M 39 | Q33: M 42 | R33: M 45 | S33: M 48 | T33: M 51 | U33: M 54 | V33: M 57 | W33: M 60 | X33: M 63 | Y33: M 66 | Z33: M 69 | AA33: M 72 | AB33: M 75 | AC33: M 78 | AD33: M 81 | AE33: M 84 | AF33: M 87 | AG33: M 90 | AH33: M 93 | AI33: M 96 | AJ33: M 99 | AK33: M 102 | AL33: M 105 | AM33: M 108 | AN33: M 111 | AO33: M 114 | AP33: M 117 | AQ33: M 120 | AR33: M 123 | AS33: M 126 | AT33: M 129
B34: Green Square | C34: =SUM(D34:ZZ34) -> 592.63947 | D34: =+D28/((1+'Green Square'!$C$72)^'Green Square'!E$73) -> 0 | E34: =+E28/((1+'Green Square'!$C$72)^'Green Square'!F$73) -> 0 | F34: =+F28/((1+'Green Square'!$C$72)^'Green Square'!G$73) -> 0 | G34: =+G28/((1+'Green Square'!$C$72)^'Green Square'!H$73) -> 0 | H34: =+H28/((1+'Green Square'!$C$72)^'Green Square'!I$73) -> 19.525258 | I34: =+I28/((1+'Green Square'!$C$72)^'Green Square'!J$73) -> 24.942759 | J34: =+J28/((1+'Green Square'!$C$72)^'Green Square'!K$73) -> 46.203808 | K34: =+K28/((1+'Green Square'!$C$72)^'Green Square'!L$73) -> 32.680355 | ... AA34: =+AA28/((1+'Green Square'!$C$72)^'Green Square'!AB$73) -> 0 | AB34: =+AF28/((1+'Green Square'!$C$72)^'Green Square'!AC$73) -> 0 | AC34: =+AG28/((1+'Green Square'!$C$72)^'Green Square'!AD$73) -> 0 | AD34: =+AH28/((1+'Green Square'!$C$72)^'Green Square'!AE$73) -> 0 | AE34: =+AI28/((1+'Green Square'!$C$72)^'Green Square'!AF$73) -> 0 | AF34: =+AJ28/((1+'Green Square'!$C$72)^'Green Square'!AG$73) -> 0 | AG34: =+AK28/((1+'Green Square'!$C$72)^'Green Square'!AH$73) -> 0 | AH34: =+AL28/((1+'Green Square'!$C$72)^'Green Square'!AI$73) -> 0 | AI34: =+AM28/((1+'Green Square'!$C$72)^'Green Square'!AJ$73) -> 0 | ... AT34: =+AX28/((1+'Green Square'!$C$72)^'Green Square'!AU$73) -> 0
B35: L'avenir | C35: =SUM(D35:ZZ35) -> 565.10474 | D35: =+D29/((1+'Green Square'!$C$72)^'Green Square'!E$73) -> 0 | E35: =+E29/((1+'Green Square'!$C$72)^'Green Square'!F$73) -> 0 | F35: =+F29/((1+'Green Square'!$C$72)^'Green Square'!G$73) -> 0 | G35: =+G29/((1+'Green Square'!$C$72)^'Green Square'!H$73) -> 0 | H35: =+H29/((1+'Green Square'!$C$72)^'Green Square'!I$73) -> 0 | I35: =+I29/((1+'Green Square'!$C$72)^'Green Square'!J$73) -> 0 | J35: =+J29/((1+'Green Square'!$C$72)^'Green Square'!K$73) -> 18.287079 | K35: =+K29/((1+'Green Square'!$C$72)^'Green Square'!L$73) -> 23.361034 | ... AA35: =+AA29/((1+'Green Square'!$C$72)^'Green Square'!AB$73) -> 0 | AB35: =+AF29/((1+'Green Square'!$C$72)^'Green Square'!AC$73) -> 0 | AC35: =+AG29/((1+'Green Square'!$C$72)^'Green Square'!AD$73) -> 0 | AD35: =+AH29/((1+'Green Square'!$C$72)^'Green Square'!AE$73) -> 0 | AE35: =+AI29/((1+'Green Square'!$C$72)^'Green Square'!AF$73) -> 0 | AF35: =+AJ29/((1+'Green Square'!$C$72)^'Green Square'!AG$73) -> 0 | AG35: =+AK29/((1+'Green Square'!$C$72)^'Green Square'!AH$73) -> 0 | AH35: =+AL29/((1+'Green Square'!$C$72)^'Green Square'!AI$73) -> 0 | AI35: =+AM29/((1+'Green Square'!$C$72)^'Green Square'!AJ$73) -> 0 | ... AT35: =+AX29/((1+'Green Square'!$C$72)^'Green Square'!AU$73) -> 0
B36: Total | C36: =SUM(C34:C35) -> 1157.7442 | D36: =SUM(D34:D35) -> 0 | E36: =SUM(E34:E35) -> 0 | F36: =SUM(F34:F35) -> 0 | G36: =SUM(G34:G35) -> 0 | H36: =SUM(H34:H35) -> 19.525258 | I36: =SUM(I34:I35) -> 24.942759 | J36: =SUM(J34:J35) -> 64.490888 | ... AT36: =SUM(AT34:AT35) -> 0
B38: NET CASH FLOW -MEGP
B39: Project | C39: Total Sales | D39: M 3 | E39: M 6 | F39: M 9 | G39: M 12 | H39: M 15 | I39: M 18 | J39: M 21 | K39: M 24 | L39: M 27 | M39: M 30 | N39: M 33 | O39: M 36 | P39: M 39 | Q39: M 42 | R39: M 45 | S39: M 48 | T39: M 51 | U39: M 54 | V39: M 57 | W39: M 60 | X39: M 63 | Y39: M 66 | Z39: M 69 | AA39: M 72 | AB39: M 75 | AC39: M 78 | AD39: M 81 | AE39: M 84 | AF39: M 87 | AG39: M 90 | AH39: M 93 | AI39: M 96 | AJ39: M 99 | AK39: M 102 | AL39: M 105 | AM39: M 108 | AN39: M 111 | AO39: M 114 | AP39: M 117 | AQ39: M 120 | AR39: M 123 | AS39: M 126 | AT39: M 129
B40: Green Square | C40: =SUM(D40:ZZ40) -> 375.44753 | D40: =D16-D28 -> -91.25 | E40: =E16-E28 -> -11.25 | F40: =F16-F28 -> 3.8892375 | G40: =G16-G28 -> 19.028475 | H40: =H16-H28 -> 1.0120062 | I40: =I16-I28 -> 9.8855375 | J40: =J16-J28 -> -18.24569 | K40: =K16-K28 -> -1.4978306 | ... AT40: =AT16-AT28 -> 0
B41: L'avenir | C41: =SUM(D41:ZZ41) -> 595.29293 | D41: =D17-D29 -> 0 | E41: =E17-E29 -> 0 | F41: =F17-F29 -> 0 | G41: =G17-G29 -> -85 | H41: =H17-H29 -> -4.38435 | I41: =I17-I29 -> 13.7313 | J41: =J17-J29 -> 12.760825 | K41: =K17-K29 -> 16.15839 | ... AT41: =AT17-AT29 -> 0
B42: Total | C42: =SUM(C40:C41) -> 970.74046 | D42: =SUM(D40:D41) -> -91.25 | E42: =SUM(E40:E41) -> -11.25 | F42: =SUM(F40:F41) -> 3.8892375 | G42: =SUM(G40:G41) -> -65.971525 | H42: =SUM(H40:H41) -> -3.3723438 | I42: =SUM(I40:I41) -> 23.616837 | J42: =SUM(J40:J41) -> -5.484865 | ... AT42: =SUM(AT40:AT41) -> 0
B44: NPV NET CASH FLOW -MEGP
B45: Project | C45: Total Sales | D45: M 3 | E45: M 6 | F45: M 9 | G45: M 12 | H45: M 15 | I45: M 18 | J45: M 21 | K45: M 24 | L45: M 27 | M45: M 30 | N45: M 33 | O45: M 36 | P45: M 39 | Q45: M 42 | R45: M 45 | S45: M 48 | T45: M 51 | U45: M 54 | V45: M 57 | W45: M 60 | X45: M 63 | Y45: M 66 | Z45: M 69 | AA45: M 72 | AB45: M 75 | AC45: M 78 | AD45: M 81 | AE45: M 84 | AF45: M 87 | AG45: M 90 | AH45: M 93 | AI45: M 96 | AJ45: M 99 | AK45: M 102 | AL45: M 105 | AM45: M 108 | AN45: M 111 | AO45: M 114 | AP45: M 117 | AQ45: M 120 | AR45: M 123 | AS45: M 126 | AT45: M 129
B46: Green Square | C46: =SUM(D46:ZZ46) -> 215.31139 | D46: =+D40/((1+'Green Square'!$C$72)^'Green Square'!E$73) -> -88.309344 | E46: =+E40/((1+'Green Square'!$C$72)^'Green Square'!F$73) -> -10.53659 | F46: =+F40/((1+'Green Square'!$C$72)^'Green Square'!G$73) -> 3.5252168 | G46: =+G40/((1+'Green Square'!$C$72)^'Green Square'!H$73) -> 16.691645 | H46: =+H40/((1+'Green Square'!$C$72)^'Green Square'!I$73) -> 0.85911664 | I46: =+I40/((1+'Green Square'!$C$72)^'Green Square'!J$73) -> 8.1216265 | J46: =+J40/((1+'Green Square'!$C$72)^'Green Square'!K$73) -> -14.506973 | K46: =+K40/((1+'Green Square'!$C$72)^'Green Square'!L$73) -> -1.152532 | ... AT46: =+AT40/((1+'Green Square'!$C$72)^'Green Square'!AU$73) -> 0
B47: L'avenir | C47: =SUM(D47:ZZ47) -> 307.53237 | D47: =+D41/((1+'Green Square'!$C$72)^'Green Square'!E$73) -> 0 | E47: =+E41/((1+'Green Square'!$C$72)^'Green Square'!F$73) -> 0 | F47: =+F41/((1+'Green Square'!$C$72)^'Green Square'!G$73) -> 0 | G47: =+G41/((1+'Green Square'!$C$72)^'Green Square'!H$73) -> -74.561404 | H47: =+H41/((1+'Green Square'!$C$72)^'Green Square'!I$73) -> -3.721981 | I47: =+I41/((1+'Green Square'!$C$72)^'Green Square'!J$73) -> 11.281176 | J47: =+J41/((1+'Green Square'!$C$72)^'Green Square'!K$73) -> 10.146009 | K47: =+K41/((1+'Green Square'!$C$72)^'Green Square'!L$73) -> 12.433356 | ... AT47: =+AT41/((1+'Green Square'!$C$72)^'Green Square'!AU$73) -> 0
...

Sheet Net Cash Flow -Without DP
B1: Cash Available for Operation after - 20% RETAINED UNITS
B2: Total Collections MEGP
B3: Project | C3: Total Sales | D3: M 3 | E3: M 6 | F3: M 9 | G3: M 12 | H3: M 15 | I3: M 18 | J3: M 21 | K3: M 24 | L3: M 27 | M3: M 30 | N3: M 33 | O3: M 36 | P3: M 39 | Q3: M 42 | R3: M 45 | S3: M 48 | T3: M 51 | U3: M 54 | V3: M 57 | W3: M 60 | X3: M 63 | Y3: M 66 | Z3: M 69 | AA3: M 72 | AB3: M 75 | AC3: M 78 | AD3: M 81 | AE3: M 84 | AF3: M 87 | AG3: M 90 | AH3: M 93 | AI3: M 96 | AJ3: M 99 | AK3: M 102 | AL3: M 105 | AM3: M 108 | AN3: M 111 | AO3: M 114 | AP3: M 117 | AQ3: M 120 | AR3: M 123 | AS3: M 126 | AT3: M 129
B4: Green Square | C4: =SUM(D4:ZZ4) -> 2252.979 | D4: ='Cash In Flow Summary'!D4 -> 0 | E4: ='Cash In Flow Summary'!E4 -> 0 | F4: ='Cash In Flow Summary'!F4 -> 15.139238 | G4: ='Cash In Flow Summary'!G4 -> 30.278475 | H4: ='Cash In Flow Summary'!H4 -> 46.512006 | I4: ='Cash In Flow Summary'!I4 -> 62.745537 | J4: ='Cash In Flow Summary'!J4 -> 62.3657 | K4: ='Cash In Flow Summary'!K4 -> 63.473559 | ... AT4: ='Cash In Flow Summary'!AT4 -> 0
B5: L'avenir | C5: =SUM(D5:ZZ5) -> 2673.7357 | D5: ='Cash In Flow Summary'!D5 -> 0 | E5: ='Cash In Flow Summary'!E5 -> 0 | F5: ='Cash In Flow Summary'!F5 -> 0 | G5: ='Cash In Flow Summary'!G5 -> 0 | H5: ='Cash In Flow Summary'!H5 -> 18.11565 | I5: ='Cash In Flow Summary'!I5 -> 36.2313 | J5: ='Cash In Flow Summary'!J5 -> 58.260825 | K5: ='Cash In Flow Summary'!K5 -> 69.01839 | ... AT5: ='Cash In Flow Summary'!AT5 -> 0
C6: =SUM(C4:C5) -> 4926.7148 | D6: =SUM(D4:D5) -> 0 | E6: =SUM(E4:E5) -> 0 | F6: =SUM(F4:F5) -> 15.139238 | G6: =SUM(G4:G5) -> 30.278475 | H6: =SUM(H4:H5) -> 64.627656 | I6: =SUM(I4:I5) -> 98.976838 | J6: =SUM(J4:J5) -> 120.62653 | ... AT6: =SUM(AT4:AT5) -> 0
B8: ALAHLY - SABBOUR Payments MEGP
B9: Project | C9: Total Sales | D9: M 3 | E9: M 6 | F9: M 9 | G9: M 12 | H9: M 15 | I9: M 18 | J9: M 21 | K9: M 24 | L9: M 27 | M9: M 30 | N9: M 33 | O9: M 36 | P9: M 39 | Q9: M 42 | R9: M 45 | S9: M 48 | T9: M 51 | U9: M 54 | V9: M 57 | W9: M 60 | X9: M 63 | Y9: M 66 | Z9: M 69 | AA9: M 72 | AB9: M 75 | AC9: M 78 | AD9: M 81 | AE9: M 84 | AF9: M 87 | AG9: M 90 | AH9: M 93 | AI9: M 96 | AJ9: M 99 | AK9: M 102 | AL9: M 105 | AM9: M 108 | AN9: M 111 | AO9: M 114 | AP9: M 117 | AQ9: M 120 | AR9: M 123 | AS9: M 126 | AT9: M 129
B10: Green Square | C10: =SUM(D10:ZZ10) -> 985.67831 | D10: =Offers!$C$6/4 -> 12.5 | E10: =Offers!$C$6/4 -> 12.5 | F10: =Offers!$C$6/4 -> 12.5 | G10: =Offers!$C$6/4 -> 12.5 | H10: =Offers!$C$7/4 -> 25 | I10: =Offers!$C$7/4 -> 25 | J10: =Offers!$C$7/4 -> 25 | K10: =Offers!$C$7/4 -> 25 | L10: =Offers!$C$8/4 -> 37.5 | M10: =Offers!$C$8/4 -> 37.5 | N10: =Offers!$C$8/4 -> 37.5 | O10: =Offers!$C$8/4 -> 37.5 | P10: =Offers!$C$9/4 -> 50 | Q10: =Offers!$C$9/4 -> 50 | R10: =Offers!$C$9/4 -> 50 | S10: =Offers!$C$9/4 -> 50 | T10: =Offers!$C$10/4 -> 50 | U10: =Offers!$C$10/4 -> 50 | V10: =Offers!$C$10/4 -> 50 | W10: =Offers!$C$10/4 -> 50 | X10: =Offers!$C$11/4 -> 25 | Y10: =Offers!$C$11/4 -> 25 | Z10: =Offers!$C$11/4 -> 25 | AA10: =Offers!$C$11/4 -> 25 | AB10: =Offers!$C$12/4 -> 0 | AC10: =Offers!$C$12/4 -> 0 | AD10: =Offers!$C$12/4 -> 0 | AE10: =Offers!$C$12/4 -> 0 | AF10: =-SUM(D10:AE10)+SUM('Cash In Flow Summary'!D37:AE37)+'Cash In Flow Summary'!AF37 -> 107.75821 | AG10: ='Cash In Flow Summary'!AG37 -> 10.976512 | AH10: ='Cash In Flow Summary'!AH37 -> 10.976512 | AI10: ='Cash In Flow Summary'!AI37 -> 10.976512 | AJ10: ='Cash In Flow Summary'!AJ37 -> 10.976512 | AK10: ='Cash In Flow Summary'!AK37 -> 10.020984 | AL10: ='Cash In Flow Summary'!AL37 -> 10.020984 | AM10: ='Cash In Flow Summary'!AM37 -> 8.198555 | AN10: ='Cash In Flow Summary'!AN37 -> 4.2114483 | ... AT10: ='Cash In Flow Summary'!AT37 -> 0
B11: L'avenir | C11: =SUM(D11:ZZ11) -> 1169.7594 | D11: =Offers!$D$6/4 -> 0 | E11: =Offers!$D$6/4 -> 0 | F11: =Offers!$D$6/4 -> 0 | G11: =Offers!$D$6/4 -> 0 | H11: =Offers!$D$7/4 -> 25 | I11: =Offers!$D$7/4 -> 25 | J11: =Offers!$D$7/4 -> 25 | K11: =Offers!$D$7/4 -> 25 | L11: =Offers!$D$8/4 -> 50 | M11: =Offers!$D$8/4 -> 50 | N11: =Offers!$D$8/4 -> 50 | O11: =Offers!$D$8/4 -> 50 | P11: =Offers!$D$9/4 -> 62.5 | Q11: =Offers!$D$9/4 -> 62.5 | R11: =Offers!$D$9/4 -> 62.5 | S11: =Offers!$D$9/4 -> 62.5 | T11: =Offers!$D$10/4 -> 50 | U11: =Offers!$D$10/4 -> 50 | V11: =Offers!$D$10/4 -> 50 | W11: =Offers!$D$10/4 -> 50 | X11: =Offers!$D$11/4 -> 25 | Y11: =Offers!$D$11/4 -> 25 | Z11: =Offers!$D$11/4 -> 25 | AA11: =Offers!$D$11/4 -> 25 | AB11: =Offers!$D$12/4 -> 0 | AC11: =Offers!$D$12/4 -> 0 | AD11: =Offers!$D$12/4 -> 0 | AE11: =Offers!$D$12/4 -> 0 | AF11: =-SUM(D11:AE11)+SUM('Cash In Flow Summary'!D38:AE38)+'Cash In Flow Summary'!AF38 -> 241.19161 | AG11: ='Cash In Flow Summary'!AG38 -> 16.107226 | AH11: ='Cash In Flow Summary'!AH38 -> 14.419368 | AI11: ='Cash In Flow Summary'!AI38 -> 12.731509 | AJ11: ='Cash In Flow Summary'!AJ38 -> 10.011366 | AK11: ='Cash In Flow Summary'!AK38 -> 8.4360314 | AL11: ='Cash In Flow Summary'!AL38 -> 7.3515619 | AM11: ='Cash In Flow Summary'!AM38 -> 3.1702388 | AN11: ='Cash In Flow Summary'!AN38 -> 3.1702388 | ... AT11: ='Cash In Flow Summary'!AT38 -> 0
C12: =SUM(C10:C11) -> 2155.4377 | D12: =SUM(D10:D11) -> 12.5 | E12: =SUM(E10:E11) -> 12.5 | F12: =SUM(F10:F11) -> 12.5 | G12: =SUM(G10:G11) -> 12.5 | H12: =SUM(H10:H11) -> 50 | I12: =SUM(I10:I11) -> 50 | J12: =SUM(J10:J11) -> 50 | ... AT12: =SUM(AT10:AT11) -> 0
B14: Cash Available for Operation -MEGP
B15: Project | C15: Total Sales | D15: M 3 | E15: M 6 | F15: M 9 | G15: M 12 | H15: M 15 | I15: M 18 | J15: M 21 | K15: M 24 | L15: M 27 | M15: M 30 | N15: M 33 | O15: M 36 | P15: M 39 | Q15: M 42 | R15: M 45 | S15: M 48 | T15: M 51 | U15: M 54 | V15: M 57 | W15: M 60 | X15: M 63 | Y15: M 66 | Z15: M 69 | AA15: M 72 | AB15: M 75 | AC15: M 78 | AD15: M 81 | AE15: M 84 | AF15: M 87 | AG15: M 90 | AH15: M 93 | AI15: M 96 | AJ15: M 99 | AK15: M 102 | AL15: M 105 | AM15: M 108 | AN15: M 111 | AO15: M 114 | AP15: M 117 | AQ15: M 120 | AR15: M 123 | AS15: M 126 | AT15: M 129
B16: Green Square | C16: =SUM(D16:ZZ16) -> 1267.3007 | D16: =D4-D10 -> -12.5 | E16: =E4-E10 -> -12.5 | F16: =F4-F10 -> 2.6392375 | G16: =G4-G10 -> 17.778475 | H16: =H4-H10 -> 21.512006 | I16: =I4-I10 -> 37.745537 | J16: =J4-J10 -> 37.3657 | K16: =K4-K10 -> 38.473559 | ... AT16: =AT4-AT10 -> 0
B17: L'avenir | C17: =SUM(D17:ZZ17) -> 1503.9764 | D17: =D5-D11 -> 0 | E17: =E5-E11 -> 0 | F17: =F5-F11 -> 0 | G17: =G5-G11 -> 0 | H17: =H5-H11 -> -6.88435 | I17: =I5-I11 -> 11.2313 | J17: =J5-J11 -> 33.260825 | K17: =K5-K11 -> 44.01839 | ... AT17: =AT5-AT11 -> 0
B18: Total | C18: =SUM(C16:C17) -> 2771.277 | D18: =SUM(D16:D17) -> -12.5 | E18: =SUM(E16:E17) -> -12.5 | F18: =SUM(F16:F17) -> 2.6392375 | G18: =SUM(G16:G17) -> 17.778475 | H18: =SUM(H16:H17) -> 14.627656 | I18: =SUM(I16:I17) -> 48.976838 | J18: =SUM(J16:J17) -> 70.626525 | ... AT18: =SUM(AT16:AT17) -> 0
B20: NPV Cash Available for Operation -MEGP
B21: Project | C21: Total Sales | D21: M 3 | E21: M 6 | F21: M 9 | G21: M 12 | H21: M 15 | I21: M 18 | J21: M 21 | K21: M 24 | L21: M 27 | M21: M 30 | N21: M 33 | O21: M 36 | P21: M 39 | Q21: M 42 | R21: M 45 | S21: M 48 | T21: M 51 | U21: M 54 | V21: M 57 | W21: M 60 | X21: M 63 | Y21: M 66 | Z21: M 69 | AA21: M 72 | AB21: M 75 | AC21: M 78 | AD21: M 81 | AE21: M 84 | AF21: M 87 | AG21: M 90 | AH21: M 93 | AI21: M 96 | AJ21: M 99 | AK21: M 102 | AL21: M 105 | AM21: M 108 | AN21: M 111 | AO21: M 114 | AP21: M 117 | AQ21: M 120 | AR21: M 123 | AS21: M 126 | AT21: M 129
B22: Green Square | C22: =SUM(D22:ZZ22) -> 833.88091 | D22: =+D16/((1+'Green Square'!$C$72)^'Green Square'!E$73) -> -12.09717 | E22: =+E16/((1+'Green Square'!$C$72)^'Green Square'!F$73) -> -11.707323 | F22: =+F16/((1+'Green Square'!$C$72)^'Green Square'!G$73) -> 2.3922129 | G22: =+G16/((1+'Green Square'!$C$72)^'Green Square'!H$73) -> 15.595154 | H22: =+H16/((1+'Green Square'!$C$72)^'Green Square'!I$73) -> 18.262064 | I22: =+I16/((1+'Green Square'!$C$72)^'Green Square'!J$73) -> 31.010469 | J22: =+J16/((1+'Green Square'!$C$72)^'Green Square'!K$73) -> 29.709109 | K22: =+K16/((1+'Green Square'!$C$72)^'Green Square'!L$73) -> 29.604155 | ... AT22: =+AT16/((1+'Green Square'!$C$72)^'Green Square'!AU$73) -> 0
B23: L'avenir | C23: =SUM(D23:ZZ23) -> 893.65783 | D23: =+D17/((1+'Green Square'!$C$72)^'Green Square'!E$73) -> 0 | E23: =+E17/((1+'Green Square'!$C$72)^'Green Square'!F$73) -> 0 | F23: =+F17/((1+'Green Square'!$C$72)^'Green Square'!G$73) -> 0 | G23: =+G17/((1+'Green Square'!$C$72)^'Green Square'!H$73) -> 0 | H23: =+H17/((1+'Green Square'!$C$72)^'Green Square'!I$73) -> -5.8442916 | I23: =+I17/((1+'Green Square'!$C$72)^'Green Square'!J$73) -> 9.2272598 | J23: =+J17/((1+'Green Square'!$C$72)^'Green Square'!K$73) -> 26.445363 | K23: =+K17/((1+'Green Square'!$C$72)^'Green Square'!L$73) -> 33.870722 | ... AT23: =+AT17/((1+'Green Square'!$C$72)^'Green Square'!AU$73) -> 0
B24: Total | C24: =SUM(C22:C23) -> 1727.5387 | D24: =SUM(D22:D23) -> -12.09717 | E24: =SUM(E22:E23) -> -11.707323 | F24: =SUM(F22:F23) -> 2.3922129 | G24: =SUM(G22:G23) -> 15.595154 | H24: =SUM(H22:H23) -> 12.417772 | I24: =SUM(I22:I23) -> 40.237729 | J24: =SUM(J22:J23) -> 56.154472 | ... AT24: =SUM(AT22:AT23) -> 0
B26: CASH OUT FLOW CAPEX -MEGP
B27: Project | C27: Total Sales | D27: M 3 | E27: M 6 | F27: M 9 | G27: M 12 | H27: M 15 | I27: M 18 | J27: M 21 | K27: M 24 | L27: M 27 | M27: M 30 | N27: M 33 | O27: M 36 | P27: M 39 | Q27: M 42 | R27: M 45 | S27: M 48 | T27: M 51 | U27: M 54 | V27: M 57 | W27: M 60 | X27: M 63 | Y27: M 66 | Z27: M 69 | AA27: M 72 | AB27: M 75 | AC27: M 78 | AD27: M 81 | AE27: M 84 | AF27: M 87 | AG27: M 90 | AH27: M 93 | AI27: M 96 | AJ27: M 99 | AK27: M 102 | AL27: M 105 | AM27: M 108 | AN27: M 111 | AO27: M 114 | AP27: M 117 | AQ27: M 120 | AR27: M 123 | AS27: M 126 | AT27: M 129
B28: Green Square | C28: =SUM(H28:AAD28) -> 891.85316 | H28: =SUM('Cash Out Detail'!P43:R43)/1000000 -> 23 | I28: =SUM('Cash Out Detail'!S43:U43)/1000000 -> 30.36 | J28: =SUM('Cash Out Detail'!V43:X43)/1000000 -> 58.11139 | K28: =SUM('Cash Out Detail'!Y43:AA43)/1000000 -> 42.47139 | L28: =SUM('Cash Out Detail'!AB43:AD43)/1000000 -> 39.88126 | M28: =SUM('Cash Out Detail'!AE43:AG43)/1000000 -> 39.88126 | N28: =SUM('Cash Out Detail'!AH43:AJ43)/1000000 -> 13.06101 | O28: =SUM('Cash Out Detail'!AK43:AM43)/1000000 -> 13.06101 | P28: =SUM('Cash Out Detail'!AN43:AP43)/1000000 -> 145.69804 | Q28: =SUM('Cash Out Detail'!AQ43:AS43)/1000000 -> 147.2608 | R28: =SUM('Cash Out Detail'!AT43:AV43)/1000000 -> 197.8608 | S28: =SUM('Cash Out Detail'!AW43:AY43)/1000000 -> 141.2062 | T28: =SUM('Cash Out Detail'!AZ43:BB43)/1000000 -> 0 | U28: =SUM('Cash Out Detail'!BC43:BE43)/1000000 -> 0 | V28: =SUM('Cash Out Detail'!BF43:BH43)/1000000 -> 0 | W28: =SUM('Cash Out Detail'!BI43:BK43)/1000000 -> 0 | X28: =SUM('Cash Out Detail'!BL43:BN43)/1000000 -> 0 | Y28: =SUM('Cash Out Detail'!BO43:BQ43)/1000000 -> 0
B29: L'avenir | C29: =SUM(H29:AAD29) -> 908.68343 | H29: =SUM('Cash Out Detail'!P44:R44)/1000000 -> 0 | I29: =SUM('Cash Out Detail'!S44:U44)/1000000 -> 0 | J29: =SUM('Cash Out Detail'!V44:X44)/1000000 -> 23 | K29: =SUM('Cash Out Detail'!Y44:AA44)/1000000 -> 30.36 | L29: =SUM('Cash Out Detail'!AB44:AD44)/1000000 -> 60.49252 | M29: =SUM('Cash Out Detail'!AE44:AG44)/1000000 -> 44.85252 | N29: =SUM('Cash Out Detail'!AH44:AJ44)/1000000 -> 42.79494 | O29: =SUM('Cash Out Detail'!AK44:AM44)/1000000 -> 37.56153 | P29: =SUM('Cash Out Detail'!AN44:AP44)/1000000 -> 14.00412 | Q29: =SUM('Cash Out Detail'!AQ44:AS44)/1000000 -> 13.46736 | R29: =SUM('Cash Out Detail'!AT44:AV44)/1000000 -> 145.54446 | S29: =SUM('Cash Out Detail'!AW44:AY44)/1000000 -> 145.54446 | T29: =SUM('Cash Out Detail'!AZ44:BB44)/1000000 -> 196.83032 | U29: =SUM('Cash Out Detail'!BC44:BE44)/1000000 -> 142.78032 | V29: =SUM('Cash Out Detail'!BF44:BH44)/1000000 -> 5.72544 | W29: =SUM('Cash Out Detail'!BI44:BK44)/1000000 -> 5.72544 | X29: =SUM('Cash Out Detail'!BL44:BN44)/1000000 -> 0 | Y29: =SUM('Cash Out Detail'!BO44:BQ44)/1000000 -> 0
B30: Total | C30: =SUM(C28:C29) -> 1800.5366 | D30: =SUM(H28:H29) -> 23 | E30: =SUM(I28:I29) -> 30.36 | F30: =SUM(J28:J29) -> 81.11139 | G30: =SUM(K28:K29) -> 72.83139 | H30: =SUM(L28:L29) -> 100.37378 | I30: =SUM(M28:M29) -> 84.73378 | J30: =SUM(N28:N29) -> 55.85595 | K30: =SUM(O28:O29) -> 50.62254 | ... AT30: =SUM(AX28:AX29) -> 0
B32: NPV CASH OUT FLOW CAPEX -MEGP | D32: 32.971612 | E32: 38.802329 | F32: 49.131115 | G32: 33.8285 | H32: 31.104567 | I32: 30.10218 | J32: 10.384684 | K32: 11.152308 | L32: 109.66076 | M32: 0.00010424973 | N32: 131.53864 | O32: 90.817418 | P32: 0 | Q32: 0 | R32: 0 | S32: 0 | T32: 0
B33: Project | C33: Total Sales | D33: M 3 | E33: M 6 | F33: M 9 | G33: M 12 | H33: M 15 | I33: M 18 | J33: M 21 | K33: M 24 | L33: M 27 | M33: M 30 | N33: M 33 | O33: M 36 | P33: M 39 | Q33: M 42 | R33: M 45 | S33: M 48 | T33: M 51 | U33: M 54 | V33: M 57 | W33: M 60 | X33: M 63 | Y33: M 66 | Z33: M 69 | AA33: M 72 | AB33: M 75 | AC33: M 78 | AD33: M 81 | AE33: M 84 | AF33: M 87 | AG33: M 90 | AH33: M 93 | AI33: M 96 | AJ33: M 99 | AK33: M 102 | AL33: M 105 | AM33: M 108 | AN33: M 111 | AO33: M 114 | AP33: M 117 | AQ33: M 120 | AR33: M 123 | AS33: M 126 | AT33: M 129
B34: Green Square | C34: =SUM(D34:ZZ34) -> 592.63947 | D34: =+D28/((1+'Green Square'!$C$72)^'Green Square'!E$73) -> 0 | E34: =+E28/((1+'Green Square'!$C$72)^'Green Square'!F$73) -> 0 | F34: =+F28/((1+'Green Square'!$C$72)^'Green Square'!G$73) -> 0 | G34: =+G28/((1+'Green Square'!$C$72)^'Green Square'!H$73) -> 0 | H34: =+H28/((1+'Green Square'!$C$72)^'Green Square'!I$73) -> 19.525258 | I34: =+I28/((1+'Green Square'!$C$72)^'Green Square'!J$73) -> 24.942759 | J34: =+J28/((1+'Green Square'!$C$72)^'Green Square'!K$73) -> 46.203808 | K34: =+K28/((1+'Green Square'!$C$72)^'Green Square'!L$73) -> 32.680355 | ... AA34: =+AA28/((1+'Green Square'!$C$72)^'Green Square'!AB$73) -> 0 | AB34: =+AF28/((1+'Green Square'!$C$72)^'Green Square'!AC$73) -> 0 | AC34: =+AG28/((1+'Green Square'!$C$72)^'Green Square'!AD$73) -> 0 | AD34: =+AH28/((1+'Green Square'!$C$72)^'Green Square'!AE$73) -> 0 | AE34: =+AI28/((1+'Green Square'!$C$72)^'Green Square'!AF$73) -> 0 | AF34: =+AJ28/((1+'Green Square'!$C$72)^'Green Square'!AG$73) -> 0 | AG34: =+AK28/((1+'Green Square'!$C$72)^'Green Square'!AH$73) -> 0 | AH34: =+AL28/((1+'Green Square'!$C$72)^'Green Square'!AI$73) -> 0 | AI34: =+AM28/((1+'Green Square'!$C$72)^'Green Square'!AJ$73) -> 0 | ... AT34: =+AX28/((1+'Green Square'!$C$72)^'Green Square'!AU$73) -> 0
B35: L'avenir | C35: =SUM(D35:ZZ35) -> 565.10474 | D35: =+D29/((1+'Green Square'!$C$72)^'Green Square'!E$73) -> 0 | E35: =+E29/((1+'Green Square'!$C$72)^'Green Square'!F$73) -> 0 | F35: =+F29/((1+'Green Square'!$C$72)^'Green Square'!G$73) -> 0 | G35: =+G29/((1+'Green Square'!$C$72)^'Green Square'!H$73) -> 0 | H35: =+H29/((1+'Green Square'!$C$72)^'Green Square'!I$73) -> 0 | I35: =+I29/((1+'Green Square'!$C$72)^'Green Square'!J$73) -> 0 | J35: =+J29/((1+'Green Square'!$C$72)^'Green Square'!K$73) -> 18.287079 | K35: =+K29/((1+'Green Square'!$C$72)^'Green Square'!L$73) -> 23.361034 | ... AA35: =+AA29/((1+'Green Square'!$C$72)^'Green Square'!AB$73) -> 0 | AB35: =+AF29/((1+'Green Square'!$C$72)^'Green Square'!AC$73) -> 0 | AC35: =+AG29/((1+'Green Square'!$C$72)^'Green Square'!AD$73) -> 0 | AD35: =+AH29/((1+'Green Square'!$C$72)^'Green Square'!AE$73) -> 0 | AE35: =+AI29/((1+'Green Square'!$C$72)^'Green Square'!AF$73) -> 0 | AF35: =+AJ29/((1+'Green Square'!$C$72)^'Green Square'!AG$73) -> 0 | AG35: =+AK29/((1+'Green Square'!$C$72)^'Green Square'!AH$73) -> 0 | AH35: =+AL29/((1+'Green Square'!$C$72)^'Green Square'!AI$73) -> 0 | AI35: =+AM29/((1+'Green Square'!$C$72)^'Green Square'!AJ$73) -> 0 | ... AT35: =+AX29/((1+'Green Square'!$C$72)^'Green Square'!AU$73) -> 0
B36: Total | C36: =SUM(C34:C35) -> 1157.7442 | D36: =SUM(D34:D35) -> 0 | E36: =SUM(E34:E35) -> 0 | F36: =SUM(F34:F35) -> 0 | G36: =SUM(G34:G35) -> 0 | H36: =SUM(H34:H35) -> 19.525258 | I36: =SUM(I34:I35) -> 24.942759 | J36: =SUM(J34:J35) -> 64.490888 | ... AT36: =SUM(AT34:AT35) -> 0
B38: NET CASH FLOW -MEGP
B39: Project | C39: Total Sales | D39: M 3 | E39: M 6 | F39: M 9 | G39: M 12 | H39: M 15 | I39: M 18 | J39: M 21 | K39: M 24 | L39: M 27 | M39: M 30 | N39: M 33 | O39: M 36 | P39: M 39 | Q39: M 42 | R39: M 45 | S39: M 48 | T39: M 51 | U39: M 54 | V39: M 57 | W39: M 60 | X39: M 63 | Y39: M 66 | Z39: M 69 | AA39: M 72 | AB39: M 75 | AC39: M 78 | AD39: M 81 | AE39: M 84 | AF39: M 87 | AG39: M 90 | AH39: M 93 | AI39: M 96 | AJ39: M 99 | AK39: M 102 | AL39: M 105 | AM39: M 108 | AN39: M 111 | AO39: M 114 | AP39: M 117 | AQ39: M 120 | AR39: M 123 | AS39: M 126 | AT39: M 129
B40: Green Square | C40: =SUM(D40:ZZ40) -> 375.44753 | D40: =D16-D28 -> -12.5 | E40: =E16-E28 -> -12.5 | F40: =F16-F28 -> 2.6392375 | G40: =G16-G28 -> 17.778475 | H40: =H16-H28 -> -1.4879938 | I40: =I16-I28 -> 7.3855375 | J40: =J16-J28 -> -20.74569 | K40: =K16-K28 -> -3.9978306 | ... AT40: =AT16-AT28 -> 0
B41: L'avenir | C41: =SUM(D41:ZZ41) -> 595.29293 | D41: =D17-D29 -> 0 | E41: =E17-E29 -> 0 | F41: =F17-F29 -> 0 | G41: =G17-G29 -> 0 | H41: =H17-H29 -> -6.88435 | I41: =I17-I29 -> 11.2313 | J41: =J17-J29 -> 10.260825 | K41: =K17-K29 -> 13.65839 | ... AT41: =AT17-AT29 -> 0
B42: Total | C42: =SUM(C40:C41) -> 970.74046 | D42: =SUM(D40:D41) -> -12.5 | E42: =SUM(E40:E41) -> -12.5 | F42: =SUM(F40:F41) -> 2.6392375 | G42: =SUM(G40:G41) -> 17.778475 | H42: =SUM(H40:H41) -> -8.3723438 | I42: =SUM(I40:I41) -> 18.616837 | J42: =SUM(J40:J41) -> -10.484865 | ... AT42: =SUM(AT40:AT41) -> 0
B44: NPV NET CASH FLOW -MEGP
B45: Project | C45: Total Sales | D45: M 3 | E45: M 6 | F45: M 9 | G45: M 12 | H45: M 15 | I45: M 18 | J45: M 21 | K45: M 24 | L45: M 27 | M45: M 30 | N45: M 33 | O45: M 36 | P45: M 39 | Q45: M 42 | R45: M 45 | S45: M 48 | T45: M 51 | U45: M 54 | V45: M 57 | W45: M 60 | X45: M 63 | Y45: M 66 | Z45: M 69 | AA45: M 72 | AB45: M 75 | AC45: M 78 | AD45: M 81 | AE45: M 84 | AF45: M 87 | AG45: M 90 | AH45: M 93 | AI45: M 96 | AJ45: M 99 | AK45: M 102 | AL45: M 105 | AM45: M 108 | AN45: M 111 | AO45: M 114 | AP45: M 117 | AQ45: M 120 | AR45: M 123 | AS45: M 126 | AT45: M 129
B46: Green Square | C46: =SUM(D46:ZZ46) -> 241.24144 | D46: =+D40/((1+'Green Square'!$C$72)^'Green Square'!E$73) -> -12.09717 | E46: =+E40/((1+'Green Square'!$C$72)^'Green Square'!F$73) -> -11.707323 | F46: =+F40/((1+'Green Square'!$C$72)^'Green Square'!G$73) -> 2.3922129 | G46: =+G40/((1+'Green Square'!$C$72)^'Green Square'!H$73) -> 15.595154 | H46: =+H40/((1+'Green Square'!$C$72)^'Green Square'!I$73) -> -1.263194 | I46: =+I40/((1+'Green Square'!$C$72)^'Green Square'!J$73) -> 6.0677102 | J46: =+J40/((1+'Green Square'!$C$72)^'Green Square'!K$73) -> -16.494699 | K46: =+K40/((1+'Green Square'!$C$72)^'Green Square'!L$73) -> -3.0762009 | ... AT46: =+AT40/((1+'Green Square'!$C$72)^'Green Square'!AU$73) -> 0
B47: L'avenir | C47: =SUM(D47:ZZ47) -> 328.55309 | D47: =+D41/((1+'Green Square'!$C$72)^'Green Square'!E$73) -> 0 | E47: =+E41/((1+'Green Square'!$C$72)^'Green Square'!F$73) -> 0 | F47: =+F41/((1+'Green Square'!$C$72)^'Green Square'!G$73) -> 0 | G47: =+G41/((1+'Green Square'!$C$72)^'Green Square'!H$73) -> 0 | H47: =+H41/((1+'Green Square'!$C$72)^'Green Square'!I$73) -> -5.8442916 | I47: =+I41/((1+'Green Square'!$C$72)^'Green Square'!J$73) -> 9.2272598 | J47: =+J41/((1+'Green Square'!$C$72)^'Green Square'!K$73) -> 8.1582835 | K47: =+K41/((1+'Green Square'!$C$72)^'Green Square'!L$73) -> 10.509688 | ... AT47: =+AT41/((1+'Green Square'!$C$72)^'Green Square'!AU$73) -> 0
...

Sheet Cash In Flow Summary
B1: Sales - 20% RETAINED
B2: MEGP
B3: Project | C3: Total Sales | D3: M 3 | E3: M 6 | F3: M 9 | G3: M 12 | H3: M 15 | I3: M 18 | J3: M 21 | K3: M 24 | L3: M 27 | M3: M 30 | N3: M 33 | O3: M 36 | P3: M 39 | Q3: M 42 | R3: M 45 | S3: M 48 | T3: M 51 | U3: M 54 | V3: M 57 | W3: M 60 | X3: M 63 | Y3: M 66 | Z3: M 69 | AA3: M 72 | AB3: M 75 | AC3: M 78 | AD3: M 81 | AE3: M 84 | AF3: M 87 | AG3: M 90 | AH3: M 93 | AI3: M 96 | AJ3: M 99 | AK3: M 102 | AL3: M 105 | AM3: M 108 | AN3: M 111 | AO3: M 114 | AP3: M 117 | AQ3: M 120 | AR3: M 123 | AS3: M 126 | AT3: M 129
B4: Green Square | C4: =SUM(D4:ZZ4) -> 2252.979 | D4: ='Green Square'!E70/1000 -> 0 | E4: ='Green Square'!F70/1000 -> 0 | F4: ='Green Square'!G70/1000 -> 15.139238 | G4: ='Green Square'!H70/1000 -> 30.278475 | H4: ='Green Square'!I70/1000 -> 46.512006 | I4: ='Green Square'!J70/1000 -> 62.745537 | J4: ='Green Square'!K70/1000 -> 62.3657 | K4: ='Green Square'!L70/1000 -> 63.473559 | ... AT4: ='Green Square'!AU70/1000 -> 0
B5: L'avenir | C5: =SUM(D5:ZZ5) -> 2673.7357 | D5: ='L''avenir'!E70/1000 -> 0 | E5: ='L''avenir'!F70/1000 -> 0 | F5: ='L''avenir'!G70/1000 -> 0 | G5: ='L''avenir'!H70/1000 -> 0 | H5: ='L''avenir'!I70/1000 -> 18.11565 | I5: ='L''avenir'!J70/1000 -> 36.2313 | J5: ='L''avenir'!K70/1000 -> 58.260825 | K5: ='L''avenir'!L70/1000 -> 69.01839 | ... AT5: ='L''avenir'!AU70/1000 -> 0
C6: =SUM(C4:C5) -> 4926.7148 | D6: =SUM(D4:D5) -> 0 | E6: =SUM(E4:E5) -> 0 | F6: =SUM(F4:F5) -> 15.139238 | G6: =SUM(G4:G5) -> 30.278475 | H6: =SUM(H4:H5) -> 64.627656 | I6: =SUM(I4:I5) -> 98.976838 | J6: =SUM(J4:J5) -> 120.62653 | ... AT6: =SUM(AT4:AT5) -> 0
B8: Project | C8: Total Sales NPV | D8: M 3 | E8: M 6 | F8: M 9 | G8: M 12 | H8: M 15 | I8: M 18 | J8: M 21 | K8: M 24 | L8: M 27 | M8: M 30 | N8: M 33 | O8: M 36 | P8: M 39 | Q8: M 42 | R8: M 45 | S8: M 48 | T8: M 51 | U8: M 54 | V8: M 57 | W8: M 60 | X8: M 63 | Y8: M 66 | Z8: M 69 | AA8: M 72 | AB8: M 75 | AC8: M 78 | AD8: M 81 | AE8: M 84 | AF8: M 87 | AG8: M 90 | AH8: M 93 | AI8: M 96 | AJ8: M 99 | AK8: M 102 | AL8: M 105 | AM8: M 108 | AN8: M 111 | AO8: M 114 | AP8: M 117 | AQ8: M 120 | AR8: M 123 | AS8: M 126 | AT8: M 129
B9: Green Square | C9: =SUM(D9:ZZ9) -> 1416.8308 | D9: ='Green Square'!E71/1000 -> 0 | E9: ='Green Square'!F71/1000 -> 0 | F9: ='Green Square'!G71/1000 -> 13.722251 | G9: ='Green Square'!H71/1000 -> 26.560066 | H9: ='Green Square'!I71/1000 -> 39.48517 | I9: ='Green Square'!J71/1000 -> 51.549632 | J9: ='Green Square'!K71/1000 -> 49.586369 | K9: ='Green Square'!L71/1000 -> 48.840843 | ... AT9: ='Green Square'!AU71/1000 -> 0
B10: L'avenir | C10: =SUM(D10:ZZ10) -> 1549.3963 | D10: ='L''avenir'!E71/1000 -> 0 | E10: ='L''avenir'!F71/1000 -> 0 | F10: ='L''avenir'!G71/1000 -> 0 | G10: ='L''avenir'!H71/1000 -> 0 | H10: ='L''avenir'!I71/1000 -> 15.378814 | I10: ='L''avenir'!J71/1000 -> 29.766422 | J10: ='L''avenir'!K71/1000 -> 46.322623 | K10: ='L''avenir'!L71/1000 -> 53.10741 | ... AT10: ='L''avenir'!AU71/1000 -> 0
C11: =SUM(C9:C10) -> 2966.2271 | D11: =SUM(D9:D10) -> 0 | E11: =SUM(E9:E10) -> 0 | F11: =SUM(F9:F10) -> 13.722251 | G11: =SUM(G9:G10) -> 26.560066 | H11: =SUM(H9:H10) -> 54.863984 | I11: =SUM(I9:I10) -> 81.316054 | J11: =SUM(J9:J10) -> 95.908992 | ... AT11: =SUM(AT9:AT10) -> 0
B13: Accumulated MEGP
B14: Project | C14: Total Sales | D14: M 3 | E14: M 6 | F14: M 9 | G14: M 12 | H14: M 15 | I14: M 18 | J14: M 21 | K14: M 24 | L14: M 27 | M14: M 30 | N14: M 33 | O14: M 36 | P14: M 39 | Q14: M 42 | R14: M 45 | S14: M 48 | T14: M 51 | U14: M 54 | V14: M 57 | W14: M 60 | X14: M 63 | Y14: M 66 | Z14: M 69 | AA14: M 72 | AB14: M 75 | AC14: M 78 | AD14: M 81 | AE14: M 84 | AF14: M 87 | AG14: M 90 | AH14: M 93 | AI14: M 96 | AJ14: M 99 | AK14: M 102 | AL14: M 105 | AM14: M 108 | AN14: M 111 | AO14: M 114 | AP14: M 117 | AQ14: M 120 | AR14: M 123 | AS14: M 126 | AT14: M 129
B15: Green Square | C15: =MAX(D15:ZZ15) -> 2252.979 | D15: =D4 -> 0 | E15: =D15+E4 -> 0 | F15: =E15+F4 -> 15.139238 | G15: =F15+G4 -> 45.417713 | H15: =G15+H4 -> 91.929719 | I15: =H15+I4 -> 154.67526 | J15: =I15+J4 -> 217.04096 | K15: =J15+K4 -> 280.51452 | L15: =K15+L4 -> 360.84336 | ... AT15: =AS15+AT4 -> 2252.979
B16: L'avenir | C16: =MAX(D16:ZZ16) -> 2673.7357 | D16: =D5 -> 0 | E16: =D16+E5 -> 0 | F16: =E16+F5 -> 0 | G16: =F16+G5 -> 0 | H16: =G16+H5 -> 18.11565 | I16: =H16+I5 -> 54.34695 | J16: =I16+J5 -> 112.60778 | K16: =J16+K5 -> 181.62616 | L16: =K16+L5 -> 248.71371 | ... AT16: =AS16+AT5 -> 2673.7357
C17: =SUM(C15:C16) -> 4926.7148 | D17: =SUM(D15:D16) -> 0 | E17: =SUM(E15:E16) -> 0 | F17: =SUM(F15:F16) -> 15.139238 | G17: =SUM(G15:G16) -> 45.417713 | H17: =SUM(H15:H16) -> 110.04537 | I17: =SUM(I15:I16) -> 209.02221 | J17: =SUM(J15:J16) -> 329.64873 | ... AT17: =SUM(AT15:AT16) -> 4926.7148
B19: Project | C19: Total Sales NPV | D19: M 3 | E19: M 6 | F19: M 9 | G19: M 12 | H19: M 15 | I19: M 18 | J19: M 21 | K19: M 24 | L19: M 27 | M19: M 30 | N19: M 33 | O19: M 36 | P19: M 39 | Q19: M 42 | R19: M 45 | S19: M 48 | T19: M 51 | U19: M 54 | V19: M 57 | W19: M 60 | X19: M 63 | Y19: M 66 | Z19: M 69 | AA19: M 72 | AB19: M 75 | AC19: M 78 | AD19: M 81 | AE19: M 84 | AF19: M 87 | AG19: M 90 | AH19: M 93 | AI19: M 96 | AJ19: M 99 | AK19: M 102 | AL19: M 105 | AM19: M 108 | AN19: M 111 | AO19: M 114 | AP19: M 117 | AQ19: M 120 | AR19: M 123 | AS19: M 126 | AT19: M 129
B20: Green Square | C20: =MAX(D20:ZZ20) -> 1416.8308 | D20: =D9 -> 0 | E20: =D20+E9 -> 0 | F20: =E20+F9 -> 13.722251 | G20: =F20+G9 -> 40.282317 | H20: =G20+H9 -> 79.767487 | I20: =H20+I9 -> 131.31712 | J20: =I20+J9 -> 180.90349 | K20: =J20+K9 -> 229.74433 | L20: =K20+L9 -> 289.56285 | ... AT20: =AS20+AT9 -> 1416.8308
B21: L'avenir | C21: =MAX(D21:ZZ21) -> 1549.3963 | D21: =D10 -> 0 | E21: =D21+E10 -> 0 | F21: =E21+F10 -> 0 | G21: =F21+G10 -> 0 | H21: =G21+H10 -> 15.378814 | I21: =H21+I10 -> 45.145237 | J21: =I21+J10 -> 91.46786 | K21: =J21+K10 -> 144.57527 | L21: =K21+L10 -> 194.53338 | ... AT21: =AS21+AT10 -> 1549.3963
C22: =SUM(C20:C21) -> 2966.2271 | D22: =SUM(D20:D21) -> 0 | E22: =SUM(E20:E21) -> 0 | F22: =SUM(F20:F21) -> 13.722251 | G22: =SUM(G20:G21) -> 40.282317 | H22: =SUM(H20:H21) -> 95.146301 | I22: =SUM(I20:I21) -> 176.46236 | J22: =SUM(J20:J21) -> 272.37135 | ... AT22: =SUM(AT20:AT21) -> 2966.2271
B27: 100% Sales
B28: Project | C28: Total Sales | D28: M 3 | E28: M 6 | F28: M 9 | G28: M 12 | H28: M 15 | I28: M 18 | J28: M 21 | K28: M 24 | L28: M 27 | M28: M 30 | N28: M 33 | O28: M 36 | P28: M 39 | Q28: M 42 | R28: M 45 | S28: M 48 | T28: M 51 | U28: M 54 | V28: M 57 | W28: M 60 | X28: M 63 | Y28: M 66 | Z28: M 69 | AA28: M 72 | AB28: M 75 | AC28: M 78 | AD28: M 81 | AE28: M 84 | AF28: M 87 | AG28: M 90 | AH28: M 93 | AI28: M 96 | AJ28: M 99 | AK28: M 102 | AL28: M 105 | AM28: M 108 | AN28: M 111 | AO28: M 114 | AP28: M 117 | AQ28: M 120 | AR28: M 123 | AS28: M 126 | AT28: M 129
