Workbook

Sheet Summary
A1: L'avenir EL-Mostakbal City -Summary
A2: Land Area: | B2: m² | C2: 14910 | D2: Construction Start: | E2: =Assumptions!$C$12 -> 7 | F2: Month
A3: footprint % : | C3: =C4/C2 -> 0.3 | D3: Construction Duration : | E3: =Assumptions!$C$13 -> 36 | F3: Month
A4: footprint : | B4: m² | C4: 4473 | D4: Project Delivery : | E4: =E3+E2-1 -> 42 | F4: Month
A5: Height: | C5: G+2
A6: Retail: | B6: m² | C6: =C4 -> 4473 | D6: Sales Start: | E6: =Assumptions!$C$10 -> 1 | F6: Month
A7: Offices: | B7: m² | C7: 8946 | D7: Maximum Cash Shortage : | E7: =MIN(C49:AT49) -> -102.01806 | F7: MEGP
A8: Total BUA: | B8: m² | C8: =C7+C6 -> 13419
A9: RETAINED %: | C9: 0.2
A10: Downpayment | C10: =Assumptions!$C$27 -> 200
C11: MEGP | D11: NPV-With DP | E11: NPV-Without DP
A12: CASH INFLOW JALOUR | C12: =SUM(C13:C14) -> 1503.9764 | D12: ='Net Cash Flow -With DP'!C16 -> 994.8063 | E12: ='Net Cash Flow -Without DP'!C16 -> 1018.7699
A13: COMMERCIAL | C13: =C32-C36 -> 605.74205
A14: ADMIN | C14: =C33-C37 -> 898.23431
C16: MEGP | D16: NPV-With DP | E16: NPV-Without DP
A17: CASH OUTFLOW JALOUR | C17: =SUM(C18:C20) -> -862.28343 | D17: =-'Net Cash Flow -With DP'!C24 -> -644.2194 | E17: =-'Net Cash Flow -Without DP'!C24 -> -644.2194
A18: Construction Cost | C18: =-'Cash Out Detail'!C28/1000000 -> -650.76
A19: Sales Commission | B19: 0.04 | C19: =-'Cash Out Detail'!C31/1000000 -> -106.94943
A20: SGA& Others Cost | B20: 0.15 | C20: =-'Cash Out Detail'!C34/1000000 -> -104.574
C22: MEGP | D22: NPV-With DP | E22: NPV-Without DP | F22: Diff
A23: NET CASH FLOW JALOUR -MEGP | C23: =C12+C17 -> 641.69293 | D23: ='Net Cash Flow -With DP'!C40 -> 350.5869 | E23: ='Net Cash Flow -Without DP'!C40 -> 374.55052 | F23: =D23-E23 -> -23.963617
A25: Note: NPV figures are as at this project's own start (M1 = sales launch), not the shared calendar start used in the combined workbook. All time axes are shifted back 12 months.
A26: Note: 'Construction Cost', 'Sales Commission' and 'SGA' above are picked up exactly as in the original Summary sheet (see Cash Out Detail check rows).
A27: Total Sales 100% | C27: =SUM(C28:C29) -> 3342.1697
A28: COMMERCIAL | C28: =C32*100/80 -> 1346.0934
A29: ADMIN | C29: =C33*100/80 -> 1996.0763
A31: Total Sales 80% | C31: =SUM(C32:C33) -> 2673.7357
A32: COMMERCIAL | C32: ='L''avenir'!D24/1000 -> 1076.8747
A33: ADMIN | C33: ='L''avenir'!D25/1000 -> 1596.861
A35: ALAHLY - SABBOUR % | B35: 0.35 | C35: =SUM(C36:C37) -> 1169.7594
A36: COMMERCIAL | C36: =C28*B35 -> 471.1327
A37: ADMIN | C37: =C29*B35 -> 698.62669
C44: ='Net Cash Flow -With DP'!D3 -> M -9 | D44: ='Net Cash Flow -With DP'!E3 -> M -6 | E44: ='Net Cash Flow -With DP'!F3 -> M -3 | F44: ='Net Cash Flow -With DP'!G3 -> M 0 | G44: ='Net Cash Flow -With DP'!H3 -> M 3 | H44: ='Net Cash Flow -With DP'!I3 -> M 6 | I44: ='Net Cash Flow -With DP'!J3 -> M 9 | J44: ='Net Cash Flow -With DP'!K3 -> M 12 | ... AT44: ='Net Cash Flow -With DP'!AU3 -> 0
A45: Total Collections MEGP | C45: ='Net Cash Flow -With DP'!D4 -> 0 | D45: ='Net Cash Flow -With DP'!E4 -> 0 | E45: ='Net Cash Flow -With DP'!F4 -> 0 | F45: ='Net Cash Flow -With DP'!G4 -> 0 | G45: ='Net Cash Flow -With DP'!H4 -> 18.11565 | H45: ='Net Cash Flow -With DP'!I4 -> 36.2313 | I45: ='Net Cash Flow -With DP'!J4 -> 58.260825 | J45: ='Net Cash Flow -With DP'!K4 -> 69.01839 | ... AT45: ='Net Cash Flow -With DP'!AU4 -> 0
A46: ALAHLY - SABBOUR Payments MEGP | C46: =-'Net Cash Flow -With DP'!D8 -> 0 | D46: =-'Net Cash Flow -With DP'!E8 -> 0 | E46: =-'Net Cash Flow -With DP'!F8 -> 0 | F46: =-'Net Cash Flow -With DP'!G8 -> -85 | G46: =-'Net Cash Flow -With DP'!H8 -> -22.5 | H46: =-'Net Cash Flow -With DP'!I8 -> -22.5 | I46: =-'Net Cash Flow -With DP'!J8 -> -22.5 | J46: =-'Net Cash Flow -With DP'!K8 -> -22.5 | ... AT46: =-'Net Cash Flow -With DP'!AU8 -> 0
A47: CASH OUT FLOW CAPEX -MEGP | C47: =-'Net Cash Flow -With DP'!D20 -> 0 | D47: =-'Net Cash Flow -With DP'!E20 -> 0 | E47: =-'Net Cash Flow -With DP'!F20 -> 0 | F47: =-'Net Cash Flow -With DP'!G20 -> 0 | G47: =-'Net Cash Flow -With DP'!H20 -> 0 | H47: =-'Net Cash Flow -With DP'!I20 -> 0 | I47: =-'Net Cash Flow -With DP'!J20 -> -23 | J47: =-'Net Cash Flow -With DP'!K20 -> -30.36 | ... AT47: =-'Net Cash Flow -With DP'!AU20 -> 0
A48: Net Cash Flow | C48: =SUM(C45:C47) -> 0 | D48: =SUM(D45:D47) -> 0 | E48: =SUM(E45:E47) -> 0 | F48: =SUM(F45:F47) -> -85 | G48: =SUM(G45:G47) -> -4.38435 | H48: =SUM(H45:H47) -> 13.7313 | I48: =SUM(I45:I47) -> 12.760825 | J48: =SUM(J45:J47) -> 16.15839 | ... AT48: =SUM(AT45:AT47) -> 0
A49: Net Cash Flow-Accum | C49: =C48 -> 0 | D49: =C49+D48 -> 0 | E49: =D49+E48 -> 0 | F49: =E49+F48 -> -85 | G49: =F49+G48 -> -89.38435 | H49: =G49+H48 -> -75.65305 | I49: =H49+I48 -> -62.892225 | J49: =I49+J48 -> -46.733835 | K49: =J49+K48 -> -85.13881 | ... AT49: =AS49+AT48 -> 595.29293

Sheet Assumptions
A1: L'AVENIR - ASSUMPTIONS AND TIMELINE
A2: Standalone model. Month 1 (M1) is this project's own sales launch. Blue = input, black = formula or fixed reference. Cash flows are in MEGP unless stated.
A4: NPV SETTINGS
A5: Cost of capital (annual) | C5: 0.14 | D5: Carried over unchanged from the combined model, where it was a single shared input.
A6: Quarter column (month at end of quarter) | E6: M -9 | F6: M -6 | G6: M -3 | H6: M 0 | I6: M 3 | J6: M 6 | K6: M 9 | L6: M 12 | M6: M 15 | N6: M 18 | O6: M 21 | P6: M 24 | Q6: M 27 | R6: M 30 | S6: M 33 | T6: M 36 | U6: M 39 | V6: M 42 | W6: M 45 | X6: M 48 | Y6: M 51 | Z6: M 54 | AA6: M 57 | AB6: M 60 | AC6: M 63 | AD6: M 66 | AE6: M 69 | AF6: M 72 | AG6: M 75 | AH6: M 78 | AI6: M 81 | AJ6: M 84 | AK6: M 87 | AL6: M 90 | AM6: M 93 | AN6: M 96 | AO6: M 99 | AP6: M 102 | AQ6: M 105 | AR6: M 108 | AS6: M 111
A7: Discount period (years from the start of M1) | E7: =(3-$C$15)/12 -> -0.75 | F7: =0.25+E7 -> -0.5 | G7: =0.25+F7 -> -0.25 | H7: =0.25+G7 -> 0 | I7: =0.25+H7 -> 0.25 | J7: =0.25+I7 -> 0.5 | K7: =0.25+J7 -> 0.75 | L7: =0.25+K7 -> 1 | M7: =0.25+L7 -> 1.25 | ... AS7: =0.25+AR7 -> 9.25
A9: TIMELINE (months counted from this project's own M1)
A10: Sales start (launch) month | C10: 1 | D10: M1 = launch. Equals original Sales Start less the calendar offset below.
A11: Construction start offset from launch (months) | C11: 6 | D11: Gap kept from the original model: construction start less sales start on the shared calendar.
A12: Construction start month | C12: =$C$10+$C$11 -> 7 | D12: Drives the stage schedule on 'Cash Out Detail'.
A13: Construction duration (months) | C13: 36
A14: Project delivery month (end of construction) | C14: =$C$12+$C$13-1 -> 42
A15: Calendar offset removed from the shared timeline (months) | C15: 12 | D15: Equals original Sales Start month less 1. Structural: it re-labels the axis and the discount months; do not overwrite.
A16: Original Sales Start month (shared calendar, for reference) | C16: 13
A17: Original Construction Start month (shared calendar, for reference) | C17: 19
A18: Unit handover month, original shared calendar (project sheet C5) | C18: 48
A19: Unit handover month, own timeline | C19: =$C$18-$C$15 -> 36 | D19: Feeds project sheet C5 (months-to-delivery row).
A21: COST SCALING (as picked up by the original Cash Out Detail)
A22: Construction cost multiple of the base stage schedule | C22: 8 | D22: Base 'Stage Schedule & Costs (2)' is the NURV build cost; this project is a multiple of it.
A23: Additional size multiple | C23: 1 | D23: None for this project (1.0).
A24: Combined multiple (information) | C24: =$C$22*$C$23 -> 8
A26: OTHER
A27: Downpayment shown on Summary (MEGP) | C27: 200 | D27: Was 'Summary'!B3:B5 on the combined sheet.

Sheet L'avenir
A1: L'AVENIR
B2: BUA (M²) | C2: RETAINED% | D2: Total | E2: M -9 | F2: M -6 | G2: M -3 | H2: M 0 | I2: M 3 | J2: M 6 | K2: M 9 | L2: M 12 | M2: M 15 | N2: M 18 | O2: M 21 | P2: M 24 | Q2: M 27 | R2: M 30 | S2: M 33 | T2: M 36 | U2: M 39 | V2: M 42 | W2: M 45 | X2: M 48 | Y2: M 51 | Z2: M 54 | AA2: M 57 | AB2: M 60 | AC2: M 63 | AD2: M 66 | AE2: M 69 | AF2: M 72 | AG2: M 75 | AH2: M 78 | AI2: M 81 | AJ2: M 84 | AK2: M 87 | AL2: M 90 | AM2: M 93 | AN2: M 96
A3: COMMERCIAL PRICE | E3: 200 | F3: 200 | G3: 225 | H3: 225 | I3: 250 | J3: 250 | K3: 275 | L3: 275 | M3: 300 | N3: 300 | O3: 330 | P3: 330 | Q3: 360 | R3: 360 | S3: 360 | T3: 360
A4: ADMIN PRICE | E4: 125 | F4: 125 | G4: 135 | H4: 135 | I4: 160 | J4: 160 | K4: 180 | L4: 180 | M4: 200 | N4: 200 | O4: 220 | P4: 220 | Q4: 240 | R4: 240 | S4: 240 | T4: 240
A5: DELIVERY DATE(month) | C5: =Assumptions!$C$19 -> 36 | E5: =IF(C5-3<0,0,C5-3) -> 33 | F5: =IF(E5-3<0,0,E5-3) -> 30 | G5: =IF(F5-3<0,0,F5-3) -> 27 | H5: =IF(G5-3<0,0,G5-3) -> 24 | I5: =IF(H5-3<0,0,H5-3) -> 21 | J5: =IF(I5-3<0,0,I5-3) -> 18 | K5: =IF(J5-3<0,0,J5-3) -> 15 | L5: =IF(K5-3<0,0,K5-3) -> 12 | M5: =IF(L5-3<0,0,L5-3) -> 9 | ... T5: =IF(S5-3<0,0,S5-3) -> 0
A6: TARGET SALES % COMM. | B6: 4473 | C6: 20 | I6: 10 | J6: 10 | K6: 10 | L6: 7 | M6: 7 | N6: 6 | O6: 5 | P6: 5 | Q6: 5 | R6: 5 | S6: 5 | T6: 5
A7: TARGET SALES % ADMIN | B7: 10437 | C7: 20 | I7: 15 | J7: 15 | K7: 10 | L7: 5 | M7: 5 | N7: 5 | O7: 5 | P7: 5 | Q7: 5 | R7: 5 | S7: 2.5 | T7: 2.5
A8: INSTALLMENTS (YRS) | I8: 8 | J8: 8 | K8: 8 | L8: 6 | M8: 6 | N8: 6 | O8: 4 | P8: 4 | Q8: 4 | R8: 3 | S8: 3 | T8: 2
A10: DOWN PAYMENT % | I10: 5 | J10: 5 | K10: 10 | L10: 10 | M10: 10 | N10: 10 | O10: 15 | P10: 15 | Q10: 15 | R10: 15 | S10: 20 | T10: 20
A11: 3 MONTHS % | I11: 5 | J11: 5 | K11: 10 | L11: 10 | M11: 10 | N11: 10 | O11: 15 | P11: 15 | Q11: 15 | R11: 15 | S11: 20 | T11: 20
A12: DELIVERY PAYMENT % | I12: 20 | J12: 20 | K12: 20 | L12: 20 | M12: 20 | N12: 20 | O12: 25 | P12: 25 | Q12: 25 | R12: 25 | S12: 25 | T12: 25
A14: YEAR 1 (4Q) % | I14: 10 | J14: 12 | K14: 12 | L14: 12 | M14: 15 | N14: 15 | O14: 15 | P14: 15 | Q14: 15 | R14: 15 | S14: 15 | T14: 15
A15: YEAR 2 (4Q) % | I15: 10 | J15: 12 | K15: 12 | L15: 12 | M15: 15 | N15: 15 | O15: 15 | P15: 15 | Q15: 15 | R15: 15 | S15: 10 | T15: 10
A16: YEAR 3 (4Q) % | I16: 10 | J16: 12 | K16: 12 | L16: 12 | M16: 15 | N16: 15 | O16: 7.5 | P16: 7.5 | Q16: 7.5 | R16: 7.5 | S16: 10 | T16: 10
A17: YEAR 4 (4Q) % | I17: 8 | J17: 10 | K17: 8 | L17: 8 | M17: 5 | N17: 5 | O17: 7.5 | P17: 7.5 | Q17: 7.5 | R17: 7.5 | S17: 0 | T17: 0
A18: YEAR 5 (4Q) % | I18: 8 | J18: 8 | K18: 8 | L18: 8 | M18: 5 | N18: 5 | O18: 0 | P18: 0 | Q18: 0 | R18: 0 | S18: 0 | T18: 0
A19: YEAR 6 (4Q) % | I19: 8 | J19: 8 | K19: 8 | L19: 8 | M19: 5 | N19: 5 | O19: 0 | P19: 0 | Q19: 0 | R19: 0 | S19: 0 | T19: 0
A20: YEAR 7 (4Q) % | I20: 8 | J20: 8 | K20: 0 | L20: 0 | M20: 0 | N20: 0 | O20: 0 | P20: 0 | Q20: 0 | R20: 0 | S20: 0 | T20: 0
A21: YEAR 8 (4Q) % | I21: 8 | J21: 0 | K21: 0 | L21: 0 | M21: 0 | N21: 0 | O21: 0 | P21: 0 | Q21: 0 | R21: 0 | S21: 0 | T21: 0
A24: Total Sales(COMMERCIAL) | D24: =SUM(E24:T24) -> 1076874.8 | E24: =E3*$B$6*(E6/100) -> 0 | F24: =F3*$B$6*(F6/100) -> 0 | G24: =G3*$B$6*(G6/100) -> 0 | H24: =H3*$B$6*(H6/100) -> 0 | I24: =I3*$B$6*(I6/100) -> 111825 | J24: =J3*$B$6*(J6/100) -> 111825 | K24: =K3*$B$6*(K6/100) -> 123007.5 | L24: =L3*$B$6*(L6/100) -> 86105.25 | ... T24: =T3*$B$6*(T6/100) -> 80514
A25: Total Sales (ADMIN) | D25: =SUM(E25:T25) -> 1596861 | E25: =E4*$B$7*(E7/100) -> 0 | F25: =F4*$B$7*(F7/100) -> 0 | G25: =G4*$B$7*(G7/100) -> 0 | H25: =H4*$B$7*(H7/100) -> 0 | I25: =I4*$B$7*(I7/100) -> 250488 | J25: =J4*$B$7*(J7/100) -> 250488 | K25: =K4*$B$7*(K7/100) -> 187866 | L25: =L4*$B$7*(L7/100) -> 93933 | ... T25: =T4*$B$7*(T7/100) -> 62622
A26: Total Sales | D26: =SUM(D24:D25) -> 2673735.8 | E26: =SUM(E24:E25) -> 0 | F26: =SUM(F24:F25) -> 0 | G26: =SUM(G24:G25) -> 0 | H26: =SUM(H24:H25) -> 0 | I26: =SUM(I24:I25) -> 362313 | J26: =SUM(J24:J25) -> 362313 | K26: =SUM(K24:K25) -> 310873.5 | ... T26: =SUM(T24:T25) -> 143136
E27: =E26 -> 0 | F27: =E27+F26 -> 0 | G27: =E27+G26 -> 0 | H27: =G27+H26 -> 0 | I27: =H27+I26 -> 362313 | J27: =I27+J26 -> 724626 | K27: =J27+K26 -> 1035499.5 | L27: =K27+L26 -> 1215537.8 | M27: =L27+M26 -> 1413840.8 | N27: =M27+N26 -> 1598724.8 | O27: =N27+O26 -> 1787336.2 | ... T27: =S27+T26 -> 2673735.8
G28: =G26*4% -> 0 | H28: =H26*4% -> 0 | I28: =I26*4% -> 14492.52 | J28: =J26*4% -> 14492.52 | K28: =K26*4% -> 12434.94 | L28: =L26*4% -> 7201.53 | M28: =M26*4% -> 7932.12 | N28: =N26*4% -> 7395.36 | ... T28: =T26*4% -> 5725.44
D29: Total | E29: M -9 | F29: M -6 | G29: M -3 | H29: M 0 | I29: M 3 | J29: M 6 | K29: M 9 | L29: M 12 | M29: M 15 | N29: M 18 | O29: M 21 | P29: M 24 | Q29: M 27 | R29: M 30 | S29: M 33 | T29: M 36 | U29: M 39 | V29: M 42 | W29: M 45 | X29: M 48 | Y29: M 51 | Z29: M 54 | AA29: M 57 | AB29: M 60 | AC29: M 63 | AD29: M 66 | AE29: M 69 | AF29: M 72 | AG29: M 75 | AH29: M 78 | AI29: M 81 | AJ29: M 84 | AK29: M 87 | AL29: M 90 | AM29: M 93 | AN29: M 96
A30: Bulk Payments
A31: DOWN PAYMENT (COMMERCIAL) | D31: =SUM(E31:AZ31) -> 128039.62 | E31: =E3*$B$6*(E6/100)*E10/100 -> 0 | F31: =F3*$B$6*(F6/100)*F10/100 -> 0 | G31: =G3*$B$6*(G6/100)*G10/100 -> 0 | H31: =H3*$B$6*(H6/100)*H10/100 -> 0 | I31: =I3*$B$6*(I6/100)*I10/100 -> 5591.25 | J31: =J3*$B$6*(J6/100)*J10/100 -> 5591.25 | K31: =K3*$B$6*(K6/100)*K10/100 -> 12300.75 | L31: =L3*$B$6*(L6/100)*L10/100 -> 8610.525 | ... V31: =V3*$B$6*(V6/100)*V10/100 -> 0
A32: DOWN PAYMENT (ADMIN) | D32: =SUM(E32:AZ32) -> 171166.8 | E32: =E4*$B$7*(E7/100)*E10/100 -> 0 | F32: =F4*$B$7*(F7/100)*F10/100 -> 0 | G32: =G4*$B$7*(G7/100)*G10/100 -> 0 | H32: =H4*$B$7*(H7/100)*H10/100 -> 0 | I32: =I4*$B$7*(I7/100)*I10/100 -> 12524.4 | J32: =J4*$B$7*(J7/100)*J10/100 -> 12524.4 | K32: =K4*$B$7*(K7/100)*K10/100 -> 18786.6 | L32: =L4*$B$7*(L7/100)*L10/100 -> 9393.3 | ... V32: =V4*$B$7*(V7/100)*V10/100 -> 0
A33: 3 MONTHS (COMMERCIAL) | D33: =SUM(E33:AZ33) -> 128039.62 | F33: =E31 -> 0 | G33: =F31 -> 0 | H33: =G31 -> 0 | I33: =H31 -> 0 | J33: =I31 -> 5591.25 | K33: =J31 -> 5591.25 | L33: =K31 -> 12300.75 | M33: =L31 -> 8610.525 | ... V33: =U31 -> 0
A34: 3 MONTHS (ADMIN) | D34: =SUM(E34:AZ34) -> 171166.8 | F34: =E32 -> 0 | G34: =F32 -> 0 | H34: =G32 -> 0 | I34: =H32 -> 0 | J34: =I32 -> 12524.4 | K34: =J32 -> 12524.4 | L34: =K32 -> 18786.6 | M34: =L32 -> 9393.3 | ... V34: =U32 -> 0
A35: DELIVERY PAYMENT (COMMERCIAL) | D35: =SUM(E35:AZ35) -> 238858.2 | S35: =SUM(E85:S85) -> 218729.7 | T35: =SUM(T85) -> 20128.5 | U35: =SUM(U85) -> 0 | V35: =SUM(V85) -> 0 | W35: =SUM(W85) -> 0
A36: DELIVERY PAYMENT (ADMIN) | D36: =SUM(E36:AZ36) -> 349639.5 | S36: =SUM(E86:S86) -> 333984 | T36: =SUM(T86) -> 15655.5 | U36: =SUM(U86) -> 0 | V36: =SUM(V86) -> 0 | W36: =SUM(W86) -> 0
A37: Instalments | D37: =SUM(E37:AZ37) -> 0
A38: MONTH -9 (COMMERCIAL) | D38: =SUM(E38:AZ38) -> 0 | G38: =$E$24*$E$14/100/4 -> 0 | H38: =$E$24*$E$14/100/4 -> 0 | I38: =$E$24*$E$14/100/4 -> 0 | J38: =$E$24*$E$14/100/4 -> 0 | K38: =$E$24*$E$15/100/4 -> 0 | L38: =$E$24*$E$15/100/4 -> 0 | M38: =$E$24*$E$15/100/4 -> 0 | N38: =$E$24*$E$15/100/4 -> 0 | O38: =$E$24*$E$16/100/4 -> 0 | P38: =$E$24*$E$16/100/4 -> 0 | Q38: =$E$24*$E$16/100/4 -> 0 | R38: =$E$24*$E$16/100/4 -> 0 | S38: =$E$24*$E$17/100/4 -> 0 | T38: =$E$24*$E$17/100/4 -> 0 | U38: =$E$24*$E$17/100/4 -> 0 | V38: =$E$24*$E$17/100/4 -> 0 | W38: =$E$24*$E$18/100/4 -> 0 | X38: =$E$24*$E$18/100/4 -> 0 | Y38: =$E$24*$E$18/100/4 -> 0 | Z38: =$E$24*$E$18/100/4 -> 0 | AA38: =$E$24*$E$19/100/4 -> 0 | AB38: =$E$24*$E$19/100/4 -> 0 | AC38: =$E$24*$E$19/100/4 -> 0 | AD38: =$E$24*$E$19/100/4 -> 0 | AE38: =$E$24*$E$20/100/4 -> 0 | AF38: =$E$24*$E$20/100/4 -> 0 | AG38: =$E$24*$E$20/100/4 -> 0 | AH38: =$E$24*$E$20/100/4 -> 0 | AI38: =$E$24*$E$21/100/4 -> 0 | AJ38: =$E$24*$E$21/100/4 -> 0 | AK38: =$E$24*$E$21/100/4 -> 0 | AL38: =$E$24*$E$21/100/4 -> 0
A39: MONTH -9 (ADMIN) | D39: =SUM(E39:AZ39) -> 0 | G39: =$E$25*$E$14/100/4 -> 0 | H39: =$E$25*$E$14/100/4 -> 0 | I39: =$E$25*$E$14/100/4 -> 0 | J39: =$E$25*$E$14/100/4 -> 0 | K39: =$E$25*$E$15/100/4 -> 0 | L39: =$E$25*$E$15/100/4 -> 0 | M39: =$E$25*$E$15/100/4 -> 0 | N39: =$E$25*$E$15/100/4 -> 0 | O39: =$E$25*$E$16/100/4 -> 0 | P39: =$E$25*$E$16/100/4 -> 0 | Q39: =$E$25*$E$16/100/4 -> 0 | R39: =$E$25*$E$16/100/4 -> 0 | S39: =$E$25*$E$17/100/4 -> 0 | T39: =$E$25*$E$17/100/4 -> 0 | U39: =$E$25*$E$17/100/4 -> 0 | V39: =$E$25*$E$17/100/4 -> 0 | W39: =$E$25*$E$18/100/4 -> 0 | X39: =$E$25*$E$18/100/4 -> 0 | Y39: =$E$25*$E$18/100/4 -> 0 | Z39: =$E$25*$E$18/100/4 -> 0 | AA39: =$E$25*$E$19/100/4 -> 0 | AB39: =$E$25*$E$19/100/4 -> 0 | AC39: =$E$25*$E$19/100/4 -> 0 | AD39: =$E$25*$E$19/100/4 -> 0 | AE39: =$E$25*$E$20/100/4 -> 0 | AF39: =$E$25*$E$20/100/4 -> 0 | AG39: =$E$25*$E$20/100/4 -> 0 | AH39: =$E$25*$E$20/100/4 -> 0 | AI39: =$E$25*$E$21/100/4 -> 0 | AJ39: =$E$25*$E$21/100/4 -> 0 | AK39: =$E$25*$E$21/100/4 -> 0 | AL39: =$E$25*$E$21/100/4 -> 0
A40: MONTH -6 (COMMERCIAL) | D40: =SUM(E40:AZ40) -> 0 | H40: =$F$24*$F$14/100/4 -> 0 | I40: =$F$24*$F$14/100/4 -> 0 | J40: =$F$24*$F$14/100/4 -> 0 | K40: =$F$24*$F$14/100/4 -> 0 | L40: =$F$24*$F$15/100/4 -> 0 | M40: =$F$24*$F$15/100/4 -> 0 | N40: =$F$24*$F$15/100/4 -> 0 | O40: =$F$24*$F$15/100/4 -> 0 | P40: =$F$24*$F$16/100/4 -> 0 | Q40: =$F$24*$F$16/100/4 -> 0 | R40: =$F$24*$F$16/100/4 -> 0 | S40: =$F$24*$F$16/100/4 -> 0 | T40: =$F$24*$F$17/100/4 -> 0 | U40: =$F$24*$F$17/100/4 -> 0 | V40: =$F$24*$F$17/100/4 -> 0 | W40: =$F$24*$F$17/100/4 -> 0 | X40: =$F$24*$F$18/100/4 -> 0 | Y40: =$F$24*$F$18/100/4 -> 0 | Z40: =$F$24*$F$18/100/4 -> 0 | AA40: =$F$24*$F$18/100/4 -> 0 | AB40: =$F$24*$F$19/100/4 -> 0 | AC40: =$F$24*$F$19/100/4 -> 0 | AD40: =$F$24*$F$19/100/4 -> 0 | AE40: =$F$24*$F$19/100/4 -> 0 | AF40: =$F$24*$F$20/100/4 -> 0 | AG40: =$F$24*$F$20/100/4 -> 0 | AH40: =$F$24*$F$20/100/4 -> 0 | AI40: =$F$24*$F$20/100/4 -> 0 | AJ40: =$F$24*$F$21/100/4 -> 0 | AK40: =$F$24*$F$21/100/4 -> 0 | AL40: =$F$24*$F$21/100/4 -> 0 | AM40: =$F$24*$F$21/100/4 -> 0
A41: MONTH -6 (ADMIN) | D41: =SUM(E41:AZ41) -> 0 | H41: =$F$25*$F$14/100/4 -> 0 | I41: =$F$25*$F$14/100/4 -> 0 | J41: =$F$25*$F$14/100/4 -> 0 | K41: =$F$25*$F$14/100/4 -> 0 | L41: =$F$25*$F$15/100/4 -> 0 | M41: =$F$25*$F$15/100/4 -> 0 | N41: =$F$25*$F$15/100/4 -> 0 | O41: =$F$25*$F$15/100/4 -> 0 | P41: =$F$25*$F$16/100/4 -> 0 | Q41: =$F$25*$F$16/100/4 -> 0 | R41: =$F$25*$F$16/100/4 -> 0 | S41: =$F$25*$F$16/100/4 -> 0 | T41: =$F$25*$F$17/100/4 -> 0 | U41: =$F$25*$F$17/100/4 -> 0 | V41: =$F$25*$F$17/100/4 -> 0 | W41: =$F$25*$F$17/100/4 -> 0 | X41: =$F$25*$F$18/100/4 -> 0 | Y41: =$F$25*$F$18/100/4 -> 0 | Z41: =$F$25*$F$18/100/4 -> 0 | AA41: =$F$25*$F$18/100/4 -> 0 | AB41: =$F$25*$F$19/100/4 -> 0 | AC41: =$F$25*$F$19/100/4 -> 0 | AD41: =$F$25*$F$19/100/4 -> 0 | AE41: =$F$25*$F$19/100/4 -> 0 | AF41: =$F$25*$F$20/100/4 -> 0 | AG41: =$F$25*$F$20/100/4 -> 0 | AH41: =$F$25*$F$20/100/4 -> 0 | AI41: =$F$25*$F$20/100/4 -> 0 | AJ41: =$F$25*$F$21/100/4 -> 0 | AK41: =$F$25*$F$21/100/4 -> 0 | AL41: =$F$25*$F$21/100/4 -> 0 | AM41: =$F$25*$F$21/100/4 -> 0
A42: MONTH -3 (COMMERCIAL) | D42: =SUM(E42:AZ42) -> 0 | I42: =$G$24*$G$14/100/4 -> 0 | J42: =$G$24*$G$14/100/4 -> 0 | K42: =$G$24*$G$14/100/4 -> 0 | L42: =$G$24*$G$14/100/4 -> 0 | M42: =$G$24*$G$15/100/4 -> 0 | N42: =$G$24*$G$15/100/4 -> 0 | O42: =$G$24*$G$15/100/4 -> 0 | P42: =$G$24*$G$15/100/4 -> 0 | Q42: =$G$24*$G$16/100/4 -> 0 | R42: =$G$24*$G$16/100/4 -> 0 | S42: =$G$24*$G$16/100/4 -> 0 | T42: =$G$24*$G$16/100/4 -> 0 | U42: =$G$24*$G$17/100/4 -> 0 | V42: =$G$24*$G$17/100/4 -> 0 | W42: =$G$24*$G$17/100/4 -> 0 | X42: =$G$24*$G$17/100/4 -> 0 | Y42: =$G$24*$G$18/100/4 -> 0 | Z42: =$G$24*$G$18/100/4 -> 0 | AA42: =$G$24*$G$18/100/4 -> 0 | AB42: =$G$24*$G$18/100/4 -> 0 | AC42: =$G$24*$G$19/100/4 -> 0 | AD42: =$G$24*$G$19/100/4 -> 0 | AE42: =$G$24*$G$19/100/4 -> 0 | AF42: =$G$24*$G$19/100/4 -> 0 | AG42: =$G$24*$G$20/100/4 -> 0 | AH42: =$G$24*$G$20/100/4 -> 0 | AI42: =$G$24*$G$20/100/4 -> 0 | AJ42: =$G$24*$G$20/100/4 -> 0 | AK42: =$G$24*$G$21/100/4 -> 0 | AL42: =$G$24*$G$21/100/4 -> 0 | AM42: =$G$24*$G$21/100/4 -> 0 | AN42: =$G$24*$G$21/100/4 -> 0
A43: MONTH -3 (ADMIN) | D43: =SUM(E43:AZ43) -> 0 | I43: =$G$25*$G$14/100/4 -> 0 | J43: =$G$25*$G$14/100/4 -> 0 | K43: =$G$25*$G$14/100/4 -> 0 | L43: =$G$25*$G$14/100/4 -> 0 | M43: =$G$25*$G$15/100/4 -> 0 | N43: =$G$25*$G$15/100/4 -> 0 | O43: =$G$25*$G$15/100/4 -> 0 | P43: =$G$25*$G$15/100/4 -> 0 | Q43: =$G$25*$G$16/100/4 -> 0 | R43: =$G$25*$G$16/100/4 -> 0 | S43: =$G$25*$G$16/100/4 -> 0 | T43: =$G$25*$G$16/100/4 -> 0 | U43: =$G$25*$G$17/100/4 -> 0 | V43: =$G$25*$G$17/100/4 -> 0 | W43: =$G$25*$G$17/100/4 -> 0 | X43: =$G$25*$G$17/100/4 -> 0 | Y43: =$G$25*$G$18/100/4 -> 0 | Z43: =$G$25*$G$18/100/4 -> 0 | AA43: =$G$25*$G$18/100/4 -> 0 | AB43: =$G$25*$G$18/100/4 -> 0 | AC43: =$G$25*$G$19/100/4 -> 0 | AD43: =$G$25*$G$19/100/4 -> 0 | AE43: =$G$25*$G$19/100/4 -> 0 | AF43: =$G$25*$G$19/100/4 -> 0 | AG43: =$G$25*$G$20/100/4 -> 0 | AH43: =$G$25*$G$20/100/4 -> 0 | AI43: =$G$25*$G$20/100/4 -> 0 | AJ43: =$G$25*$G$20/100/4 -> 0 | AK43: =$G$25*$G$21/100/4 -> 0 | AL43: =$G$25*$G$21/100/4 -> 0 | AM43: =$G$25*$G$21/100/4 -> 0 | AN43: =$G$25*$G$21/100/4 -> 0
A44: MONTH 0 (COMMERCIAL) | D44: =SUM(E44:AZ44) -> 0 | J44: =$H$24*$H$14/100/4 -> 0 | K44: =$H$24*$H$14/100/4 -> 0 | L44: =$H$24*$H$14/100/4 -> 0 | M44: =$H$24*$H$14/100/4 -> 0 | N44: =$H$24*$H$15/100/4 -> 0 | O44: =$H$24*$H$15/100/4 -> 0 | P44: =$H$24*$H$15/100/4 -> 0 | Q44: =$H$24*$H$15/100/4 -> 0 | R44: =$H$24*$H$16/100/4 -> 0 | S44: =$H$24*$H$16/100/4 -> 0 | T44: =$H$24*$H$16/100/4 -> 0 | U44: =$H$24*$H$16/100/4 -> 0 | V44: =$H$24*$H$17/100/4 -> 0 | W44: =$H$24*$H$17/100/4 -> 0 | X44: =$H$24*$H$17/100/4 -> 0 | Y44: =$H$24*$H$17/100/4 -> 0 | Z44: =$H$24*$H$18/100/4 -> 0 | AA44: =$H$24*$H$18/100/4 -> 0 | AB44: =$H$24*$H$18/100/4 -> 0 | AC44: =$H$24*$H$18/100/4 -> 0 | AD44: =$H$24*$H$19/100/4 -> 0 | AE44: =$H$24*$H$19/100/4 -> 0 | AF44: =$H$24*$H$19/100/4 -> 0 | AG44: =$H$24*$H$19/100/4 -> 0 | AH44: =$H$24*$H$20/100/4 -> 0 | AI44: =$H$24*$H$20/100/4 -> 0 | AJ44: =$H$24*$H$20/100/4 -> 0 | AK44: =$H$24*$H$20/100/4 -> 0 | AL44: =$H$24*$H$21/100/4 -> 0 | AM44: =$H$24*$H$21/100/4 -> 0 | AN44: =$H$24*$H$21/100/4 -> 0 | AO44: =$H$24*$H$21/100/4 -> 0
...

Sheet Stage Schedule & Costs (2)
A1: Construction Schedule & Cost Plan
A2: Enter Duration (months) and Stage Cost (EGP) in the grey cells. All other fields calculate automatically.
A4: No. | B4: Category | C4: Stage | D4: Duration (Months) | E4: Start Month | F4: End Month | G4: Stage Cost (EGP) | H4: Cost / Month (EGP)
A5: 1 | B5: Excavation | C5: Excavation | D5: 3 | E5: 0 | F5: =E5+D5 -> 3 | G5: 2500000 | H5: =IF(D5=0,0,G5/D5) -> 833333.33
A6: 2 | B6: Replacement | C6: Replacement (Backfill) | D6: 3 | E6: =F5 -> 3 | F6: =E6+D6 -> 6 | G6: 3300000 | H6: =IF(D6=0,0,G6/D6) -> 1100000
A7: 3 | B7: Concrete Structure | C7: Basement Floor | D7: 3 | E7: =F6 -> 6 | F7: =E7+D7 -> 9 | G7: 5000000 | H7: =IF(D7=0,0,G7/D7) -> 1666666.7
A8: 4 | C8: Ground Floor | D8: 3 | E8: =F7 -> 9 | F8: =E8+D8 -> 12 | G8: 3300000 | H8: =IF(D8=0,0,G8/D8) -> 1100000
A9: 5 | C9: 1st Floor | D9: 3 | E9: =F8 -> 12 | F9: =E9+D9 -> 15 | G9: 3300000 | H9: =IF(D9=0,0,G9/D9) -> 1100000
A10: 6 | C10: 2nd Floor | D10: 3 | E10: =F9 -> 15 | F10: =E10+D10 -> 18 | G10: 3300000 | H10: =IF(D10=0,0,G10/D10) -> 1100000
A11: 7 | C11: 3rd Floor | E11: =F10 -> 18 | F11: =E11+D11 -> 18 | H11: =IF(D11=0,0,G11/D11) -> 0
A12: 8 | B12: Building Works | C12: Basement Floor | D12: 1.5 | E12: =F11 -> 18 | F12: =E12+D12 -> 19.5 | G12: 330000 | H12: =IF(D12=0,0,G12/D12) -> 220000
A13: 9 | C13: Ground Floor | D13: 1.5 | E13: =F12 -> 19.5 | F13: =E13+D13 -> 21 | G13: 330000 | H13: =IF(D13=0,0,G13/D13) -> 220000
A14: 10 | C14: 1st Floor | D14: 1.5 | E14: =F13 -> 21 | F14: =E14+D14 -> 22.5 | G14: 330000 | H14: =IF(D14=0,0,G14/D14) -> 220000
A15: 11 | C15: 2nd Floor | D15: 1.5 | E15: =F14 -> 22.5 | F15: =E15+D15 -> 24 | G15: 330000 | H15: =IF(D15=0,0,G15/D15) -> 220000
A16: 12 | C16: 3rd Floor | D16: 0 | E16: =F15 -> 24 | F16: =E16+D16 -> 24 | G16: 0 | H16: =IF(D16=0,0,G16/D16) -> 0
A17: 13 | B17: MEP & Plumbing | C17: Basement Floor | D17: 2 | E17: =F16 -> 24 | F17: =E17+D17 -> 26 | G17: 10000000 | H17: =IF(D17=0,0,G17/D17) -> 5000000
A18: 14 | C18: Ground Floor | D18: 2 | E18: =F17 -> 26 | F18: =E18+D18 -> 28 | G18: 10000000 | H18: =IF(D18=0,0,G18/D18) -> 5000000
A19: 15 | C19: 1st Floor | D19: 2 | E19: =F18 -> 28 | F19: =E19+D19 -> 30 | G19: 10000000 | H19: =IF(D19=0,0,G19/D19) -> 5000000
A20: 16 | C20: 2nd Floor | D20: 2 | E20: =F19 -> 30 | F20: =E20+D20 -> 32 | G20: 10000000 | H20: =IF(D20=0,0,G20/D20) -> 5000000
A21: 17 | C21: 3rd Floor | D21: 0 | E21: =F20 -> 32 | F21: =E21+D21 -> 32 | H21: =IF(D21=0,0,G21/D21) -> 0
A22: 18 | B22: Curtain Walls | C22: Curtain Walls | D22: 2 | E22: =F21 -> 32 | F22: =E22+D22 -> 34 | G22: 21000000 | H22: =IF(D22=0,0,G22/D22) -> 10500000
A23: 19 | B23: Landscape | C23: Landscape | D23: 2 | E23: =F22 -> 34 | F23: =E23+D23 -> 36 | G23: 4125000 | H23: =IF(D23=0,0,G23/D23) -> 2062500
B25: TOTAL | C25: Project Duration & Cost | F25: =F23 -> 36 | G25: =SUM(G5:G23) -> 87145000
A27: Notes: Stages run sequentially (Start Month of each stage = End Month of the previous stage). MEP & Plumbing duration is split evenly across the 5 floor stages. To run two stages in parallel, overwrite that stage's Start Month formula.

Sheet Cash Out Detail
A1: Cash Out — Construction Spend by Stage
A2: Stage costs are spread evenly (straight-line) across each stage's duration and pulled from the Stage Schedule & Costs sheet. Row 3 = project month (M1 = sales launch); row 4 = construction month (1 = construction start).
B3: Project month (M1 = sales launch) | D3: 1 | E3: =D3+1 -> 2 | F3: =E3+1 -> 3 | G3: =F3+1 -> 4 | H3: =G3+1 -> 5 | I3: =H3+1 -> 6 | J3: =I3+1 -> 7 | K3: =J3+1 -> 8 | L3: =K3+1 -> 9 | ... BK3: =BJ3+1 -> 60
A4: No. | B4: Stage | D4: =D3-(Assumptions!$C$12-1) -> -5 | E4: =E3-(Assumptions!$C$12-1) -> -4 | F4: =F3-(Assumptions!$C$12-1) -> -3 | G4: =G3-(Assumptions!$C$12-1) -> -2 | H4: =H3-(Assumptions!$C$12-1) -> -1 | I4: =I3-(Assumptions!$C$12-1) -> 0 | J4: =J3-(Assumptions!$C$12-1) -> 1 | K4: =K3-(Assumptions!$C$12-1) -> 2 | ... BK4: =BK3-(Assumptions!$C$12-1) -> 54
A5: ='Stage Schedule & Costs (2)'!A5 -> 1 | B5: ='Stage Schedule & Costs (2)'!B5&" - "&'Stage Schedule & Costs (2)'!C5 -> Excavation - Excavation | C5: =SUM(D5:BE5) -> 2500000 | D5: =MAX(0,MIN('Stage Schedule & Costs (2)'!$F5,D$4)-MAX('Stage Schedule & Costs (2)'!$E5,D$4-1))*'Stage Schedule & Costs (2)'!$H5 -> 0 | E5: =MAX(0,MIN('Stage Schedule & Costs (2)'!$F5,E$4)-MAX('Stage Schedule & Costs (2)'!$E5,E$4-1))*'Stage Schedule & Costs (2)'!$H5 -> 0 | F5: =MAX(0,MIN('Stage Schedule & Costs (2)'!$F5,F$4)-MAX('Stage Schedule & Costs (2)'!$E5,F$4-1))*'Stage Schedule & Costs (2)'!$H5 -> 0 | G5: =MAX(0,MIN('Stage Schedule & Costs (2)'!$F5,G$4)-MAX('Stage Schedule & Costs (2)'!$E5,G$4-1))*'Stage Schedule & Costs (2)'!$H5 -> 0 | H5: =MAX(0,MIN('Stage Schedule & Costs (2)'!$F5,H$4)-MAX('Stage Schedule & Costs (2)'!$E5,H$4-1))*'Stage Schedule & Costs (2)'!$H5 -> 0 | I5: =MAX(0,MIN('Stage Schedule & Costs (2)'!$F5,I$4)-MAX('Stage Schedule & Costs (2)'!$E5,I$4-1))*'Stage Schedule & Costs (2)'!$H5 -> 0 | J5: =MAX(0,MIN('Stage Schedule & Costs (2)'!$F5,J$4)-MAX('Stage Schedule & Costs (2)'!$E5,J$4-1))*'Stage Schedule & Costs (2)'!$H5 -> 833333.33 | K5: =MAX(0,MIN('Stage Schedule & Costs (2)'!$F5,K$4)-MAX('Stage Schedule & Costs (2)'!$E5,K$4-1))*'Stage Schedule & Costs (2)'!$H5 -> 833333.33 | ... BK5: =MAX(0,MIN('Stage Schedule & Costs (2)'!$F5,BK$4)-MAX('Stage Schedule & Costs (2)'!$E5,BK$4-1))*'Stage Schedule & Costs (2)'!$H5 -> 0
A6: ='Stage Schedule & Costs (2)'!A6 -> 2 | B6: ='Stage Schedule & Costs (2)'!B6&" - "&'Stage Schedule & Costs (2)'!C6 -> Replacement - Replacement (Backfill) | C6: =SUM(D6:BE6) -> 3300000 | D6: =MAX(0,MIN('Stage Schedule & Costs (2)'!$F6,D$4)-MAX('Stage Schedule & Costs (2)'!$E6,D$4-1))*'Stage Schedule & Costs (2)'!$H6 -> 0 | E6: =MAX(0,MIN('Stage Schedule & Costs (2)'!$F6,E$4)-MAX('Stage Schedule & Costs (2)'!$E6,E$4-1))*'Stage Schedule & Costs (2)'!$H6 -> 0 | F6: =MAX(0,MIN('Stage Schedule & Costs (2)'!$F6,F$4)-MAX('Stage Schedule & Costs (2)'!$E6,F$4-1))*'Stage Schedule & Costs (2)'!$H6 -> 0 | G6: =MAX(0,MIN('Stage Schedule & Costs (2)'!$F6,G$4)-MAX('Stage Schedule & Costs (2)'!$E6,G$4-1))*'Stage Schedule & Costs (2)'!$H6 -> 0 | H6: =MAX(0,MIN('Stage Schedule & Costs (2)'!$F6,H$4)-MAX('Stage Schedule & Costs (2)'!$E6,H$4-1))*'Stage Schedule & Costs (2)'!$H6 -> 0 | I6: =MAX(0,MIN('Stage Schedule & Costs (2)'!$F6,I$4)-MAX('Stage Schedule & Costs (2)'!$E6,I$4-1))*'Stage Schedule & Costs (2)'!$H6 -> 0 | J6: =MAX(0,MIN('Stage Schedule & Costs (2)'!$F6,J$4)-MAX('Stage Schedule & Costs (2)'!$E6,J$4-1))*'Stage Schedule & Costs (2)'!$H6 -> 0 | K6: =MAX(0,MIN('Stage Schedule & Costs (2)'!$F6,K$4)-MAX('Stage Schedule & Costs (2)'!$E6,K$4-1))*'Stage Schedule & Costs (2)'!$H6 -> 0 | ... BK6: =MAX(0,MIN('Stage Schedule & Costs (2)'!$F6,BK$4)-MAX('Stage Schedule & Costs (2)'!$E6,BK$4-1))*'Stage Schedule & Costs (2)'!$H6 -> 0
A7: ='Stage Schedule & Costs (2)'!A7 -> 3 | B7: ='Stage Schedule & Costs (2)'!B7&" - "&'Stage Schedule & Costs (2)'!C7 -> Concrete Structure - Basement Floor | C7: =SUM(D7:BE7) -> 5000000 | D7: =MAX(0,MIN('Stage Schedule & Costs (2)'!$F7,D$4)-MAX('Stage Schedule & Costs (2)'!$E7,D$4-1))*'Stage Schedule & Costs (2)'!$H7 -> 0 | E7: =MAX(0,MIN('Stage Schedule & Costs (2)'!$F7,E$4)-MAX('Stage Schedule & Costs (2)'!$E7,E$4-1))*'Stage Schedule & Costs (2)'!$H7 -> 0 | F7: =MAX(0,MIN('Stage Schedule & Costs (2)'!$F7,F$4)-MAX('Stage Schedule & Costs (2)'!$E7,F$4-1))*'Stage Schedule & Costs (2)'!$H7 -> 0 | G7: =MAX(0,MIN('Stage Schedule & Costs (2)'!$F7,G$4)-MAX('Stage Schedule & Costs (2)'!$E7,G$4-1))*'Stage Schedule & Costs (2)'!$H7 -> 0 | H7: =MAX(0,MIN('Stage Schedule & Costs (2)'!$F7,H$4)-MAX('Stage Schedule & Costs (2)'!$E7,H$4-1))*'Stage Schedule & Costs (2)'!$H7 -> 0 | I7: =MAX(0,MIN('Stage Schedule & Costs (2)'!$F7,I$4)-MAX('Stage Schedule & Costs (2)'!$E7,I$4-1))*'Stage Schedule & Costs (2)'!$H7 -> 0 | J7: =MAX(0,MIN('Stage Schedule & Costs (2)'!$F7,J$4)-MAX('Stage Schedule & Costs (2)'!$E7,J$4-1))*'Stage Schedule & Costs (2)'!$H7 -> 0 | K7: =MAX(0,MIN('Stage Schedule & Costs (2)'!$F7,K$4)-MAX('Stage Schedule & Costs (2)'!$E7,K$4-1))*'Stage Schedule & Costs (2)'!$H7 -> 0 | ... BK7: =MAX(0,MIN('Stage Schedule & Costs (2)'!$F7,BK$4)-MAX('Stage Schedule & Costs (2)'!$E7,BK$4-1))*'Stage Schedule & Costs (2)'!$H7 -> 0
A8: ='Stage Schedule & Costs (2)'!A8 -> 4 | B8: ='Stage Schedule & Costs (2)'!B8&" - "&'Stage Schedule & Costs (2)'!C8 -> - Ground Floor | C8: =SUM(D8:BE8) -> 3300000 | D8: =MAX(0,MIN('Stage Schedule & Costs (2)'!$F8,D$4)-MAX('Stage Schedule & Costs (2)'!$E8,D$4-1))*'Stage Schedule & Costs (2)'!$H8 -> 0 | E8: =MAX(0,MIN('Stage Schedule & Costs (2)'!$F8,E$4)-MAX('Stage Schedule & Costs (2)'!$E8,E$4-1))*'Stage Schedule & Costs (2)'!$H8 -> 0 | F8: =MAX(0,MIN('Stage Schedule & Costs (2)'!$F8,F$4)-MAX('Stage Schedule & Costs (2)'!$E8,F$4-1))*'Stage Schedule & Costs (2)'!$H8 -> 0 | G8: =MAX(0,MIN('Stage Schedule & Costs (2)'!$F8,G$4)-MAX('Stage Schedule & Costs (2)'!$E8,G$4-1))*'Stage Schedule & Costs (2)'!$H8 -> 0 | H8: =MAX(0,MIN('Stage Schedule & Costs (2)'!$F8,H$4)-MAX('Stage Schedule & Costs (2)'!$E8,H$4-1))*'Stage Schedule & Costs (2)'!$H8 -> 0 | I8: =MAX(0,MIN('Stage Schedule & Costs (2)'!$F8,I$4)-MAX('Stage Schedule & Costs (2)'!$E8,I$4-1))*'Stage Schedule & Costs (2)'!$H8 -> 0 | J8: =MAX(0,MIN('Stage Schedule & Costs (2)'!$F8,J$4)-MAX('Stage Schedule & Costs (2)'!$E8,J$4-1))*'Stage Schedule & Costs (2)'!$H8 -> 0 | K8: =MAX(0,MIN('Stage Schedule & Costs (2)'!$F8,K$4)-MAX('Stage Schedule & Costs (2)'!$E8,K$4-1))*'Stage Schedule & Costs (2)'!$H8 -> 0 | ... BK8: =MAX(0,MIN('Stage Schedule & Costs (2)'!$F8,BK$4)-MAX('Stage Schedule & Costs (2)'!$E8,BK$4-1))*'Stage Schedule & Costs (2)'!$H8 -> 0
A9: ='Stage Schedule & Costs (2)'!A9 -> 5 | B9: ='Stage Schedule & Costs (2)'!B9&" - "&'Stage Schedule & Costs (2)'!C9 -> - 1st Floor | C9: =SUM(D9:BE9) -> 3300000 | D9: =MAX(0,MIN('Stage Schedule & Costs (2)'!$F9,D$4)-MAX('Stage Schedule & Costs (2)'!$E9,D$4-1))*'Stage Schedule & Costs (2)'!$H9 -> 0 | E9: =MAX(0,MIN('Stage Schedule & Costs (2)'!$F9,E$4)-MAX('Stage Schedule & Costs (2)'!$E9,E$4-1))*'Stage Schedule & Costs (2)'!$H9 -> 0 | F9: =MAX(0,MIN('Stage Schedule & Costs (2)'!$F9,F$4)-MAX('Stage Schedule & Costs (2)'!$E9,F$4-1))*'Stage Schedule & Costs (2)'!$H9 -> 0 | G9: =MAX(0,MIN('Stage Schedule & Costs (2)'!$F9,G$4)-MAX('Stage Schedule & Costs (2)'!$E9,G$4-1))*'Stage Schedule & Costs (2)'!$H9 -> 0 | H9: =MAX(0,MIN('Stage Schedule & Costs (2)'!$F9,H$4)-MAX('Stage Schedule & Costs (2)'!$E9,H$4-1))*'Stage Schedule & Costs (2)'!$H9 -> 0 | I9: =MAX(0,MIN('Stage Schedule & Costs (2)'!$F9,I$4)-MAX('Stage Schedule & Costs (2)'!$E9,I$4-1))*'Stage Schedule & Costs (2)'!$H9 -> 0 | J9: =MAX(0,MIN('Stage Schedule & Costs (2)'!$F9,J$4)-MAX('Stage Schedule & Costs (2)'!$E9,J$4-1))*'Stage Schedule & Costs (2)'!$H9 -> 0 | K9: =MAX(0,MIN('Stage Schedule & Costs (2)'!$F9,K$4)-MAX('Stage Schedule & Costs (2)'!$E9,K$4-1))*'Stage Schedule & Costs (2)'!$H9 -> 0 | ... BK9: =MAX(0,MIN('Stage Schedule & Costs (2)'!$F9,BK$4)-MAX('Stage Schedule & Costs (2)'!$E9,BK$4-1))*'Stage Schedule & Costs (2)'!$H9 -> 0
A10: ='Stage Schedule & Costs (2)'!A10 -> 6 | B10: ='Stage Schedule & Costs (2)'!B10&" - "&'Stage Schedule & Costs (2)'!C10 -> - 2nd Floor | C10: =SUM(D10:BE10) -> 3300000 | D10: =MAX(0,MIN('Stage Schedule & Costs (2)'!$F10,D$4)-MAX('Stage Schedule & Costs (2)'!$E10,D$4-1))*'Stage Schedule & Costs (2)'!$H10 -> 0 | E10: =MAX(0,MIN('Stage Schedule & Costs (2)'!$F10,E$4)-MAX('Stage Schedule & Costs (2)'!$E10,E$4-1))*'Stage Schedule & Costs (2)'!$H10 -> 0 | F10: =MAX(0,MIN('Stage Schedule & Costs (2)'!$F10,F$4)-MAX('Stage Schedule & Costs (2)'!$E10,F$4-1))*'Stage Schedule & Costs (2)'!$H10 -> 0 | G10: =MAX(0,MIN('Stage Schedule & Costs (2)'!$F10,G$4)-MAX('Stage Schedule & Costs (2)'!$E10,G$4-1))*'Stage Schedule & Costs (2)'!$H10 -> 0 | H10: =MAX(0,MIN('Stage Schedule & Costs (2)'!$F10,H$4)-MAX('Stage Schedule & Costs (2)'!$E10,H$4-1))*'Stage Schedule & Costs (2)'!$H10 -> 0 | I10: =MAX(0,MIN('Stage Schedule & Costs (2)'!$F10,I$4)-MAX('Stage Schedule & Costs (2)'!$E10,I$4-1))*'Stage Schedule & Costs (2)'!$H10 -> 0 | J10: =MAX(0,MIN('Stage Schedule & Costs (2)'!$F10,J$4)-MAX('Stage Schedule & Costs (2)'!$E10,J$4-1))*'Stage Schedule & Costs (2)'!$H10 -> 0 | K10: =MAX(0,MIN('Stage Schedule & Costs (2)'!$F10,K$4)-MAX('Stage Schedule & Costs (2)'!$E10,K$4-1))*'Stage Schedule & Costs (2)'!$H10 -> 0 | ... BK10: =MAX(0,MIN('Stage Schedule & Costs (2)'!$F10,BK$4)-MAX('Stage Schedule & Costs (2)'!$E10,BK$4-1))*'Stage Schedule & Costs (2)'!$H10 -> 0
A11: ='Stage Schedule & Costs (2)'!A11 -> 7 | B11: ='Stage Schedule & Costs (2)'!B11&" - "&'Stage Schedule & Costs (2)'!C11 -> - 3rd Floor | C11: =SUM(D11:BE11) -> 0 | D11: =MAX(0,MIN('Stage Schedule & Costs (2)'!$F11,D$4)-MAX('Stage Schedule & Costs (2)'!$E11,D$4-1))*'Stage Schedule & Costs (2)'!$H11 -> 0 | E11: =MAX(0,MIN('Stage Schedule & Costs (2)'!$F11,E$4)-MAX('Stage Schedule & Costs (2)'!$E11,E$4-1))*'Stage Schedule & Costs (2)'!$H11 -> 0 | F11: =MAX(0,MIN('Stage Schedule & Costs (2)'!$F11,F$4)-MAX('Stage Schedule & Costs (2)'!$E11,F$4-1))*'Stage Schedule & Costs (2)'!$H11 -> 0 | G11: =MAX(0,MIN('Stage Schedule & Costs (2)'!$F11,G$4)-MAX('Stage Schedule & Costs (2)'!$E11,G$4-1))*'Stage Schedule & Costs (2)'!$H11 -> 0 | H11: =MAX(0,MIN('Stage Schedule & Costs (2)'!$F11,H$4)-MAX('Stage Schedule & Costs (2)'!$E11,H$4-1))*'Stage Schedule & Costs (2)'!$H11 -> 0 | I11: =MAX(0,MIN('Stage Schedule & Costs (2)'!$F11,I$4)-MAX('Stage Schedule & Costs (2)'!$E11,I$4-1))*'Stage Schedule & Costs (2)'!$H11 -> 0 | J11: =MAX(0,MIN('Stage Schedule & Costs (2)'!$F11,J$4)-MAX('Stage Schedule & Costs (2)'!$E11,J$4-1))*'Stage Schedule & Costs (2)'!$H11 -> 0 | K11: =MAX(0,MIN('Stage Schedule & Costs (2)'!$F11,K$4)-MAX('Stage Schedule & Costs (2)'!$E11,K$4-1))*'Stage Schedule & Costs (2)'!$H11 -> 0 | ... BK11: =MAX(0,MIN('Stage Schedule & Costs (2)'!$F11,BK$4)-MAX('Stage Schedule & Costs (2)'!$E11,BK$4-1))*'Stage Schedule & Costs (2)'!$H11 -> 0
A12: ='Stage Schedule & Costs (2)'!A12 -> 8 | B12: ='Stage Schedule & Costs (2)'!B12&" - "&'Stage Schedule & Costs (2)'!C12 -> Building Works - Basement Floor | C12: =SUM(D12:BE12) -> 330000 | D12: =MAX(0,MIN('Stage Schedule & Costs (2)'!$F12,D$4)-MAX('Stage Schedule & Costs (2)'!$E12,D$4-1))*'Stage Schedule & Costs (2)'!$H12 -> 0 | E12: =MAX(0,MIN('Stage Schedule & Costs (2)'!$F12,E$4)-MAX('Stage Schedule & Costs (2)'!$E12,E$4-1))*'Stage Schedule & Costs (2)'!$H12 -> 0 | F12: =MAX(0,MIN('Stage Schedule & Costs (2)'!$F12,F$4)-MAX('Stage Schedule & Costs (2)'!$E12,F$4-1))*'Stage Schedule & Costs (2)'!$H12 -> 0 | G12: =MAX(0,MIN('Stage Schedule & Costs (2)'!$F12,G$4)-MAX('Stage Schedule & Costs (2)'!$E12,G$4-1))*'Stage Schedule & Costs (2)'!$H12 -> 0 | H12: =MAX(0,MIN('Stage Schedule & Costs (2)'!$F12,H$4)-MAX('Stage Schedule & Costs (2)'!$E12,H$4-1))*'Stage Schedule & Costs (2)'!$H12 -> 0 | I12: =MAX(0,MIN('Stage Schedule & Costs (2)'!$F12,I$4)-MAX('Stage Schedule & Costs (2)'!$E12,I$4-1))*'Stage Schedule & Costs (2)'!$H12 -> 0 | J12: =MAX(0,MIN('Stage Schedule & Costs (2)'!$F12,J$4)-MAX('Stage Schedule & Costs (2)'!$E12,J$4-1))*'Stage Schedule & Costs (2)'!$H12 -> 0 | K12: =MAX(0,MIN('Stage Schedule & Costs (2)'!$F12,K$4)-MAX('Stage Schedule & Costs (2)'!$E12,K$4-1))*'Stage Schedule & Costs (2)'!$H12 -> 0 | ... BK12: =MAX(0,MIN('Stage Schedule & Costs (2)'!$F12,BK$4)-MAX('Stage Schedule & Costs (2)'!$E12,BK$4-1))*'Stage Schedule & Costs (2)'!$H12 -> 0
A13: ='Stage Schedule & Costs (2)'!A13 -> 9 | B13: ='Stage Schedule & Costs (2)'!B13&" - "&'Stage Schedule & Costs (2)'!C13 -> - Ground Floor | C13: =SUM(D13:BE13) -> 330000 | D13: =MAX(0,MIN('Stage Schedule & Costs (2)'!$F13,D$4)-MAX('Stage Schedule & Costs (2)'!$E13,D$4-1))*'Stage Schedule & Costs (2)'!$H13 -> 0 | E13: =MAX(0,MIN('Stage Schedule & Costs (2)'!$F13,E$4)-MAX('Stage Schedule & Costs (2)'!$E13,E$4-1))*'Stage Schedule & Costs (2)'!$H13 -> 0 | F13: =MAX(0,MIN('Stage Schedule & Costs (2)'!$F13,F$4)-MAX('Stage Schedule & Costs (2)'!$E13,F$4-1))*'Stage Schedule & Costs (2)'!$H13 -> 0 | G13: =MAX(0,MIN('Stage Schedule & Costs (2)'!$F13,G$4)-MAX('Stage Schedule & Costs (2)'!$E13,G$4-1))*'Stage Schedule & Costs (2)'!$H13 -> 0 | H13: =MAX(0,MIN('Stage Schedule & Costs (2)'!$F13,H$4)-MAX('Stage Schedule & Costs (2)'!$E13,H$4-1))*'Stage Schedule & Costs (2)'!$H13 -> 0 | I13: =MAX(0,MIN('Stage Schedule & Costs (2)'!$F13,I$4)-MAX('Stage Schedule & Costs (2)'!$E13,I$4-1))*'Stage Schedule & Costs (2)'!$H13 -> 0 | J13: =MAX(0,MIN('Stage Schedule & Costs (2)'!$F13,J$4)-MAX('Stage Schedule & Costs (2)'!$E13,J$4-1))*'Stage Schedule & Costs (2)'!$H13 -> 0 | K13: =MAX(0,MIN('Stage Schedule & Costs (2)'!$F13,K$4)-MAX('Stage Schedule & Costs (2)'!$E13,K$4-1))*'Stage Schedule & Costs (2)'!$H13 -> 0 | ... BK13: =MAX(0,MIN('Stage Schedule & Costs (2)'!$F13,BK$4)-MAX('Stage Schedule & Costs (2)'!$E13,BK$4-1))*'Stage Schedule & Costs (2)'!$H13 -> 0
A14: ='Stage Schedule & Costs (2)'!A14 -> 10 | B14: ='Stage Schedule & Costs (2)'!B14&" - "&'Stage Schedule & Costs (2)'!C14 -> - 1st Floor | C14: =SUM(D14:BE14) -> 330000 | D14: =MAX(0,MIN('Stage Schedule & Costs (2)'!$F14,D$4)-MAX('Stage Schedule & Costs (2)'!$E14,D$4-1))*'Stage Schedule & Costs (2)'!$H14 -> 0 | E14: =MAX(0,MIN('Stage Schedule & Costs (2)'!$F14,E$4)-MAX('Stage Schedule & Costs (2)'!$E14,E$4-1))*'Stage Schedule & Costs (2)'!$H14 -> 0 | F14: =MAX(0,MIN('Stage Schedule & Costs (2)'!$F14,F$4)-MAX('Stage Schedule & Costs (2)'!$E14,F$4-1))*'Stage Schedule & Costs (2)'!$H14 -> 0 | G14: =MAX(0,MIN('Stage Schedule & Costs (2)'!$F14,G$4)-MAX('Stage Schedule & Costs (2)'!$E14,G$4-1))*'Stage Schedule & Costs (2)'!$H14 -> 0 | H14: =MAX(0,MIN('Stage Schedule & Costs (2)'!$F14,H$4)-MAX('Stage Schedule & Costs (2)'!$E14,H$4-1))*'Stage Schedule & Costs (2)'!$H14 -> 0 | I14: =MAX(0,MIN('Stage Schedule & Costs (2)'!$F14,I$4)-MAX('Stage Schedule & Costs (2)'!$E14,I$4-1))*'Stage Schedule & Costs (2)'!$H14 -> 0 | J14: =MAX(0,MIN('Stage Schedule & Costs (2)'!$F14,J$4)-MAX('Stage Schedule & Costs (2)'!$E14,J$4-1))*'Stage Schedule & Costs (2)'!$H14 -> 0 | K14: =MAX(0,MIN('Stage Schedule & Costs (2)'!$F14,K$4)-MAX('Stage Schedule & Costs (2)'!$E14,K$4-1))*'Stage Schedule & Costs (2)'!$H14 -> 0 | ... BK14: =MAX(0,MIN('Stage Schedule & Costs (2)'!$F14,BK$4)-MAX('Stage Schedule & Costs (2)'!$E14,BK$4-1))*'Stage Schedule & Costs (2)'!$H14 -> 0
A15: ='Stage Schedule & Costs (2)'!A15 -> 11 | B15: ='Stage Schedule & Costs (2)'!B15&" - "&'Stage Schedule & Costs (2)'!C15 -> - 2nd Floor | C15: =SUM(D15:BE15) -> 330000 | D15: =MAX(0,MIN('Stage Schedule & Costs (2)'!$F15,D$4)-MAX('Stage Schedule & Costs (2)'!$E15,D$4-1))*'Stage Schedule & Costs (2)'!$H15 -> 0 | E15: =MAX(0,MIN('Stage Schedule & Costs (2)'!$F15,E$4)-MAX('Stage Schedule & Costs (2)'!$E15,E$4-1))*'Stage Schedule & Costs (2)'!$H15 -> 0 | F15: =MAX(0,MIN('Stage Schedule & Costs (2)'!$F15,F$4)-MAX('Stage Schedule & Costs (2)'!$E15,F$4-1))*'Stage Schedule & Costs (2)'!$H15 -> 0 | G15: =MAX(0,MIN('Stage Schedule & Costs (2)'!$F15,G$4)-MAX('Stage Schedule & Costs (2)'!$E15,G$4-1))*'Stage Schedule & Costs (2)'!$H15 -> 0 | H15: =MAX(0,MIN('Stage Schedule & Costs (2)'!$F15,H$4)-MAX('Stage Schedule & Costs (2)'!$E15,H$4-1))*'Stage Schedule & Costs (2)'!$H15 -> 0 | I15: =MAX(0,MIN('Stage Schedule & Costs (2)'!$F15,I$4)-MAX('Stage Schedule & Costs (2)'!$E15,I$4-1))*'Stage Schedule & Costs (2)'!$H15 -> 0 | J15: =MAX(0,MIN('Stage Schedule & Costs (2)'!$F15,J$4)-MAX('Stage Schedule & Costs (2)'!$E15,J$4-1))*'Stage Schedule & Costs (2)'!$H15 -> 0 | K15: =MAX(0,MIN('Stage Schedule & Costs (2)'!$F15,K$4)-MAX('Stage Schedule & Costs (2)'!$E15,K$4-1))*'Stage Schedule & Costs (2)'!$H15 -> 0 | ... BK15: =MAX(0,MIN('Stage Schedule & Costs (2)'!$F15,BK$4)-MAX('Stage Schedule & Costs (2)'!$E15,BK$4-1))*'Stage Schedule & Costs (2)'!$H15 -> 0
A16: ='Stage Schedule & Costs (2)'!A16 -> 12 | B16: ='Stage Schedule & Costs (2)'!B16&" - "&'Stage Schedule & Costs (2)'!C16 -> - 3rd Floor | C16: =SUM(D16:BE16) -> 0 | D16: =MAX(0,MIN('Stage Schedule & Costs (2)'!$F16,D$4)-MAX('Stage Schedule & Costs (2)'!$E16,D$4-1))*'Stage Schedule & Costs (2)'!$H16 -> 0 | E16: =MAX(0,MIN('Stage Schedule & Costs (2)'!$F16,E$4)-MAX('Stage Schedule & Costs (2)'!$E16,E$4-1))*'Stage Schedule & Costs (2)'!$H16 -> 0 | F16: =MAX(0,MIN('Stage Schedule & Costs (2)'!$F16,F$4)-MAX('Stage Schedule & Costs (2)'!$E16,F$4-1))*'Stage Schedule & Costs (2)'!$H16 -> 0 | G16: =MAX(0,MIN('Stage Schedule & Costs (2)'!$F16,G$4)-MAX('Stage Schedule & Costs (2)'!$E16,G$4-1))*'Stage Schedule & Costs (2)'!$H16 -> 0 | H16: =MAX(0,MIN('Stage Schedule & Costs (2)'!$F16,H$4)-MAX('Stage Schedule & Costs (2)'!$E16,H$4-1))*'Stage Schedule & Costs (2)'!$H16 -> 0 | I16: =MAX(0,MIN('Stage Schedule & Costs (2)'!$F16,I$4)-MAX('Stage Schedule & Costs (2)'!$E16,I$4-1))*'Stage Schedule & Costs (2)'!$H16 -> 0 | J16: =MAX(0,MIN('Stage Schedule & Costs (2)'!$F16,J$4)-MAX('Stage Schedule & Costs (2)'!$E16,J$4-1))*'Stage Schedule & Costs (2)'!$H16 -> 0 | K16: =MAX(0,MIN('Stage Schedule & Costs (2)'!$F16,K$4)-MAX('Stage Schedule & Costs (2)'!$E16,K$4-1))*'Stage Schedule & Costs (2)'!$H16 -> 0 | ... BK16: =MAX(0,MIN('Stage Schedule & Costs (2)'!$F16,BK$4)-MAX('Stage Schedule & Costs (2)'!$E16,BK$4-1))*'Stage Schedule & Costs (2)'!$H16 -> 0
... A23: ='Stage Schedule & Costs (2)'!A23 -> 19 | B23: ='Stage Schedule & Costs (2)'!B23&" - "&'Stage Schedule & Costs (2)'!C23 -> Landscape - Landscape | C23: =SUM(D23:BE23) -> 4125000 | D23: =MAX(0,MIN('Stage Schedule & Costs (2)'!$F23,D$4)-MAX('Stage Schedule & Costs (2)'!$E23,D$4-1))*'Stage Schedule & Costs (2)'!$H23 -> 0 | E23: =MAX(0,MIN('Stage Schedule & Costs (2)'!$F23,E$4)-MAX('Stage Schedule & Costs (2)'!$E23,E$4-1))*'Stage Schedule & Costs (2)'!$H23 -> 0 | F23: =MAX(0,MIN('Stage Schedule & Costs (2)'!$F23,F$4)-MAX('Stage Schedule & Costs (2)'!$E23,F$4-1))*'Stage Schedule & Costs (2)'!$H23 -> 0 | G23: =MAX(0,MIN('Stage Schedule & Costs (2)'!$F23,G$4)-MAX('Stage Schedule & Costs (2)'!$E23,G$4-1))*'Stage Schedule & Costs (2)'!$H23 -> 0 | H23: =MAX(0,MIN('Stage Schedule & Costs (2)'!$F23,H$4)-MAX('Stage Schedule & Costs (2)'!$E23,H$4-1))*'Stage Schedule & Costs (2)'!$H23 -> 0 | I23: =MAX(0,MIN('Stage Schedule & Costs (2)'!$F23,I$4)-MAX('Stage Schedule & Costs (2)'!$E23,I$4-1))*'Stage Schedule & Costs (2)'!$H23 -> 0 | J23: =MAX(0,MIN('Stage Schedule & Costs (2)'!$F23,J$4)-MAX('Stage Schedule & Costs (2)'!$E23,J$4-1))*'Stage Schedule & Costs (2)'!$H23 -> 0 | K23: =MAX(0,MIN('Stage Schedule & Costs (2)'!$F23,K$4)-MAX('Stage Schedule & Costs (2)'!$E23,K$4-1))*'Stage Schedule & Costs (2)'!$H23 -> 0 | ... BK23: =MAX(0,MIN('Stage Schedule & Costs (2)'!$F23,BK$4)-MAX('Stage Schedule & Costs (2)'!$E23,BK$4-1))*'Stage Schedule & Costs (2)'!$H23 -> 0
B24: Total Monthly Spend (EGP) | C24: =SUM(D24:BE24) -> 87145000 | D24: =SUM(D5:D23) -> 0 | E24: =SUM(E5:E23) -> 0 | F24: =SUM(F5:F23) -> 0 | G24: =SUM(G5:G23) -> 0 | H24: =SUM(H5:H23) -> 0 | I24: =SUM(I5:I23) -> 0 | J24: =SUM(J5:J23) -> 833333.33 | K24: =SUM(K5:K23) -> 833333.33 | ... BE24: =SUM(BE5:BE23) -> 0
B25: Cumulative Spend (EGP) | D25: =D24 -> 0 | E25: =D25+E24 -> 0 | F25: =E25+F24 -> 0 | G25: =F25+G24 -> 0 | H25: =G25+H24 -> 0 | I25: =H25+I24 -> 0 | J25: =I25+J24 -> 833333.33 | K25: =J25+K24 -> 1666666.7 | L25: =K25+L24 -> 2500000 | ... BE25: =BD25+BE24 -> 87145000
B27: Construction Cost
B28: L'avenir | C28: =SUM(P28:BQ28) -> 650760000 | D28: =D24*Assumptions!$C$22*Assumptions!$C$23 -> 0 | E28: =E24*Assumptions!$C$22*Assumptions!$C$23 -> 0 | F28: =F24*Assumptions!$C$22*Assumptions!$C$23 -> 0 | G28: =G24*Assumptions!$C$22*Assumptions!$C$23 -> 0 | H28: =H24*Assumptions!$C$22*Assumptions!$C$23 -> 0 | I28: =I24*Assumptions!$C$22*Assumptions!$C$23 -> 0 | J28: =J24*Assumptions!$C$22*Assumptions!$C$23 -> 6666666.7 | K28: =K24*Assumptions!$C$22*Assumptions!$C$23 -> 6666666.7 | ... BK28: =BK24*Assumptions!$C$22*Assumptions!$C$23 -> 0
B30: Sales Commission | C30: 0.04
B31: L'avenir | C31: =SUM(D31:BE31) -> 106949430 | D31: ='L''avenir'!$E$26/3*$C$30*1000 -> 0 | E31: ='L''avenir'!$E$26/3*$C$30*1000 -> 0 | F31: ='L''avenir'!$E$26/3*$C$30*1000 -> 0 | G31: ='L''avenir'!$F$26/3*$C$30*1000 -> 0 | H31: ='L''avenir'!$F$26/3*$C$30*1000 -> 0 | I31: ='L''avenir'!$F$26/3*$C$30*1000 -> 0 | J31: ='L''avenir'!$G$26/3*$C$30*1000 -> 0 | K31: ='L''avenir'!$G$26/3*$C$30*1000 -> 0 | L31: ='L''avenir'!$G$26/3*$C$30*1000 -> 0 | M31: ='L''avenir'!$H$26/3*$C$30*1000 -> 0 | N31: ='L''avenir'!$H$26/3*$C$30*1000 -> 0 | O31: ='L''avenir'!$H$26/3*$C$30*1000 -> 0 | P31: ='L''avenir'!$I$26/3*$C$30*1000 -> 4830840 | Q31: ='L''avenir'!$I$26/3*$C$30*1000 -> 4830840 | R31: ='L''avenir'!$I$26/3*$C$30*1000 -> 4830840 | S31: ='L''avenir'!$J$26/3*$C$30*1000 -> 4830840 | T31: ='L''avenir'!$J$26/3*$C$30*1000 -> 4830840 | U31: ='L''avenir'!$J$26/3*$C$30*1000 -> 4830840 | V31: ='L''avenir'!$K$26/3*$C$30*1000 -> 4144980 | W31: ='L''avenir'!$K$26/3*$C$30*1000 -> 4144980 | X31: ='L''avenir'!$K$26/3*$C$30*1000 -> 4144980 | Y31: ='L''avenir'!$L$26/3*$C$30*1000 -> 2400510 | Z31: ='L''avenir'!$L$26/3*$C$30*1000 -> 2400510 | AA31: ='L''avenir'!$L$26/3*$C$30*1000 -> 2400510 | AB31: ='L''avenir'!$M$26/3*$C$30*1000 -> 2644040 | AC31: ='L''avenir'!$M$26/3*$C$30*1000 -> 2644040 | AD31: ='L''avenir'!$M$26/3*$C$30*1000 -> 2644040 | AE31: ='L''avenir'!$N$26/3*$C$30*1000 -> 2465120 | AF31: ='L''avenir'!$N$26/3*$C$30*1000 -> 2465120 | AG31: ='L''avenir'!$N$26/3*$C$30*1000 -> 2465120 | AH31: ='L''avenir'!$O$26/3*$C$30*1000 -> 2514820 | AI31: ='L''avenir'!$O$26/3*$C$30*1000 -> 2514820 | AJ31: ='L''avenir'!$O$26/3*$C$30*1000 -> 2514820 | AK31: ='L''avenir'!$P$26/3*$C$30*1000 -> 2514820 | AL31: ='L''avenir'!$P$26/3*$C$30*1000 -> 2514820 | AM31: ='L''avenir'!$P$26/3*$C$30*1000 -> 2514820 | AN31: ='L''avenir'!$Q$26/3*$C$30*1000 -> 2743440 | AO31: ='L''avenir'!$Q$26/3*$C$30*1000 -> 2743440 | AP31: ='L''avenir'!$Q$26/3*$C$30*1000 -> 2743440 | AQ31: ='L''avenir'!$R$26/3*$C$30*1000 -> 2743440 | AR31: ='L''avenir'!$R$26/3*$C$30*1000 -> 2743440 | AS31: ='L''avenir'!$R$26/3*$C$30*1000 -> 2743440 | AT31: ='L''avenir'!$S$26/3*$C$30*1000 -> 1908480 | AU31: ='L''avenir'!$S$26/3*$C$30*1000 -> 1908480 | AV31: ='L''avenir'!$S$26/3*$C$30*1000 -> 1908480 | AW31: ='L''avenir'!$T$26/3*$C$30*1000 -> 1908480 | AX31: ='L''avenir'!$T$26/3*$C$30*1000 -> 1908480 | AY31: ='L''avenir'!$T$26/3*$C$30*1000 -> 1908480 | AZ31: ='L''avenir'!$U$26/3*$C$30*1000 -> 0 | BA31: ='L''avenir'!$U$26/3*$C$30*1000 -> 0 | BB31: ='L''avenir'!$U$26/3*$C$30*1000 -> 0 | BC31: ='L''avenir'!$V$26/3*$C$30*1000 -> 0 | BD31: ='L''avenir'!$V$26/3*$C$30*1000 -> 0 | BE31: ='L''avenir'!$V$26/3*$C$30*1000 -> 0 | BF31: ='L''avenir'!$W$26/3*$C$30*1000 -> 0 | BG31: ='L''avenir'!$W$26/3*$C$30*1000 -> 0 | BH31: ='L''avenir'!$W$26/3*$C$30*1000 -> 0 | BI31: ='L''avenir'!$X$26/3*$C$30*1000 -> 0 | BJ31: ='L''avenir'!$X$26/3*$C$30*1000 -> 0 | BK31: ='L''avenir'!$X$26/3*$C$30*1000 -> 0
B33: SGA& Others Cost | C33: =C42 -> 0.15
B34: L'avenir | C34: =SUM(D34:BE34) -> 104574000 | D34: =D28*$C$33 -> 0 | E34: =E28*$C$33 -> 0 | F34: =F28*$C$33 -> 0 | G34: =G28*$C$33 -> 0 | H34: =H28*$C$33 -> 0 | I34: =I28*$C$33 -> 0 | J34: =J28*$C$33 -> 1000000 | K34: =K28*$C$33 -> 1000000 | ... BK34: =BK28*$C$33 -> 0
B36: Total Cost
B37: L'avenir | C37: =SUM(D37:BK37) -> 908683430 | D37: =SUM(D34,D31,D28) -> 0 | E37: =SUM(E34,E31,E28) -> 0 | F37: =SUM(F34,F31,F28) -> 0 | G37: =SUM(G34,G31,G28) -> 0 | H37: =SUM(H34,H31,H28) -> 0 | I37: =SUM(I34,I31,I28) -> 0 | J37: =SUM(J34,J31,J28) -> 7666666.7 | K37: =SUM(K34,K31,K28) -> 7666666.7 | ... BK37: =SUM(BK34,BK31,BK28) -> 0
B39: Contingency (% of Construction Cost) — rate | C39: 0.05
B40: Professional Fees (% of Construction Cost) — rate | C40: 0.05
B41: G&A / Overhead (EGP, full horizon) | C41: 0.05
C42: =SUM(C39:C41) -> 0.15
D43: Cash Out Detail | E43: Net Cash Flow | F43: Diff
B44: Check: total cost (MEGP) vs capex on Net Cash Flow | D44: =C37/1000000 -> 908.68343 | E44: ='Net Cash Flow -With DP'!C20 -> 908.68343 | F44: =E44-D44 -> 0
B46: Summary basis vs full schedule (MEGP) | D46: Summary basis | E46: Full schedule | F46: Not in Summary
B47: Construction cost | D47: =C28/1000000 -> 650.76 | E47: =SUM(D28:BK28)/1000000 -> 697.16 | F47: =E47-D47 -> 46.4
B48: Sales commission | D48: =C31/1000000 -> 106.94943 | E48: =SUM(D31:BK31)/1000000 -> 106.94943 | F48: =E48-D48 -> 0
B49: SGA and others | D49: =C34/1000000 -> 104.574 | E49: =SUM(D34:BK34)/1000000 -> 104.574 | F49: =E49-D49 -> 0
B51: The Summary sheet totals each cost line over the same column ranges as the original model. Where 'Not in Summary' is non-zero, the Summary line omits part of the schedule; row 37 and the Net Cash Flow sheets always use the full schedule.

Sheet Offers
C2: L'AVENIR | D2: NOTES
B3: LANDLORD % | C3: 0.35
B4: MIN. GUARANTEED | C4: 850 M
B5: PAYMENT PERIOD | C5: 6
B6: YEAR 1 (M) | C6: 0 | D6: OR 35% OF COLLECTIONS WHICHEVER HIGHER
B7: YEAR 2 (M) | C7: 100 | D7: OR 35% OF COLLECTIONS WHICHEVER HIGHER
B8: YEAR 3 (M) | C8: 200 | D8: OR 35% OF COLLECTIONS WHICHEVER HIGHER
B9: YEAR 4 (M) | C9: 250 | D9: OR 35% OF COLLECTIONS WHICHEVER HIGHER
B10: YEAR 5 (M) | C10: 200 | D10: OR 35% OF COLLECTIONS WHICHEVER HIGHER
B11: YEAR 6 (M) | C11: 100 | D11: OR 35% OF COLLECTIONS WHICHEVER HIGHER
B12: YEAR 7 (M) | C12: 0 | D12: OR 35% OF COLLECTIONS WHICHEVER HIGHER
B13: EXCESS AMOUNT (YRS) | C13: 8
B14: PROJECT DELIVERY | C14: 54 MONTHS
B16: DEVELOPER % | C16: 0.65
B17: DESIGN | C17: ☑
B18: PERMITS | C18: ☑
B19: CONSTRUCTION | C19: ☑
B20: FINISHING | C20: CORE & SHELL
B21: MARKETING | C21: ☑
B22: SALES | C22: ☑
B23: COLLECTION | C23: ☑
B24: PROJECT NAME | C24: UNDER: JALOUR
B25: OPERATION, MANAGEMENT, MAINT. | C25: UNDER: JALOUR | D25: OR FACILITY MANAGEMENT COMPANY ASSIGNED BY JALOUR

Sheet Offers DP
B1: NPV Diff with vs without downpayments | C1: =Summary!F23 -> -23.963617
B2: NPV with DP | C2: =Summary!D23 -> 350.5869
C3: =SUM(C9:C16) -> 850 | E3: =C3-850 -> 0
B4: MEGP | C4: L'AVENIR | D4: NOTES | E4: =E3/6 -> 0
B5: Landlord Share of Collections | C5: 0.35
B6: Minimum Guaranteed Amount | C6: 850
B7: Payment Period | C7: 6
B8: Downpayment % | C8: 0.1
B9: Downpayment Amount (m) | C9: =C8*C6 -> 85
B10: Year 1 (m) | C10: 0 | D10: OR 35% OF COLLECTIONS WHICHEVER HIGHER
B11: Year 2 (m) | C11: 90 | D11: OR 35% OF COLLECTIONS WHICHEVER HIGHER
B12: Year 3 (m) | C12: 180 | D12: OR 35% OF COLLECTIONS WHICHEVER HIGHER
B13: Year 4 (m) | C13: 225 | D13: OR 35% OF COLLECTIONS WHICHEVER HIGHER
B14: Year 5 (m) | C14: 180 | D14: OR 35% OF COLLECTIONS WHICHEVER HIGHER
B15: Year 6 (m) | C15: 90 | D15: OR 35% OF COLLECTIONS WHICHEVER HIGHER
B16: Year 7 (m) | C16: 0 | D16: OR 35% OF COLLECTIONS WHICHEVER HIGHER
B17: Settlement of excess over guarantee | C17: 8
B18: PROJECT DELIVERY | C18: 54 MONTHS
C20: L'AVENIR
B21: Developer Share of Collections | C21: 0.65
B22: Design | C22: Jalour
B23: Permits & License | C23: Jalour
B24: Construction | C24: Jalour
B25: Finishing Standard | C25: CORE & SHELL
B26: Marketing, Sales and Collections | C26: Jalour
B27: Project Branding | C27: Jalour
B28: Operation, Management& Maintenance | C28: Jalour /FM co.
B29: Project Delivery | C29: 54 MONTHS | D29: OR FACILITY MANAGEMENT COMPANY ASSIGNED BY JALOUR

Sheet Cash In Flow Summary
B1: Sales - 20% RETAINED
B2: MEGP
B3: Project | C3: Total Sales | D3: M -9 | E3: M -6 | F3: M -3 | G3: M 0 | H3: M 3 | I3: M 6 | J3: M 9 | K3: M 12 | L3: M 15 | M3: M 18 | N3: M 21 | O3: M 24 | P3: M 27 | Q3: M 30 | R3: M 33 | S3: M 36 | T3: M 39 | U3: M 42 | V3: M 45 | W3: M 48 | X3: M 51 | Y3: M 54 | Z3: M 57 | AA3: M 60 | AB3: M 63 | AC3: M 66 | AD3: M 69 | AE3: M 72 | AF3: M 75 | AG3: M 78 | AH3: M 81 | AI3: M 84 | AJ3: M 87 | AK3: M 90 | AL3: M 93 | AM3: M 96 | AN3: M 99 | AO3: M 102 | AP3: M 105 | AQ3: M 108 | AR3: M 111 | AS3: M 114 | AT3: M 117
B4: L'avenir | C4: =SUM(D4:ZZ4) -> 2673.7357 | D4: ='L''avenir'!E70/1000 -> 0 | E4: ='L''avenir'!F70/1000 -> 0 | F4: ='L''avenir'!G70/1000 -> 0 | G4: ='L''avenir'!H70/1000 -> 0 | H4: ='L''avenir'!I70/1000 -> 18.11565 | I4: ='L''avenir'!J70/1000 -> 36.2313 | J4: ='L''avenir'!K70/1000 -> 58.260825 | K4: ='L''avenir'!L70/1000 -> 69.01839 | ... AT4: ='L''avenir'!AU70/1000 -> 0
B6: Project | C6: Total Sales NPV | D6: M -9 | E6: M -6 | F6: M -3 | G6: M 0 | H6: M 3 | I6: M 6 | J6: M 9 | K6: M 12 | L6: M 15 | M6: M 18 | N6: M 21 | O6: M 24 | P6: M 27 | Q6: M 30 | R6: M 33 | S6: M 36 | T6: M 39 | U6: M 42 | V6: M 45 | W6: M 48 | X6: M 51 | Y6: M 54 | Z6: M 57 | AA6: M 60 | AB6: M 63 | AC6: M 66 | AD6: M 69 | AE6: M 72 | AF6: M 75 | AG6: M 78 | AH6: M 81 | AI6: M 84 | AJ6: M 87 | AK6: M 90 | AL6: M 93 | AM6: M 96 | AN6: M 99 | AO6: M 102 | AP6: M 105 | AQ6: M 108 | AR6: M 111 | AS6: M 114 | AT6: M 117
B7: L'avenir | C7: =SUM(D7:ZZ7) -> 1766.3118 | D7: ='L''avenir'!E71/1000 -> 0 | E7: ='L''avenir'!F71/1000 -> 0 | F7: ='L''avenir'!G71/1000 -> 0 | G7: ='L''avenir'!H71/1000 -> 0 | H7: ='L''avenir'!I71/1000 -> 17.531848 | I7: ='L''avenir'!J71/1000 -> 33.933722 | J7: ='L''avenir'!K71/1000 -> 52.80779 | K7: ='L''avenir'!L71/1000 -> 60.542447 | ... AT7: ='L''avenir'!AU71/1000 -> 0
B9: Accumulated MEGP
B10: Project | C10: Total Sales | D10: M -9 | E10: M -6 | F10: M -3 | G10: M 0 | H10: M 3 | I10: M 6 | J10: M 9 | K10: M 12 | L10: M 15 | M10: M 18 | N10: M 21 | O10: M 24 | P10: M 27 | Q10: M 30 | R10: M 33 | S10: M 36 | T10: M 39 | U10: M 42 | V10: M 45 | W10: M 48 | X10: M 51 | Y10: M 54 | Z10: M 57 | AA10: M 60 | AB10: M 63 | AC10: M 66 | AD10: M 69 | AE10: M 72 | AF10: M 75 | AG10: M 78 | AH10: M 81 | AI10: M 84 | AJ10: M 87 | AK10: M 90 | AL10: M 93 | AM10: M 96 | AN10: M 99 | AO10: M 102 | AP10: M 105 | AQ10: M 108 | AR10: M 111 | AS10: M 114 | AT10: M 117
B11: L'avenir | C11: =MAX(D11:ZZ11) -> 2673.7357 | D11: =D4 -> 0 | E11: =D11+E4 -> 0 | F11: =E11+F4 -> 0 | G11: =F11+G4 -> 0 | H11: =G11+H4 -> 18.11565 | I11: =H11+I4 -> 54.34695 | J11: =I11+J4 -> 112.60778 | K11: =J11+K4 -> 181.62616 | L11: =K11+L4 -> 248.71371 | ... AT11: =AS11+AT4 -> 2673.7357
B13: Project | C13: Total Sales NPV | D13: M -9 | E13: M -6 | F13: M -3 | G13: M 0 | H13: M 3 | I13: M 6 | J13: M 9 | K13: M 12 | L13: M 15 | M13: M 18 | N13: M 21 | O13: M 24 | P13: M 27 | Q13: M 30 | R13: M 33 | S13: M 36 | T13: M 39 | U13: M 42 | V13: M 45 | W13: M 48 | X13: M 51 | Y13: M 54 | Z13: M 57 | AA13: M 60 | AB13: M 63 | AC13: M 66 | AD13: M 69 | AE13: M 72 | AF13: M 75 | AG13: M 78 | AH13: M 81 | AI13: M 84 | AJ13: M 87 | AK13: M 90 | AL13: M 93 | AM13: M 96 | AN13: M 99 | AO13: M 102 | AP13: M 105 | AQ13: M 108 | AR13: M 111 | AS13: M 114 | AT13: M 117
B14: L'avenir | C14: =MAX(D14:ZZ14) -> 1766.3118 | D14: =D7 -> 0 | E14: =D14+E7 -> 0 | F14: =E14+F7 -> 0 | G14: =F14+G7 -> 0 | H14: =G14+H7 -> 17.531848 | I14: =H14+I7 -> 51.46557 | J14: =I14+J7 -> 104.27336 | K14: =J14+K7 -> 164.81581 | L14: =K14+L7 -> 221.76805 | ... AT14: =AS14+AT7 -> 1766.3118
B16: 100% Sales
B17: Project | C17: Total Sales | D17: M -9 | E17: M -6 | F17: M -3 | G17: M 0 | H17: M 3 | I17: M 6 | J17: M 9 | K17: M 12 | L17: M 15 | M17: M 18 | N17: M 21 | O17: M 24 | P17: M 27 | Q17: M 30 | R17: M 33 | S17: M 36 | T17: M 39 | U17: M 42 | V17: M 45 | W17: M 48 | X17: M 51 | Y17: M 54 | Z17: M 57 | AA17: M 60 | AB17: M 63 | AC17: M 66 | AD17: M 69 | AE17: M 72 | AF17: M 75 | AG17: M 78 | AH17: M 81 | AI17: M 84 | AJ17: M 87 | AK17: M 90 | AL17: M 93 | AM17: M 96 | AN17: M 99 | AO17: M 102 | AP17: M 105 | AQ17: M 108 | AR17: M 111 | AS17: M 114 | AT17: M 117
B18: L'avenir | C18: =SUM(D18:ZZ18) -> 3342.1697 | D18: =D4*100/80 -> 0 | E18: =E4*100/80 -> 0 | F18: =F4*100/80 -> 0 | G18: =G4*100/80 -> 0 | H18: =H4*100/80 -> 22.644562 | I18: =I4*100/80 -> 45.289125 | J18: =J4*100/80 -> 72.826031 | K18: =K4*100/80 -> 86.272987 | ... AT18: =AT4*100/80 -> 0
B20: ALAHLY - SABBOUR % | D20: 0.35
B21: Project | C21: Total Sales | D21: M -9 | E21: M -6 | F21: M -3 | G21: M 0 | H21: M 3 | I21: M 6 | J21: M 9 | K21: M 12 | L21: M 15 | M21: M 18 | N21: M 21 | O21: M 24 | P21: M 27 | Q21: M 30 | R21: M 33 | S21: M 36 | T21: M 39 | U21: M 42 | V21: M 45 | W21: M 48 | X21: M 51 | Y21: M 54 | Z21: M 57 | AA21: M 60 | AB21: M 63 | AC21: M 66 | AD21: M 69 | AE21: M 72 | AF21: M 75 | AG21: M 78 | AH21: M 81 | AI21: M 84 | AJ21: M 87 | AK21: M 90 | AL21: M 93 | AM21: M 96 | AN21: M 99 | AO21: M 102 | AP21: M 105 | AQ21: M 108 | AR21: M 111 | AS21: M 114 | AT21: M 117
B22: L'avenir | C22: =SUM(D22:ZZ22) -> 1169.7594 | D22: =D18*$D$20 -> 0 | E22: =E18*$D$20 -> 0 | F22: =F18*$D$20 -> 0 | G22: =G18*$D$20 -> 0 | H22: =H18*$D$20 -> 7.9255969 | I22: =I18*$D$20 -> 15.851194 | J22: =J18*$D$20 -> 25.489111 | K22: =K18*$D$20 -> 30.195546 | ... AT22: =AT18*$D$20 -> 0
B24: ALAHLY - SABBOUR ACCUM
B25: Project | C25: Total Sales | D25: M -9 | E25: M -6 | F25: M -3 | G25: M 0 | H25: M 3 | I25: M 6 | J25: M 9 | K25: M 12 | L25: M 15 | M25: M 18 | N25: M 21 | O25: M 24 | P25: M 27 | Q25: M 30 | R25: M 33 | S25: M 36 | T25: M 39 | U25: M 42 | V25: M 45 | W25: M 48 | X25: M 51 | Y25: M 54 | Z25: M 57 | AA25: M 60 | AB25: M 63 | AC25: M 66 | AD25: M 69 | AE25: M 72 | AF25: M 75 | AG25: M 78 | AH25: M 81 | AI25: M 84 | AJ25: M 87 | AK25: M 90 | AL25: M 93 | AM25: M 96 | AN25: M 99 | AO25: M 102 | AP25: M 105 | AQ25: M 108 | AR25: M 111 | AS25: M 114 | AT25: M 117
B26: L'avenir | C26: =MAX(D26:ZZ26) -> 1169.7594 | D26: =D22 -> 0 | E26: =D26+E22 -> 0 | F26: =E26+F22 -> 0 | G26: =F26+G22 -> 0 | H26: =G26+H22 -> 7.9255969 | I26: =H26+I22 -> 23.776791 | J26: =I26+J22 -> 49.265902 | K26: =J26+K22 -> 79.461447 | L26: =K26+L22 -> 108.81225 | ... AT26: =AS26+AT22 -> 1169.7594

Sheet Net Cash Flow -With DP
B1: Cash Available for Operation after - 20% RETAINED UNITS
B2: Total Collections MEGP
