Workbook

Sheet Cover
A1: Green Square - Financial Annex
A2: Investor ticket EGP 100 million | Strictly private and confidential | Projections only, not guarantees
A4: ALL INFORMATION IN THIS WORKBOOK IS CONFIDENTIAL AND SUBJECT TO THE NON-DISCLOSURE AGREEMENT. Do not copy, forward or disclose it.
A5: Purpose: supports the Investment Memorandum, Pitch Deck and Due Diligence Memorandum. Every figure in those documents traces to the Summary sheet.
A6: Colour code: blue = input or value transcribed from the source model; black = formula; green = link to another sheet.
A7: Units: EGP million unless stated. Quarter-end months. NPV at 14% p.a. (end-of-quarter discounting). IRRs are annualised from quarterly flows.
A8: Sheets: Inputs, Source_Data, Project_CF, Sources_Uses, Option_A, Option_B, Scenarios, Sensitivity, Summary, Reconciliation.
A9: The balance of project funding is provided by Jalour sponsor equity, project collections and other capital sources.
A10: Jalour may raise further capital at project or holding level, subject to the investor's stated rights.
A11: Reconciliation status: | B11: =Reconciliation!D25 -> ALL CHECKS ZERO

Sheet Summary
A1: Green Square: key outputs, ticket EGP 100m (all cells are live links)
A2: USD equivalents at 48 EGP per USD.
A4: Metric | B4: Value | C4: USD m | D4: Source sheet
A5: Project (base case)
A6: Jalour net cash flow, nominal (EGP m) | B6: =Project_CF!$B$18 -> 375.44753 | C6: =B6/Inputs!$B$52 -> 7.8218235 | D6: Project_CF
A7: NPV of net cash flow @ 14% (EGP m) | B7: =Project_CF!$B$19 -> 215.31139 | C7: =B7/Inputs!$B$52 -> 4.485654 | D7: Project_CF
A8: Peak cumulative cash shortage (EGP m) | B8: =-Project_CF!$B$20 -> 102.5 | C8: =B8/Inputs!$B$52 -> 2.1354167 | D8: Project_CF
A9: Month of peak shortage | B9: =Project_CF!$B$21 -> 6 | D9: Project_CF
A10: Total collections, 80% of units sold (EGP m) | B10: =Project_CF!$C$8 -> 2252.979 | C10: =B10/Inputs!$B$52 -> 46.937063 | D10: Project_CF
A11: Landlord payments (EGP m) | B11: =Project_CF!$C$9 -> 985.67831 | D11: Project_CF
A12: Construction, commission and SG&A (EGP m) | B12: =Project_CF!$C$10+Project_CF!$C$11+Project_CF!$C$12 -> 891.85316 | D12: Project_CF
A13: Funding plan
A14: Total uses at peak (EGP m) | B14: =Sources_Uses!B8 -> 112.9574 | C14: =B14/Inputs!$B$52 -> 2.3532792 | D14: Sources_Uses
A15: Balance of project funding (EGP m) | B15: =Sources_Uses!B13 -> 12.9574 | D15: Sources_Uses
A16: Ticket in excess of modelled uses (EGP m) | B16: =Sources_Uses!B15 -> 0 | D16: Sources_Uses
A17: Ticket as % of modelled peak | B17: =Sources_Uses!B16 -> 0.97560976 | D17: Sources_Uses
A18: Ticket above modelled peak (EGP m) | B18: =Sources_Uses!B18 -> 0 | D18: Sources_Uses
A19: Option A (units)
A20: Units face value at launch list (EGP m) | B20: =Option_A!B5 -> 200 | C20: =B20/Inputs!$B$52 -> 4.1666667 | D20: Option_A
A21: Share of launch-tranche inventory | B21: =Option_A!B6 -> 0.33026762 | D21: Option_A
A22: Units value at final list price (EGP m) | B22: =Option_A!B11 -> 286.73835 | D22: Option_A
A23: Investor IRR, base | B23: =Option_A!B26 -> 0.26402991 | D23: Option_A
A24: Investor MOIC, base | B24: =Option_A!B27 -> 2.781362 | D24: Option_A
A25: Investor payback month | B25: =Option_A!B28 -> 54 | D25: Option_A
A26: Investor IRR, downside | B26: =Scenarios!$B$66 -> 0.18640161 | D26: Scenarios
A27: Investor MOIC, downside | B27: =Scenarios!$B$67 -> 2.5032258 | D27: Scenarios
A28: Investor IRR, upside | B28: =Scenarios!$B$102 -> 0.29199284 | D28: Scenarios
A29: Investor MOIC, upside | B29: =Scenarios!$B$103 -> 3.0594982 | D29: Scenarios
A30: Jalour cost of capital | B30: =Option_A!B29 -> 0.20741957 | D30: Option_A
A31: NPV cost to Jalour @ 14% (EGP m) | B31: =Option_A!B30 -> -19.093021 | D31: Option_A
A32: Nominal net cost to Jalour (EGP m) | B32: =Option_A!B31 -> -92 | D32: Option_A
A33: Option B (cash), recommended structure S1
A34: Investor IRR, base | B34: =Option_B!B34 -> 0.26546399 | D34: Option_B
A35: Investor MOIC | B35: =Option_B!B33 -> 2.3 | D35: Option_B
A36: Investor payback month | B36: =Option_B!B46 -> 45 | D36: Option_B
A37: Jalour cost of capital | B37: =Option_B!B35 -> 0.26546399 | D37: Option_B
A38: NPV cost to Jalour @ 14% (EGP m) | B38: =Option_B!B36 -> -42.536579 | D38: Option_B
A39: Lowest quarterly coverage (net cash flow / payout) | B39: =Option_B!B37 -> -8.9504782 | D39: Option_B
A40: Quarters below 1.5x (net cash flow basis) | B40: =Option_B!B38 -> 9 | D40: Option_B
A41: Payout quarters | B41: =Option_B!B39 -> 12 | D41: Option_B
...

Sheet Inputs
A1: Inputs - Green Square, ticket EGP 100m (EGP million unless stated)
A2: Blue = input. Series from the source model are on Source_Data. Every figure traces to a source cell or is labelled ASSUMPTION.
A4: Parameter | B4: Value | C4: Unit | D4: Source / basis
A6: Transaction
A7: Investor ticket | B7: 100 | C7: EGP m | D7: Offer term
A8: Option A: face value multiple of ticket (units at launch list price) | B8: 2 | C8: x | D8: Offer term (Option A)
A9: Option B: total cash return multiple | B9: 2.3 | C9: x | D9: Offer term (Option B)
A10: Option B: grace period | B10: 24 | C10: months | D10: Offer term
A11: Option B: number of quarterly payouts | B11: 12 | C11: quarters | D11: Offer term (3 years)
A12: Investor funding month (t0) | B12: 3 | C12: month | D12: ASSUMPTION: month the down payment falls due in the model ('Net Cash Flow -With DP' row 10)
A13: Project handover month | B13: 48 | C13: month | D13: Source model, Green Square Summary!E4
A14: Discount rate | B14: 0.14 | C14: % p.a. | D14: Source model, sales sheet cell C72 (labelled Cost Of Capital); kept at 14% by Jalour
A15: Option A: investor resale friction | B15: 0.03 | C15: % | D15: ASSUMPTION: broker plus developer transfer fee
A16: Option A: resale spread (quarters from handover + 3 months) | B16: 4 | C16: quarters | D16: ASSUMPTION
A18: Project and landlord terms (source model)
A19: Landlord share of collections | B19: 0.35 | C19: % | D19: Offers DP!C5
A20: Landlord minimum guarantee | B20: 800 | C20: EGP m | D20: Offers DP!C3
A21: Down payment to landlord (10% of guarantee) | B21: 80 | C21: EGP m | D21: Offers DP!C9
A22: Total sales value at 100% of units | B22: 2816.2238 | C22: EGP m | D22: Summary C27 (sold 80% plus retained 20% at modelled prices)
A23: Sales commission rate | B23: 0.04 | C23: % | D23: Summary B19
A24: Professional fees (% of construction cost) | B24: 0.05 | C24: % | D24: Cash Out Detail!C49
A25: Share of professional fees incurred before construction start | B25: 0.3 | C25: % | D25: ASSUMPTION: the model has no pre-construction cost; to be confirmed
A27: Launch price list and tranche values (source model sales sheet)
A28: Launch list price, retail | B28: 225 | C28: EGP k / m2 | D28: First sales column, row 3
A29: Launch list price, offices | B29: 135 | C29: EGP k / m2 | D29: First sales column, row 4
A30: Delivery list price, retail (last list price in the plan) | B30: 300 | C30: EGP k / m2 | D30: Last sales column, row 3
A31: Delivery list price, offices (last list price in the plan) | B31: 200 | C31: EGP k / m2 | D31: Last sales column, row 4
A32: Launch tranches: retail sales value at list | B32: 195.345 | C32: EGP m | D32: First two sales tranches (months 9 and 12), row 24
A33: Launch tranches: office sales value at list | B33: 410.2245 | C33: EGP m | D33: Same tranches, row 25
A34: Price appreciation launch to delivery list (value-weighted) | B34: =($B$32/($B$32+$B$33))*($B$30/$B$28)+($B$33/($B$32+$B$33))*($B$31/$B$29) -> 1.4336918 | C34: x | D34: Calculated. Investor resale value = face x this factor (base)
A36: Option B alternatives (considered, not recommended)
A37: S2: share of collections | B37: 0.24724933 | C37: % | D37: Calibrated (Python) so the base case reaches the target multiple by the end of the payout window
A38: S2: floor per quarter as multiple of equal instalment | B38: 0.4 | C38: x | D38: Design
A39: S2: cap per quarter as multiple of equal instalment | B39: 1.5 | C39: x | D39: Design
A40: S3: fixed minimum multiple | B40: 1.8 | C40: x | D40: Design
A41: S3: total cap multiple | B41: 2.8 | C41: x | D41: Design
A42: S3: share of collections | B42: 0.034752087 | C42: % | D42: Calibrated (Python)
A43: Coverage test threshold | B43: 1.5 | C43: x | D43: Brief
A45: Reference values from the source model (for reconciliation only)
A46: Jalour net cash flow, nominal | B46: 375.44753 | C46: EGP m | D46: 'Net Cash Flow -With DP'!C40
...

Sheet Source_Data
A1: Source model series - Green Square (EGP million, quarter-end months)
A2: Blue = values transcribed from the source model cells named in column B. Columns D onward = quarters 1..60 (month = 3 x quarter).
A4: Series | B4: Source cell / basis | C4: Total
A5: Quarter index | B5: structural | D5: 1 | E5: 2 | F5: 3 | G5: 4 | H5: 5 | I5: 6 | J5: 7 | K5: 8 | L5: 9 | M5: 10 | N5: 11 | O5: 12 | P5: 13 | Q5: 14 | R5: 15 | S5: 16 | T5: 17 | U5: 18 | V5: 19 | W5: 20 | X5: 21 | Y5: 22 | Z5: 23 | AA5: 24 | AB5: 25 | AC5: 26 | AD5: 27 | AE5: 28 | AF5: 29 | AG5: 30 | AH5: 31 | AI5: 32 | AJ5: 33 | AK5: 34 | AL5: 35 | AM5: 36 | AN5: 37 | AO5: 38 | AP5: 39 | AQ5: 40 | AR5: 41 | AS5: 42 | AT5: 43 | AU5: 44 | AV5: 45 | AW5: 46 | AX5: 47 | AY5: 48 | AZ5: 49 | BA5: 50 | BB5: 51 | BC5: 52 | BD5: 53 | BE5: 54 | BF5: 55 | BG5: 56 | BH5: 57 | BI5: 58 | BJ5: 59 | BK5: 60
A6: Month | B6: 3 x index | D6: =D5*3 -> 3 | E6: =E5*3 -> 6 | F6: =F5*3 -> 9 | G6: =G5*3 -> 12 | H6: =H5*3 -> 15 | I6: =I5*3 -> 18 | J6: =J5*3 -> 21 | K6: =K5*3 -> 24 | ... BK6: =BK5*3 -> 180
A7: Collections excluding delivery payments | B7: Net Cash Flow -With DP row 4 less delivery component | C7: =SUM(D7:BK7) -> 1761.2884 | D7: 0 | E7: 0 | F7: 15.139238 | G7: 30.278475 | H7: 46.512006 | I7: 62.745537 | J7: 62.3657 | K7: 63.473559 | L7: 80.328848 | M7: 103.04449 | N7: 127.69775 | O7: 134.93275 | P7: 97.31075 | Q7: 71.309969 | R7: 71.309969 | S7: 68.037036 | T7: 61.22664 | U7: 59.712716 | V7: 53.723945 | W7: 49.382945 | X7: 49.382945 | Y7: 42.102726 | Z7: 42.102726 | AA7: 42.102726 | AB7: 36.314726 | AC7: 33.038627 | AD7: 29.430171 | AE7: 25.089171 | AF7: 25.089171 | AG7: 25.089171 | AH7: 25.089171 | AI7: 25.089171 | AJ7: 25.089171 | AK7: 22.905106 | AL7: 22.905106 | AM7: 18.739554 | AN7: 9.6261675 | AO7: 3.5704725 | AP7: 0 | AQ7: 0 | AR7: 0 | AS7: 0 | AT7: 0 | AU7: 0 | AV7: 0 | AW7: 0 | AX7: 0 | AY7: 0 | AZ7: 0 | BA7: 0 | BB7: 0 | BC7: 0 | BD7: 0 | BE7: 0 | BF7: 0 | BG7: 0 | BH7: 0 | BI7: 0 | BJ7: 0 | BK7: 0
A8: Delivery payments (within collections) | B8: Green Square sheet rows 35-36 | C8: =SUM(D8:BK8) -> 491.6906 | D8: 0 | E8: 0 | F8: 0 | G8: 0 | H8: 0 | I8: 0 | J8: 0 | K8: 0 | L8: 0 | M8: 392.20935 | N8: 57.88 | O8: 41.60125 | P8: 0 | Q8: 0 | R8: 0 | S8: 0 | T8: 0 | U8: 0 | V8: 0 | W8: 0 | X8: 0 | Y8: 0 | Z8: 0 | AA8: 0 | AB8: 0 | AC8: 0 | AD8: 0 | AE8: 0 | AF8: 0 | AG8: 0 | AH8: 0 | AI8: 0 | AJ8: 0 | AK8: 0 | AL8: 0 | AM8: 0 | AN8: 0 | AO8: 0 | AP8: 0 | AQ8: 0 | AR8: 0 | AS8: 0 | AT8: 0 | AU8: 0 | AV8: 0 | AW8: 0 | AX8: 0 | AY8: 0 | AZ8: 0 | BA8: 0 | BB8: 0 | BC8: 0 | BD8: 0 | BE8: 0 | BF8: 0 | BG8: 0 | BH8: 0 | BI8: 0 | BJ8: 0 | BK8: 0
A9: Landlord payments: down payment and guarantee schedule | B9: Net Cash Flow -With DP row 10, schedule part | C9: =SUM(D9:BK9) -> 800 | D9: 91.25 | E9: 11.25 | F9: 11.25 | G9: 11.25 | H9: 22.5 | I9: 22.5 | J9: 22.5 | K9: 22.5 | L9: 33.75 | M9: 33.75 | N9: 33.75 | O9: 33.75 | P9: 45 | Q9: 45 | R9: 45 | S9: 45 | T9: 45 | U9: 45 | V9: 45 | W9: 45 | X9: 22.5 | Y9: 22.5 | Z9: 22.5 | AA9: 22.5 | AB9: 0 | AC9: 0 | AD9: 0 | AE9: 0 | AF9: 0 | AG9: 0 | AH9: 0 | AI9: 0 | AJ9: 0 | AK9: 0 | AL9: 0 | AM9: 0 | AN9: 0 | AO9: 0 | AP9: 0 | AQ9: 0 | AR9: 0 | AS9: 0 | AT9: 0 | AU9: 0 | AV9: 0 | AW9: 0 | AX9: 0 | AY9: 0 | AZ9: 0 | BA9: 0 | BB9: 0 | BC9: 0 | BD9: 0 | BE9: 0 | BF9: 0 | BG9: 0 | BH9: 0 | BI9: 0 | BJ9: 0 | BK9: 0
A10: Landlord payments: excess over guarantee (years 8+) | B10: Same row, excess settlement | C10: =SUM(D10:BK10) -> 185.67831 | D10: 0 | E10: 0 | F10: 0 | G10: 0 | H10: 0 | I10: 0 | J10: 0 | K10: 0 | L10: 0 | M10: 0 | N10: 0 | O10: 0 | P10: 0 | Q10: 0 | R10: 0 | S10: 0 | T10: 0 | U10: 0 | V10: 0 | W10: 0 | X10: 0 | Y10: 0 | Z10: 0 | AA10: 0 | AB10: 0 | AC10: 0 | AD10: 0 | AE10: 0 | AF10: 107.75821 | AG10: 10.976512 | AH10: 10.976512 | AI10: 10.976512 | AJ10: 10.976512 | AK10: 10.020984 | AL10: 10.020984 | AM10: 8.198555 | AN10: 4.2114483 | AO10: 1.5620817 | AP10: 0 | AQ10: 0 | AR10: 0 | AS10: 0 | AT10: 0 | AU10: 0 | AV10: 0 | AW10: 0 | AX10: 0 | AY10: 0 | AZ10: 0 | BA10: 0 | BB10: 0 | BC10: 0 | BD10: 0 | BE10: 0 | BF10: 0 | BG10: 0 | BH10: 0 | BI10: 0 | BJ10: 0 | BK10: 0
A11: Construction cost | B11: Cash Out Detail row 28 | C11: =SUM(D11:BK11) -> 697.16 | D11: 0 | E11: 0 | F11: 0 | G11: 0 | H11: 20 | I11: 26.4 | J11: 40 | K11: 26.4 | L11: 26.4 | M11: 26.4 | N11: 5.28 | O11: 5.28 | P11: 120 | Q11: 120 | R11: 164 | S11: 117 | T11: 0 | U11: 0 | V11: 0 | W11: 0 | X11: 0 | Y11: 0 | Z11: 0 | AA11: 0 | AB11: 0 | AC11: 0 | AD11: 0 | AE11: 0 | AF11: 0 | AG11: 0 | AH11: 0 | AI11: 0 | AJ11: 0 | AK11: 0 | AL11: 0 | AM11: 0 | AN11: 0 | AO11: 0 | AP11: 0 | AQ11: 0 | AR11: 0 | AS11: 0 | AT11: 0 | AU11: 0 | AV11: 0 | AW11: 0 | AX11: 0 | AY11: 0 | AZ11: 0 | BA11: 0 | BB11: 0 | BC11: 0 | BD11: 0 | BE11: 0 | BF11: 0 | BG11: 0 | BH11: 0 | BI11: 0 | BJ11: 0 | BK11: 0
A12: Sales commission | B12: Cash Out Detail row 33 | C12: =SUM(D12:BK12) -> 90.11916 | D12: 0 | E12: 0 | F12: 0 | G12: 0 | H12: 0 | I12: 0 | J12: 12.11139 | K12: 12.11139 | L12: 9.52126 | M12: 9.52126 | N12: 6.98901 | O12: 6.98901 | P12: 7.69804 | Q12: 9.2608 | R12: 9.2608 | S12: 6.6562 | T12: 0 | U12: 0 | V12: 0 | W12: 0 | X12: 0 | Y12: 0 | Z12: 0 | AA12: 0 | AB12: 0 | AC12: 0 | AD12: 0 | AE12: 0 | AF12: 0 | AG12: 0 | AH12: 0 | AI12: 0 | AJ12: 0 | AK12: 0 | AL12: 0 | AM12: 0 | AN12: 0 | AO12: 0 | AP12: 0 | AQ12: 0 | AR12: 0 | AS12: 0 | AT12: 0 | AU12: 0 | AV12: 0 | AW12: 0 | AX12: 0 | AY12: 0 | AZ12: 0 | BA12: 0 | BB12: 0 | BC12: 0 | BD12: 0 | BE12: 0 | BF12: 0 | BG12: 0 | BH12: 0 | BI12: 0 | BJ12: 0 | BK12: 0
A13: SG&A and others (15% of construction) | B13: Cash Out Detail row 38 | C13: =SUM(D13:BK13) -> 104.574 | D13: 0 | E13: 0 | F13: 0 | G13: 0 | H13: 3 | I13: 3.96 | J13: 6 | K13: 3.96 | L13: 3.96 | M13: 3.96 | N13: 0.792 | O13: 0.792 | P13: 18 | Q13: 18 | R13: 24.6 | S13: 17.55 | T13: 0 | U13: 0 | V13: 0 | W13: 0 | X13: 0 | Y13: 0 | Z13: 0 | AA13: 0 | AB13: 0 | AC13: 0 | AD13: 0 | AE13: 0 | AF13: 0 | AG13: 0 | AH13: 0 | AI13: 0 | AJ13: 0 | AK13: 0 | AL13: 0 | AM13: 0 | AN13: 0 | AO13: 0 | AP13: 0 | AQ13: 0 | AR13: 0 | AS13: 0 | AT13: 0 | AU13: 0 | AV13: 0 | AW13: 0 | AX13: 0 | AY13: 0 | AZ13: 0 | BA13: 0 | BB13: 0 | BC13: 0 | BD13: 0 | BE13: 0 | BF13: 0 | BG13: 0 | BH13: 0 | BI13: 0 | BJ13: 0 | BK13: 0
A14: Launch tranches: collections, retail and offices | B14: Green Square sheet rows 31-36, 38-69 for the first two sales tranches | C14: =SUM(D14:BK14) -> 605.5695 | D14: 0 | E14: 0 | F14: 15.139238 | G14: 30.278475 | H14: 22.708856 | I14: 15.139238 | J14: 15.139238 | K14: 15.139238 | L14: 15.139238 | M14: 136.25314 | N14: 15.139238 | O14: 15.139238 | P14: 15.139238 | Q14: 15.139238 | R14: 15.139238 | S14: 15.139238 | T14: 13.625314 | U14: 12.11139 | V14: 12.11139 | W14: 12.11139 | X14: 12.11139 | Y14: 12.11139 | Z14: 12.11139 | AA14: 12.11139 | AB14: 12.11139 | AC14: 12.11139 | AD14: 12.11139 | AE14: 12.11139 | AF14: 12.11139 | AG14: 12.11139 | AH14: 12.11139 | AI14: 12.11139 | AJ14: 12.11139 | AK14: 12.11139 | AL14: 12.11139 | AM14: 12.11139 | AN14: 6.055695 | AO14: 0 | AP14: 0 | AQ14: 0 | AR14: 0 | AS14: 0 | AT14: 0 | AU14: 0 | AV14: 0 | AW14: 0 | AX14: 0 | AY14: 0 | AZ14: 0 | BA14: 0 | BB14: 0 | BC14: 0 | BD14: 0 | BE14: 0 | BF14: 0 | BG14: 0 | BH14: 0 | BI14: 0 | BJ14: 0 | BK14: 0
A15: Launch tranches: collections, retail | B15: same, commercial rows | C15: =SUM(D15:BK15) -> 195.345 | D15: 0 | E15: 0 | F15: 4.883625 | G15: 9.76725 | H15: 7.3254375 | I15: 4.883625 | J15: 4.883625 | K15: 4.883625 | L15: 4.883625 | M15: 43.952625 | N15: 4.883625 | O15: 4.883625 | P15: 4.883625 | Q15: 4.883625 | R15: 4.883625 | S15: 4.883625 | T15: 4.3952625 | U15: 3.9069 | V15: 3.9069 | W15: 3.9069 | X15: 3.9069 | Y15: 3.9069 | Z15: 3.9069 | AA15: 3.9069 | AB15: 3.9069 | AC15: 3.9069 | AD15: 3.9069 | AE15: 3.9069 | AF15: 3.9069 | AG15: 3.9069 | AH15: 3.9069 | AI15: 3.9069 | AJ15: 3.9069 | AK15: 3.9069 | AL15: 3.9069 | AM15: 3.9069 | AN15: 1.95345 | AO15: 0 | AP15: 0 | AQ15: 0 | AR15: 0 | AS15: 0 | AT15: 0 | AU15: 0 | AV15: 0 | AW15: 0 | AX15: 0 | AY15: 0 | AZ15: 0 | BA15: 0 | BB15: 0 | BC15: 0 | BD15: 0 | BE15: 0 | BF15: 0 | BG15: 0 | BH15: 0 | BI15: 0 | BJ15: 0 | BK15: 0
A16: Launch tranches: collections, offices | B16: same, admin rows | C16: =SUM(D16:BK16) -> 410.2245 | D16: 0 | E16: 0 | F16: 10.255612 | G16: 20.511225 | H16: 15.383419 | I16: 10.255612 | J16: 10.255612 | K16: 10.255612 | L16: 10.255612 | M16: 92.300512 | N16: 10.255612 | O16: 10.255612 | P16: 10.255612 | Q16: 10.255612 | R16: 10.255612 | S16: 10.255612 | T16: 9.2300513 | U16: 8.20449 | V16: 8.20449 | W16: 8.20449 | X16: 8.20449 | Y16: 8.20449 | Z16: 8.20449 | AA16: 8.20449 | AB16: 8.20449 | AC16: 8.20449 | AD16: 8.20449 | AE16: 8.20449 | AF16: 8.20449 | AG16: 8.20449 | AH16: 8.20449 | AI16: 8.20449 | AJ16: 8.20449 | AK16: 8.20449 | AL16: 8.20449 | AM16: 8.20449 | AN16: 4.102245 | AO16: 0 | AP16: 0 | AQ16: 0 | AR16: 0 | AS16: 0 | AT16: 0 | AU16: 0 | AV16: 0 | AW16: 0 | AX16: 0 | AY16: 0 | AZ16: 0 | BA16: 0 | BB16: 0 | BC16: 0 | BD16: 0 | BE16: 0 | BF16: 0 | BG16: 0 | BH16: 0 | BI16: 0 | BJ16: 0 | BK16: 0
A17: Launch tranches: sales value at the quarter commission is paid (12 months after sale) | B17: Cash Out Detail row 33 timing | C17: =SUM(D17:BK17) -> 605.5695 | D17: 0 | E17: 0 | F17: 0 | G17: 0 | H17: 0 | I17: 0 | J17: 302.78475 | K17: 302.78475 | L17: 0 | M17: 0 | N17: 0 | O17: 0 | P17: 0 | Q17: 0 | R17: 0 | S17: 0 | T17: 0 | U17: 0 | V17: 0 | W17: 0 | X17: 0 | Y17: 0 | Z17: 0 | AA17: 0 | AB17: 0 | AC17: 0 | AD17: 0 | AE17: 0 | AF17: 0 | AG17: 0 | AH17: 0 | AI17: 0 | AJ17: 0 | AK17: 0 | AL17: 0 | AM17: 0 | AN17: 0 | AO17: 0 | AP17: 0 | AQ17: 0 | AR17: 0 | AS17: 0 | AT17: 0 | AU17: 0 | AV17: 0 | AW17: 0 | AX17: 0 | AY17: 0 | AZ17: 0 | BA17: 0 | BB17: 0 | BC17: 0 | BD17: 0 | BE17: 0 | BF17: 0 | BG17: 0 | BH17: 0 | BI17: 0 | BJ17: 0 | BK17: 0

Sheet Project_CF
A1: Green Square: project cash flow to Jalour, base case (quarterly, as per the source model)
A2: Net cash flow = collections less landlord payments, construction, commission and SG&A. Positive = cash in.
A4: Line (EGP m) | B4: Unit | C4: Total
A5: Quarter | D5: =Source_Data!D$5 -> 1 | E5: =Source_Data!E$5 -> 2 | F5: =Source_Data!F$5 -> 3 | G5: =Source_Data!G$5 -> 4 | H5: =Source_Data!H$5 -> 5 | I5: =Source_Data!I$5 -> 6 | J5: =Source_Data!J$5 -> 7 | K5: =Source_Data!K$5 -> 8 | ... BK5: =Source_Data!BK$5 -> 60
A6: Month | D6: =Source_Data!D$6 -> 3 | E6: =Source_Data!E$6 -> 6 | F6: =Source_Data!F$6 -> 9 | G6: =Source_Data!G$6 -> 12 | H6: =Source_Data!H$6 -> 15 | I6: =Source_Data!I$6 -> 18 | J6: =Source_Data!J$6 -> 21 | K6: =Source_Data!K$6 -> 24 | ... BK6: =Source_Data!BK$6 -> 180
A7: Years from month 0 | D7: =D6/12 -> 0.25 | E7: =E6/12 -> 0.5 | F7: =F6/12 -> 0.75 | G7: =G6/12 -> 1 | H7: =H6/12 -> 1.25 | I7: =I6/12 -> 1.5 | J7: =J6/12 -> 1.75 | K7: =K6/12 -> 2 | ... BK7: =BK6/12 -> 15
A8: Collections (80% of units sold) | C8: =SUM(D8:BK8) -> 2252.979 | D8: =Source_Data!D$7+Source_Data!D$8 -> 0 | E8: =Source_Data!E$7+Source_Data!E$8 -> 0 | F8: =Source_Data!F$7+Source_Data!F$8 -> 15.139238 | G8: =Source_Data!G$7+Source_Data!G$8 -> 30.278475 | H8: =Source_Data!H$7+Source_Data!H$8 -> 46.512006 | I8: =Source_Data!I$7+Source_Data!I$8 -> 62.745537 | J8: =Source_Data!J$7+Source_Data!J$8 -> 62.3657 | K8: =Source_Data!K$7+Source_Data!K$8 -> 63.473559 | ... BK8: =Source_Data!BK$7+Source_Data!BK$8 -> 0
A9: Landlord payments (35% share, guarantee, down payment) | C9: =SUM(D9:BK9) -> 985.67831 | D9: =Source_Data!D$9+Source_Data!D$10 -> 91.25 | E9: =Source_Data!E$9+Source_Data!E$10 -> 11.25 | F9: =Source_Data!F$9+Source_Data!F$10 -> 11.25 | G9: =Source_Data!G$9+Source_Data!G$10 -> 11.25 | H9: =Source_Data!H$9+Source_Data!H$10 -> 22.5 | I9: =Source_Data!I$9+Source_Data!I$10 -> 22.5 | J9: =Source_Data!J$9+Source_Data!J$10 -> 22.5 | K9: =Source_Data!K$9+Source_Data!K$10 -> 22.5 | ... BK9: =Source_Data!BK$9+Source_Data!BK$10 -> 0
A10: Construction cost | C10: =SUM(D10:BK10) -> 697.16 | D10: =Source_Data!D$11 -> 0 | E10: =Source_Data!E$11 -> 0 | F10: =Source_Data!F$11 -> 0 | G10: =Source_Data!G$11 -> 0 | H10: =Source_Data!H$11 -> 20 | I10: =Source_Data!I$11 -> 26.4 | J10: =Source_Data!J$11 -> 40 | K10: =Source_Data!K$11 -> 26.4 | ... BK10: =Source_Data!BK$11 -> 0
A11: Sales commission | C11: =SUM(D11:BK11) -> 90.11916 | D11: =Source_Data!D$12 -> 0 | E11: =Source_Data!E$12 -> 0 | F11: =Source_Data!F$12 -> 0 | G11: =Source_Data!G$12 -> 0 | H11: =Source_Data!H$12 -> 0 | I11: =Source_Data!I$12 -> 0 | J11: =Source_Data!J$12 -> 12.11139 | K11: =Source_Data!K$12 -> 12.11139 | ... BK11: =Source_Data!BK$12 -> 0
A12: SG&A and others | C12: =SUM(D12:BK12) -> 104.574 | D12: =Source_Data!D$13 -> 0 | E12: =Source_Data!E$13 -> 0 | F12: =Source_Data!F$13 -> 0 | G12: =Source_Data!G$13 -> 0 | H12: =Source_Data!H$13 -> 3 | I12: =Source_Data!I$13 -> 3.96 | J12: =Source_Data!J$13 -> 6 | K12: =Source_Data!K$13 -> 3.96 | ... BK12: =Source_Data!BK$13 -> 0
A13: Net cash flow | C13: =SUM(D13:BK13) -> 375.44753 | D13: =D8-D9-D10-D11-D12 -> -91.25 | E13: =E8-E9-E10-E11-E12 -> -11.25 | F13: =F8-F9-F10-F11-F12 -> 3.8892375 | G13: =G8-G9-G10-G11-G12 -> 19.028475 | H13: =H8-H9-H10-H11-H12 -> 1.0120062 | I13: =I8-I9-I10-I11-I12 -> 9.8855375 | J13: =J8-J9-J10-J11-J12 -> -18.24569 | K13: =K8-K9-K10-K11-K12 -> -1.4978306 | ... BK13: =BK8-BK9-BK10-BK11-BK12 -> 0
A14: Cumulative net cash flow | D14: =D13 -> -91.25 | E14: =D14+E13 -> -102.5 | F14: =E14+F13 -> -98.610763 | G14: =F14+G13 -> -79.582288 | H14: =G14+H13 -> -78.570281 | I14: =H14+I13 -> -68.684744 | J14: =I14+J13 -> -86.930434 | K14: =J14+K13 -> -88.428264 | L14: =K14+L13 -> -81.730676 | ... BK14: =BJ14+BK13 -> 375.44753
A15: Discount factor | D15: =1/(1+Inputs!$B$14)^D7 -> 0.96777364 | E15: =1/(1+Inputs!$B$14)^E7 -> 0.93658581 | F15: =1/(1+Inputs!$B$14)^F7 -> 0.90640306 | G15: =1/(1+Inputs!$B$14)^G7 -> 0.87719298 | H15: =1/(1+Inputs!$B$14)^H7 -> 0.84892424 | I15: =1/(1+Inputs!$B$14)^I7 -> 0.8215665 | J15: =1/(1+Inputs!$B$14)^J7 -> 0.7950904 | K15: =1/(1+Inputs!$B$14)^K7 -> 0.76946753 | ... BK15: =1/(1+Inputs!$B$14)^BK7 -> 0.14009648
A16: Present value of net cash flow | C16: =SUM(D16:BK16) -> 215.31139 | D16: =D13*D15 -> -88.309344 | E16: =E13*E15 -> -10.53659 | F16: =F13*F15 -> 3.5252168 | G16: =G13*G15 -> 16.691645 | H16: =H13*H15 -> 0.85911664 | I16: =I13*I15 -> 8.1216265 | J16: =J13*J15 -> -14.506973 | K16: =K13*K15 -> -1.152532 | ... BK16: =BK13*BK15 -> 0
A18: Net cash flow, nominal | B18: =C13 -> 375.44753
A19: NPV of net cash flow @ discount rate | B19: =C16 -> 215.31139
A20: Peak cumulative cash shortage | B20: =MIN(D14:BK14) -> -102.5
A21: Month of peak shortage | B21: =INDEX(D6:BK6,MATCH(B20,D14:BK14,0)) -> 6

Sheet Sources_Uses
A1: Green Square: sources and uses of funds at the modelled peak, ticket EGP 100m
A2: Nothing is ring-fenced: the ticket is project funding, not a restricted account.
A4: Uses (EGP m) | B4: Amount | C4: Basis
A5: Down payment to landlord | B5: =Inputs!$B$21 -> 80 | C5: Source model
A6: Landlord guarantee instalments and working capital to modelled peak, net of collections | B6: =-Project_CF!$B$20-Inputs!$B$21 -> 22.5 | C6: Peak shortage less down payment
A7: Design, permits and pre-construction (ASSUMPTION) | B7: =Inputs!$B$24*Project_CF!$C$10*Inputs!$B$25 -> 10.4574 | C7: 30% of the 5% professional-fee line, incurred ahead of construction start
A8: Total uses at peak | B8: =SUM(B5:B7) -> 112.9574
A11: Sources (EGP m) | B11: Amount | C11: Basis
A12: Investor ticket | B12: =Inputs!$B$7 -> 100 | C12: This offer
A13: Balance of project funding | B13: =MAX(0,B8-B12) -> 12.9574 | C13: The balance of project funding is provided by Jalour sponsor equity, project collections and other capital sources.
A14: Total sources | B14: =B12+B13 -> 112.9574
A15: Ticket in excess of modelled uses (general project liquidity, not ring-fenced) | B15: =MAX(0,B12-B8) -> 0 | C15: Flag if above zero
A16: Ticket as % of modelled peak shortage | B16: =B12/-Project_CF!$B$20 -> 0.97560976
A17: Ticket applied to uses as % of total uses | B17: =MIN(B12,B8)/B8 -> 0.8852895
A18: Ticket above modelled peak shortage | B18: =MAX(0,B12+Project_CF!$B$20) -> 0 | C18: Flag if above zero
A20: Funding-gap exposure (sponsor covers gaps in excess of project cash)

Sheet Option_A
A1: Green Square: Option A (units), ticket EGP 100m
A2: Units priced at launch list; allocated from the first two sales tranches; Jalour bears the landlord 35% on those units (landlord payments unchanged).
A4: Allocation | B4: Value | C4: Unit
A5: Face value of units at launch list | B5: =Inputs!$B$8*Inputs!$B$7 -> 200 | C5: EGP m
A6: Share of launch-tranche inventory allocated | B6: =B5/Inputs!$B$55 -> 0.33026762
A7: of which retail | B7: =B5*Inputs!$B$32/Inputs!$B$55 -> 64.516129 | C7: EGP m
A8: of which offices | B8: =B5*Inputs!$B$33/Inputs!$B$55 -> 135.48387 | C8: EGP m
A9: Retail area allocated | B9: =B7*1000/Inputs!$B$28 -> 286.73835 | C9: m2
A10: Office area allocated | B10: =B8*1000/Inputs!$B$29 -> 1003.5842 | C10: m2
A11: Value at delivery list price (before resale friction) | B11: =B5*Inputs!$B$34 -> 286.73835 | C11: EGP m
A12: Landlord 35% on the allocated units, borne by Jalour | B12: =Inputs!$B$19*B5 -> 70 | C12: EGP m
A15: Quarterly flows (EGP m) | B15: Total
A16: Month | D16: =Source_Data!D$6 -> 3 | E16: =Source_Data!E$6 -> 6 | F16: =Source_Data!F$6 -> 9 | G16: =Source_Data!G$6 -> 12 | H16: =Source_Data!H$6 -> 15 | I16: =Source_Data!I$6 -> 18 | J16: =Source_Data!J$6 -> 21 | K16: =Source_Data!K$6 -> 24 | ... BK16: =Source_Data!BK$6 -> 180
A17: Investor cash flow (base) | B17: =SUM(D17:BK17) -> 178.1362 | D17: =IF(Source_Data!D$6=Inputs!$B$12,-Inputs!$B$7,0)+IF(AND(Source_Data!D$6>=Inputs!$B$13+3,Source_Data!D$6<Inputs!$B$13+3+3*Inputs!$B$16,MOD(Source_Data!D$6-(Inputs!$B$13+3),3)=0),$B$5*Inputs!$B$34*(1-Inputs!$B$15)/Inputs!$B$16,0) -> -100 | E17: =IF(Source_Data!E$6=Inputs!$B$12,-Inputs!$B$7,0)+IF(AND(Source_Data!E$6>=Inputs!$B$13+3,Source_Data!E$6<Inputs!$B$13+3+3*Inputs!$B$16,MOD(Source_Data!E$6-(Inputs!$B$13+3),3)=0),$B$5*Inputs!$B$34*(1-Inputs!$B$15)/Inputs!$B$16,0) -> 0 | F17: =IF(Source_Data!F$6=Inputs!$B$12,-Inputs!$B$7,0)+IF(AND(Source_Data!F$6>=Inputs!$B$13+3,Source_Data!F$6<Inputs!$B$13+3+3*Inputs!$B$16,MOD(Source_Data!F$6-(Inputs!$B$13+3),3)=0),$B$5*Inputs!$B$34*(1-Inputs!$B$15)/Inputs!$B$16,0) -> 0 | G17: =IF(Source_Data!G$6=Inputs!$B$12,-Inputs!$B$7,0)+IF(AND(Source_Data!G$6>=Inputs!$B$13+3,Source_Data!G$6<Inputs!$B$13+3+3*Inputs!$B$16,MOD(Source_Data!G$6-(Inputs!$B$13+3),3)=0),$B$5*Inputs!$B$34*(1-Inputs!$B$15)/Inputs!$B$16,0) -> 0 | H17: =IF(Source_Data!H$6=Inputs!$B$12,-Inputs!$B$7,0)+IF(AND(Source_Data!H$6>=Inputs!$B$13+3,Source_Data!H$6<Inputs!$B$13+3+3*Inputs!$B$16,MOD(Source_Data!H$6-(Inputs!$B$13+3),3)=0),$B$5*Inputs!$B$34*(1-Inputs!$B$15)/Inputs!$B$16,0) -> 0 | I17: =IF(Source_Data!I$6=Inputs!$B$12,-Inputs!$B$7,0)+IF(AND(Source_Data!I$6>=Inputs!$B$13+3,Source_Data!I$6<Inputs!$B$13+3+3*Inputs!$B$16,MOD(Source_Data!I$6-(Inputs!$B$13+3),3)=0),$B$5*Inputs!$B$34*(1-Inputs!$B$15)/Inputs!$B$16,0) -> 0 | J17: =IF(Source_Data!J$6=Inputs!$B$12,-Inputs!$B$7,0)+IF(AND(Source_Data!J$6>=Inputs!$B$13+3,Source_Data!J$6<Inputs!$B$13+3+3*Inputs!$B$16,MOD(Source_Data!J$6-(Inputs!$B$13+3),3)=0),$B$5*Inputs!$B$34*(1-Inputs!$B$15)/Inputs!$B$16,0) -> 0 | K17: =IF(Source_Data!K$6=Inputs!$B$12,-Inputs!$B$7,0)+IF(AND(Source_Data!K$6>=Inputs!$B$13+3,Source_Data!K$6<Inputs!$B$13+3+3*Inputs!$B$16,MOD(Source_Data!K$6-(Inputs!$B$13+3),3)=0),$B$5*Inputs!$B$34*(1-Inputs!$B$15)/Inputs!$B$16,0) -> 0 | ... BK17: =IF(Source_Data!BK$6=Inputs!$B$12,-Inputs!$B$7,0)+IF(AND(Source_Data!BK$6>=Inputs!$B$13+3,Source_Data!BK$6<Inputs!$B$13+3+3*Inputs!$B$16,MOD(Source_Data!BK$6-(Inputs!$B$13+3),3)=0),$B$5*Inputs!$B$34*(1-Inputs!$B$15)/Inputs!$B$16,0) -> 0
A18: Jalour: ticket received | B18: =SUM(D18:BK18) -> 100 | D18: =IF(Source_Data!D$6=Inputs!$B$12,Inputs!$B$7,0) -> 100 | E18: =IF(Source_Data!E$6=Inputs!$B$12,Inputs!$B$7,0) -> 0 | F18: =IF(Source_Data!F$6=Inputs!$B$12,Inputs!$B$7,0) -> 0 | G18: =IF(Source_Data!G$6=Inputs!$B$12,Inputs!$B$7,0) -> 0 | H18: =IF(Source_Data!H$6=Inputs!$B$12,Inputs!$B$7,0) -> 0 | I18: =IF(Source_Data!I$6=Inputs!$B$12,Inputs!$B$7,0) -> 0 | J18: =IF(Source_Data!J$6=Inputs!$B$12,Inputs!$B$7,0) -> 0 | K18: =IF(Source_Data!K$6=Inputs!$B$12,Inputs!$B$7,0) -> 0 | ... BK18: =IF(Source_Data!BK$6=Inputs!$B$12,Inputs!$B$7,0) -> 0
A19: Jalour: collections forgone on allocated units | B19: =SUM(D19:BK19) -> -200 | D19: =-$B$6*Source_Data!D$14 -> 0 | E19: =-$B$6*Source_Data!E$14 -> 0 | F19: =-$B$6*Source_Data!F$14 -> -5 | G19: =-$B$6*Source_Data!G$14 -> -10 | H19: =-$B$6*Source_Data!H$14 -> -7.5 | I19: =-$B$6*Source_Data!I$14 -> -5 | J19: =-$B$6*Source_Data!J$14 -> -5 | K19: =-$B$6*Source_Data!K$14 -> -5 | ... BK19: =-$B$6*Source_Data!BK$14 -> 0
A20: Jalour: commission saved | B20: =SUM(D20:BK20) -> 8 | D20: =$B$6*Source_Data!D$17*Inputs!$B$23 -> 0 | E20: =$B$6*Source_Data!E$17*Inputs!$B$23 -> 0 | F20: =$B$6*Source_Data!F$17*Inputs!$B$23 -> 0 | G20: =$B$6*Source_Data!G$17*Inputs!$B$23 -> 0 | H20: =$B$6*Source_Data!H$17*Inputs!$B$23 -> 0 | I20: =$B$6*Source_Data!I$17*Inputs!$B$23 -> 0 | J20: =$B$6*Source_Data!J$17*Inputs!$B$23 -> 4 | K20: =$B$6*Source_Data!K$17*Inputs!$B$23 -> 4 | ... BK20: =$B$6*Source_Data!BK$17*Inputs!$B$23 -> 0
A21: Jalour: net incremental cash flow | B21: =SUM(D21:BK21) -> -92 | D21: =D18+D19+D20 -> 100 | E21: =E18+E19+E20 -> 0 | F21: =F18+F19+F20 -> -5 | G21: =G18+G19+G20 -> -10 | H21: =H18+H19+H20 -> -7.5 | I21: =I18+I19+I20 -> -5 | J21: =J18+J19+J20 -> -1 | K21: =K18+K19+K20 -> -1 | ... BK21: =BK18+BK19+BK20 -> 0
A22: Jalour: pooled position effect (cumulative) | D22: =D21 -> 100 | E22: =D22+E21 -> 100 | F22: =E22+F21 -> 95 | G22: =F22+G21 -> 85 | H22: =G22+H21 -> 77.5 | I22: =H22+I21 -> 72.5 | J22: =I22+J21 -> 71.5 | K22: =J22+K21 -> 70.5 | L22: =K22+L21 -> 65.5 | ... BK22: =BJ22+BK21 -> -92
A25: Returns | B25: Value | C25: Note
A26: Investor IRR, base | B26: =(1+IRR(D17:BK17,0.05))^4-1 -> 0.26402991 | C26: Appreciation to delivery list price in the model
A27: Investor MOIC, base | B27: =SUMIF(D17:BK17,">0")/-SUMIF(D17:BK17,"<0") -> 2.781362
A28: Investor payback month | B28: =INDEX(D16:BK16,MATCH(1,D36:BK36,0)) -> 54 | C28: First quarter cumulative cash is not negative
A29: Jalour cost of capital (IRR of ticket vs forgone collections) | B29: =(1+IRR(D21:BK21,0.05))^4-1 -> 0.20741957 | C29: Jalour bears landlord share
A30: NPV to Jalour @ discount rate | B30: =SUMPRODUCT(D21:BK21,Project_CF!$D$15:$BK$15) -> -19.093021
A31: Nominal net cost to Jalour | B31: =B21 -> -92
A32: Project NPV after the deal | B32: =Project_CF!$B$19+B30 -> 196.21837 | C32: Project NPV before the deal plus deal NPV
A33: Peak cumulative shortage excluding ticket cash (after forgone collections) | B33: =MIN(D38:BK38) -> -117.92826 | C33: Project cumulative plus deal effect, ticket cash excluded
A35: Investor cumulative cash flow | D35: =D17 -> -100 | E35: =D35+E17 -> -100 | F35: =E35+F17 -> -100 | G35: =F35+G17 -> -100 | H35: =G35+H17 -> -100 | I35: =H35+I17 -> -100 | J35: =I35+J17 -> -100 | K35: =J35+K17 -> -100 | L35: =K35+L17 -> -100 | ... BK35: =BJ35+BK17 -> 178.1362
A36: Cumulative not negative (1/0) | D36: =IF(AND(D35>=0,D16>Inputs!$B$12),1,0) -> 0 | E36: =IF(AND(E35>=0,E16>Inputs!$B$12),1,0) -> 0 | F36: =IF(AND(F35>=0,F16>Inputs!$B$12),1,0) -> 0 | G36: =IF(AND(G35>=0,G16>Inputs!$B$12),1,0) -> 0 | H36: =IF(AND(H35>=0,H16>Inputs!$B$12),1,0) -> 0 | I36: =IF(AND(I35>=0,I16>Inputs!$B$12),1,0) -> 0 | J36: =IF(AND(J35>=0,J16>Inputs!$B$12),1,0) -> 0 | K36: =IF(AND(K35>=0,K16>Inputs!$B$12),1,0) -> 0 | ... BK36: =IF(AND(BK35>=0,BK16>Inputs!$B$12),1,0) -> 1
A37: Ticket cash received (cumulative) | D37: =IF(D16>=Inputs!$B$12,Inputs!$B$7,0) -> 100 | E37: =IF(E16>=Inputs!$B$12,Inputs!$B$7,0) -> 100 | F37: =IF(F16>=Inputs!$B$12,Inputs!$B$7,0) -> 100 | G37: =IF(G16>=Inputs!$B$12,Inputs!$B$7,0) -> 100 | H37: =IF(H16>=Inputs!$B$12,Inputs!$B$7,0) -> 100 | I37: =IF(I16>=Inputs!$B$12,Inputs!$B$7,0) -> 100 | J37: =IF(J16>=Inputs!$B$12,Inputs!$B$7,0) -> 100 | K37: =IF(K16>=Inputs!$B$12,Inputs!$B$7,0) -> 100 | ... BK37: =IF(BK16>=Inputs!$B$12,Inputs!$B$7,0) -> 100
A38: Project cumulative cash plus deal effect, ticket cash excluded | D38: =Project_CF!D14+D22-D37 -> -91.25 | E38: =Project_CF!E14+E22-E37 -> -102.5 | F38: =Project_CF!F14+F22-F37 -> -103.61076 | G38: =Project_CF!G14+G22-G37 -> -94.582288 | H38: =Project_CF!H14+H22-H37 -> -101.07028 | I38: =Project_CF!I14+I22-I37 -> -96.184744 | J38: =Project_CF!J14+J22-J37 -> -115.43043 | K38: =Project_CF!K14+K22-K37 -> -117.92826 | ... BK38: =Project_CF!BK14+BK22-BK37 -> 183.44753
A40: Face multiple sensitivity | B40: Investor IRR | C40: Investor MOIC
A41: 1.5 | B41: =(1+IRR(D50:BK50,0.05))^4-1 -> 0.18330574 | C41: =SUMIF(D50:BK50,">0")/-SUMIF(D50:BK50,"<0") -> 2.0860215
A42: 1.75 | B42: =(1+IRR(D51:BK51,0.05))^4-1 -> 0.22588591 | C42: =SUMIF(D51:BK51,">0")/-SUMIF(D51:BK51,"<0") -> 2.4336918
A43: 2 | B43: =(1+IRR(D52:BK52,0.05))^4-1 -> 0.26402991 | C43: =SUMIF(D52:BK52,">0")/-SUMIF(D52:BK52,"<0") -> 2.781362
A44: 2.25 | B44: =(1+IRR(D53:BK53,0.05))^4-1 -> 0.29867736 | C44: =SUMIF(D53:BK53,">0")/-SUMIF(D53:BK53,"<0") -> 3.1290323
A45: 2.5 | B45: =(1+IRR(D54:BK54,0.05))^4-1 -> 0.33048927 | C45: =SUMIF(D54:BK54,">0")/-SUMIF(D54:BK54,"<0") -> 3.4767025
A47: Early assignment 24 months after funding (units at face, no appreciation) | B47: Investor IRR | C47: Investor MOIC
A48: 0 | B48: =(1+IRR(D56:BK56,0.05))^4-1 -> 0.39283883 | C48: =SUMIF(D56:BK56,">0")/-SUMIF(D56:BK56,"<0") -> 1.94
...

Sheet Option_B
A1: Green Square: Option B (cash), ticket EGP 100m
A2: S1 is the recommended structure. S2 and S3 are alternatives considered. Payouts after a grace period; nothing is held in a restricted account.
A4: Quarterly flows (EGP m) | B4: Total
A5: Month | D5: =Source_Data!D$6 -> 3 | E5: =Source_Data!E$6 -> 6 | F5: =Source_Data!F$6 -> 9 | G5: =Source_Data!G$6 -> 12 | H5: =Source_Data!H$6 -> 15 | I5: =Source_Data!I$6 -> 18 | J5: =Source_Data!J$6 -> 21 | K5: =Source_Data!K$6 -> 24 | ... BK5: =Source_Data!BK$6 -> 180
A6: Payout window flag | D6: =IF(AND(Source_Data!D$6>=Inputs!$B$54,Source_Data!D$6<Inputs!$B$54+3*Inputs!$B$11),1,0) -> 0 | E6: =IF(AND(Source_Data!E$6>=Inputs!$B$54,Source_Data!E$6<Inputs!$B$54+3*Inputs!$B$11),1,0) -> 0 | F6: =IF(AND(Source_Data!F$6>=Inputs!$B$54,Source_Data!F$6<Inputs!$B$54+3*Inputs!$B$11),1,0) -> 0 | G6: =IF(AND(Source_Data!G$6>=Inputs!$B$54,Source_Data!G$6<Inputs!$B$54+3*Inputs!$B$11),1,0) -> 0 | H6: =IF(AND(Source_Data!H$6>=Inputs!$B$54,Source_Data!H$6<Inputs!$B$54+3*Inputs!$B$11),1,0) -> 0 | I6: =IF(AND(Source_Data!I$6>=Inputs!$B$54,Source_Data!I$6<Inputs!$B$54+3*Inputs!$B$11),1,0) -> 0 | J6: =IF(AND(Source_Data!J$6>=Inputs!$B$54,Source_Data!J$6<Inputs!$B$54+3*Inputs!$B$11),1,0) -> 0 | K6: =IF(AND(Source_Data!K$6>=Inputs!$B$54,Source_Data!K$6<Inputs!$B$54+3*Inputs!$B$11),1,0) -> 0 | ... BK6: =IF(AND(Source_Data!BK$6>=Inputs!$B$54,Source_Data!BK$6<Inputs!$B$54+3*Inputs!$B$11),1,0) -> 0
A7: Net cash flow before payouts (Project_CF) | B7: =SUM(D7:BK7) -> 375.44753 | D7: =Project_CF!D13 -> -91.25 | E7: =Project_CF!E13 -> -11.25 | F7: =Project_CF!F13 -> 3.8892375 | G7: =Project_CF!G13 -> 19.028475 | H7: =Project_CF!H13 -> 1.0120062 | I7: =Project_CF!I13 -> 9.8855375 | J7: =Project_CF!J13 -> -18.24569 | K7: =Project_CF!K13 -> -1.4978306 | ... BK7: =Project_CF!BK13 -> 0
A8: Collections (Project_CF) | B8: =SUM(D8:BK8) -> 2252.979 | D8: =Project_CF!D8 -> 0 | E8: =Project_CF!E8 -> 0 | F8: =Project_CF!F8 -> 15.139238 | G8: =Project_CF!G8 -> 30.278475 | H8: =Project_CF!H8 -> 46.512006 | I8: =Project_CF!I8 -> 62.745537 | J8: =Project_CF!J8 -> 62.3657 | K8: =Project_CF!K8 -> 63.473559 | ... BK8: =Project_CF!BK8 -> 0
A9: S1 payouts: fixed multiple, equal instalments | B9: =SUM(D9:BK9) -> 230 | D9: =D6*(Inputs!$B$9*Inputs!$B$7/Inputs!$B$11) -> 0 | E9: =E6*(Inputs!$B$9*Inputs!$B$7/Inputs!$B$11) -> 0 | F9: =F6*(Inputs!$B$9*Inputs!$B$7/Inputs!$B$11) -> 0 | G9: =G6*(Inputs!$B$9*Inputs!$B$7/Inputs!$B$11) -> 0 | H9: =H6*(Inputs!$B$9*Inputs!$B$7/Inputs!$B$11) -> 0 | I9: =I6*(Inputs!$B$9*Inputs!$B$7/Inputs!$B$11) -> 0 | J9: =J6*(Inputs!$B$9*Inputs!$B$7/Inputs!$B$11) -> 0 | K9: =K6*(Inputs!$B$9*Inputs!$B$7/Inputs!$B$11) -> 0 | ... BK9: =BK6*(Inputs!$B$9*Inputs!$B$7/Inputs!$B$11) -> 0
A10: S2 payouts: share of collections with floor and cap | B10: =SUM(D10:BK10) -> 230 | D10: =IF(Source_Data!D$6>=Inputs!$B$54,MAX(0,MIN(MAX(MIN(Inputs!$B$37*D8,Inputs!$B$39*(Inputs!$B$9*Inputs!$B$7/Inputs!$B$11)),Inputs!$B$38*(Inputs!$B$9*Inputs!$B$7/Inputs!$B$11)),Inputs!$B$9*Inputs!$B$7-0)),0) -> 0 | E10: =IF(Source_Data!E$6>=Inputs!$B$54,MAX(0,MIN(MAX(MIN(Inputs!$B$37*E8,Inputs!$B$39*(Inputs!$B$9*Inputs!$B$7/Inputs!$B$11)),Inputs!$B$38*(Inputs!$B$9*Inputs!$B$7/Inputs!$B$11)),Inputs!$B$9*Inputs!$B$7-SUM($D$10:D10))),0) -> 0 | F10: =IF(Source_Data!F$6>=Inputs!$B$54,MAX(0,MIN(MAX(MIN(Inputs!$B$37*F8,Inputs!$B$39*(Inputs!$B$9*Inputs!$B$7/Inputs!$B$11)),Inputs!$B$38*(Inputs!$B$9*Inputs!$B$7/Inputs!$B$11)),Inputs!$B$9*Inputs!$B$7-SUM($D$10:E10))),0) -> 0 | G10: =IF(Source_Data!G$6>=Inputs!$B$54,MAX(0,MIN(MAX(MIN(Inputs!$B$37*G8,Inputs!$B$39*(Inputs!$B$9*Inputs!$B$7/Inputs!$B$11)),Inputs!$B$38*(Inputs!$B$9*Inputs!$B$7/Inputs!$B$11)),Inputs!$B$9*Inputs!$B$7-SUM($D$10:F10))),0) -> 0 | H10: =IF(Source_Data!H$6>=Inputs!$B$54,MAX(0,MIN(MAX(MIN(Inputs!$B$37*H8,Inputs!$B$39*(Inputs!$B$9*Inputs!$B$7/Inputs!$B$11)),Inputs!$B$38*(Inputs!$B$9*Inputs!$B$7/Inputs!$B$11)),Inputs!$B$9*Inputs!$B$7-SUM($D$10:G10))),0) -> 0 | I10: =IF(Source_Data!I$6>=Inputs!$B$54,MAX(0,MIN(MAX(MIN(Inputs!$B$37*I8,Inputs!$B$39*(Inputs!$B$9*Inputs!$B$7/Inputs!$B$11)),Inputs!$B$38*(Inputs!$B$9*Inputs!$B$7/Inputs!$B$11)),Inputs!$B$9*Inputs!$B$7-SUM($D$10:H10))),0) -> 0 | J10: =IF(Source_Data!J$6>=Inputs!$B$54,MAX(0,MIN(MAX(MIN(Inputs!$B$37*J8,Inputs!$B$39*(Inputs!$B$9*Inputs!$B$7/Inputs!$B$11)),Inputs!$B$38*(Inputs!$B$9*Inputs!$B$7/Inputs!$B$11)),Inputs!$B$9*Inputs!$B$7-SUM($D$10:I10))),0) -> 0 | K10: =IF(Source_Data!K$6>=Inputs!$B$54,MAX(0,MIN(MAX(MIN(Inputs!$B$37*K8,Inputs!$B$39*(Inputs!$B$9*Inputs!$B$7/Inputs!$B$11)),Inputs!$B$38*(Inputs!$B$9*Inputs!$B$7/Inputs!$B$11)),Inputs!$B$9*Inputs!$B$7-SUM($D$10:J10))),0) -> 0 | L10: =IF(Source_Data!L$6>=Inputs!$B$54,MAX(0,MIN(MAX(MIN(Inputs!$B$37*L8,Inputs!$B$39*(Inputs!$B$9*Inputs!$B$7/Inputs!$B$11)),Inputs!$B$38*(Inputs!$B$9*Inputs!$B$7/Inputs!$B$11)),Inputs!$B$9*Inputs!$B$7-SUM($D$10:K10))),0) -> 0 | ... BK10: =IF(Source_Data!BK$6>=Inputs!$B$54,MAX(0,MIN(MAX(MIN(Inputs!$B$37*BK8,Inputs!$B$39*(Inputs!$B$9*Inputs!$B$7/Inputs!$B$11)),Inputs!$B$38*(Inputs!$B$9*Inputs!$B$7/Inputs!$B$11)),Inputs!$B$9*Inputs!$B$7-SUM($D$10:BJ10))),0) -> 0
A11: S3 fixed part | B11: =SUM(D11:BK11) -> 180 | D11: =D6*Inputs!$B$40*Inputs!$B$7/Inputs!$B$11 -> 0 | E11: =E6*Inputs!$B$40*Inputs!$B$7/Inputs!$B$11 -> 0 | F11: =F6*Inputs!$B$40*Inputs!$B$7/Inputs!$B$11 -> 0 | G11: =G6*Inputs!$B$40*Inputs!$B$7/Inputs!$B$11 -> 0 | H11: =H6*Inputs!$B$40*Inputs!$B$7/Inputs!$B$11 -> 0 | I11: =I6*Inputs!$B$40*Inputs!$B$7/Inputs!$B$11 -> 0 | J11: =J6*Inputs!$B$40*Inputs!$B$7/Inputs!$B$11 -> 0 | K11: =K6*Inputs!$B$40*Inputs!$B$7/Inputs!$B$11 -> 0 | ... BK11: =BK6*Inputs!$B$40*Inputs!$B$7/Inputs!$B$11 -> 0
A12: S3 collections share | B12: =SUM(D12:BK12) -> 50 | D12: =IF(D6=1,MAX(0,MIN(Inputs!$B$42*D8,Inputs!$B$41*Inputs!$B$7-Inputs!$B$40*Inputs!$B$7-0)),0) -> 0 | E12: =IF(E6=1,MAX(0,MIN(Inputs!$B$42*E8,Inputs!$B$41*Inputs!$B$7-Inputs!$B$40*Inputs!$B$7-SUM($D$12:D12))),0) -> 0 | F12: =IF(F6=1,MAX(0,MIN(Inputs!$B$42*F8,Inputs!$B$41*Inputs!$B$7-Inputs!$B$40*Inputs!$B$7-SUM($D$12:E12))),0) -> 0 | G12: =IF(G6=1,MAX(0,MIN(Inputs!$B$42*G8,Inputs!$B$41*Inputs!$B$7-Inputs!$B$40*Inputs!$B$7-SUM($D$12:F12))),0) -> 0 | H12: =IF(H6=1,MAX(0,MIN(Inputs!$B$42*H8,Inputs!$B$41*Inputs!$B$7-Inputs!$B$40*Inputs!$B$7-SUM($D$12:G12))),0) -> 0 | I12: =IF(I6=1,MAX(0,MIN(Inputs!$B$42*I8,Inputs!$B$41*Inputs!$B$7-Inputs!$B$40*Inputs!$B$7-SUM($D$12:H12))),0) -> 0 | J12: =IF(J6=1,MAX(0,MIN(Inputs!$B$42*J8,Inputs!$B$41*Inputs!$B$7-Inputs!$B$40*Inputs!$B$7-SUM($D$12:I12))),0) -> 0 | K12: =IF(K6=1,MAX(0,MIN(Inputs!$B$42*K8,Inputs!$B$41*Inputs!$B$7-Inputs!$B$40*Inputs!$B$7-SUM($D$12:J12))),0) -> 0 | L12: =IF(L6=1,MAX(0,MIN(Inputs!$B$42*L8,Inputs!$B$41*Inputs!$B$7-Inputs!$B$40*Inputs!$B$7-SUM($D$12:K12))),0) -> 0 | ... BK12: =IF(BK6=1,MAX(0,MIN(Inputs!$B$42*BK8,Inputs!$B$41*Inputs!$B$7-Inputs!$B$40*Inputs!$B$7-SUM($D$12:BJ12))),0) -> 0
A13: S3 payouts: hybrid | B13: =SUM(D13:BK13) -> 230 | D13: =D11+D12 -> 0 | E13: =E11+E12 -> 0 | F13: =F11+F12 -> 0 | G13: =G11+G12 -> 0 | H13: =H11+H12 -> 0 | I13: =I11+I12 -> 0 | J13: =J11+J12 -> 0 | K13: =K11+K12 -> 0 | ... BK13: =BK11+BK12 -> 0
A14: S1 investor cash flow | D14: =-IF(Source_Data!D$6=Inputs!$B$12,Inputs!$B$7,0)+D9 -> -100 | E14: =-IF(Source_Data!E$6=Inputs!$B$12,Inputs!$B$7,0)+E9 -> 0 | F14: =-IF(Source_Data!F$6=Inputs!$B$12,Inputs!$B$7,0)+F9 -> 0 | G14: =-IF(Source_Data!G$6=Inputs!$B$12,Inputs!$B$7,0)+G9 -> 0 | H14: =-IF(Source_Data!H$6=Inputs!$B$12,Inputs!$B$7,0)+H9 -> 0 | I14: =-IF(Source_Data!I$6=Inputs!$B$12,Inputs!$B$7,0)+I9 -> 0 | J14: =-IF(Source_Data!J$6=Inputs!$B$12,Inputs!$B$7,0)+J9 -> 0 | K14: =-IF(Source_Data!K$6=Inputs!$B$12,Inputs!$B$7,0)+K9 -> 0 | ... BK14: =-IF(Source_Data!BK$6=Inputs!$B$12,Inputs!$B$7,0)+BK9 -> 0
A15: S2 investor cash flow | D15: =-IF(Source_Data!D$6=Inputs!$B$12,Inputs!$B$7,0)+D10 -> -100 | E15: =-IF(Source_Data!E$6=Inputs!$B$12,Inputs!$B$7,0)+E10 -> 0 | F15: =-IF(Source_Data!F$6=Inputs!$B$12,Inputs!$B$7,0)+F10 -> 0 | G15: =-IF(Source_Data!G$6=Inputs!$B$12,Inputs!$B$7,0)+G10 -> 0 | H15: =-IF(Source_Data!H$6=Inputs!$B$12,Inputs!$B$7,0)+H10 -> 0 | I15: =-IF(Source_Data!I$6=Inputs!$B$12,Inputs!$B$7,0)+I10 -> 0 | J15: =-IF(Source_Data!J$6=Inputs!$B$12,Inputs!$B$7,0)+J10 -> 0 | K15: =-IF(Source_Data!K$6=Inputs!$B$12,Inputs!$B$7,0)+K10 -> 0 | ... BK15: =-IF(Source_Data!BK$6=Inputs!$B$12,Inputs!$B$7,0)+BK10 -> 0
A16: S3 investor cash flow | D16: =-IF(Source_Data!D$6=Inputs!$B$12,Inputs!$B$7,0)+D13 -> -100 | E16: =-IF(Source_Data!E$6=Inputs!$B$12,Inputs!$B$7,0)+E13 -> 0 | F16: =-IF(Source_Data!F$6=Inputs!$B$12,Inputs!$B$7,0)+F13 -> 0 | G16: =-IF(Source_Data!G$6=Inputs!$B$12,Inputs!$B$7,0)+G13 -> 0 | H16: =-IF(Source_Data!H$6=Inputs!$B$12,Inputs!$B$7,0)+H13 -> 0 | I16: =-IF(Source_Data!I$6=Inputs!$B$12,Inputs!$B$7,0)+I13 -> 0 | J16: =-IF(Source_Data!J$6=Inputs!$B$12,Inputs!$B$7,0)+J13 -> 0 | K16: =-IF(Source_Data!K$6=Inputs!$B$12,Inputs!$B$7,0)+K13 -> 0 | ... BK16: =-IF(Source_Data!BK$6=Inputs!$B$12,Inputs!$B$7,0)+BK13 -> 0
A17: S1 Jalour cash flow (ticket less payouts) | D17: =IF(Source_Data!D$6=Inputs!$B$12,Inputs!$B$7,0)-D9 -> 100 | E17: =IF(Source_Data!E$6=Inputs!$B$12,Inputs!$B$7,0)-E9 -> 0 | F17: =IF(Source_Data!F$6=Inputs!$B$12,Inputs!$B$7,0)-F9 -> 0 | G17: =IF(Source_Data!G$6=Inputs!$B$12,Inputs!$B$7,0)-G9 -> 0 | H17: =IF(Source_Data!H$6=Inputs!$B$12,Inputs!$B$7,0)-H9 -> 0 | I17: =IF(Source_Data!I$6=Inputs!$B$12,Inputs!$B$7,0)-I9 -> 0 | J17: =IF(Source_Data!J$6=Inputs!$B$12,Inputs!$B$7,0)-J9 -> 0 | K17: =IF(Source_Data!K$6=Inputs!$B$12,Inputs!$B$7,0)-K9 -> 0 | ... BK17: =IF(Source_Data!BK$6=Inputs!$B$12,Inputs!$B$7,0)-BK9 -> 0
A18: S2 Jalour cash flow | D18: =IF(Source_Data!D$6=Inputs!$B$12,Inputs!$B$7,0)-D10 -> 100 | E18: =IF(Source_Data!E$6=Inputs!$B$12,Inputs!$B$7,0)-E10 -> 0 | F18: =IF(Source_Data!F$6=Inputs!$B$12,Inputs!$B$7,0)-F10 -> 0 | G18: =IF(Source_Data!G$6=Inputs!$B$12,Inputs!$B$7,0)-G10 -> 0 | H18: =IF(Source_Data!H$6=Inputs!$B$12,Inputs!$B$7,0)-H10 -> 0 | I18: =IF(Source_Data!I$6=Inputs!$B$12,Inputs!$B$7,0)-I10 -> 0 | J18: =IF(Source_Data!J$6=Inputs!$B$12,Inputs!$B$7,0)-J10 -> 0 | K18: =IF(Source_Data!K$6=Inputs!$B$12,Inputs!$B$7,0)-K10 -> 0 | ... BK18: =IF(Source_Data!BK$6=Inputs!$B$12,Inputs!$B$7,0)-BK10 -> 0
A19: S3 Jalour cash flow | D19: =IF(Source_Data!D$6=Inputs!$B$12,Inputs!$B$7,0)-D13 -> 100 | E19: =IF(Source_Data!E$6=Inputs!$B$12,Inputs!$B$7,0)-E13 -> 0 | F19: =IF(Source_Data!F$6=Inputs!$B$12,Inputs!$B$7,0)-F13 -> 0 | G19: =IF(Source_Data!G$6=Inputs!$B$12,Inputs!$B$7,0)-G13 -> 0 | H19: =IF(Source_Data!H$6=Inputs!$B$12,Inputs!$B$7,0)-H13 -> 0 | I19: =IF(Source_Data!I$6=Inputs!$B$12,Inputs!$B$7,0)-I13 -> 0 | J19: =IF(Source_Data!J$6=Inputs!$B$12,Inputs!$B$7,0)-J13 -> 0 | K19: =IF(Source_Data!K$6=Inputs!$B$12,Inputs!$B$7,0)-K13 -> 0 | ... BK19: =IF(Source_Data!BK$6=Inputs!$B$12,Inputs!$B$7,0)-BK13 -> 0
A20: S1 pooled cash after ticket and payouts | D20: =0+IF(Source_Data!D$6=Inputs!$B$12,Inputs!$B$7,0)+D7-D9 -> 8.75 | E20: =D20+IF(Source_Data!E$6=Inputs!$B$12,Inputs!$B$7,0)+E7-E9 -> -2.5 | F20: =E20+IF(Source_Data!F$6=Inputs!$B$12,Inputs!$B$7,0)+F7-F9 -> 1.3892375 | G20: =F20+IF(Source_Data!G$6=Inputs!$B$12,Inputs!$B$7,0)+G7-G9 -> 20.417713 | H20: =G20+IF(Source_Data!H$6=Inputs!$B$12,Inputs!$B$7,0)+H7-H9 -> 21.429719 | I20: =H20+IF(Source_Data!I$6=Inputs!$B$12,Inputs!$B$7,0)+I7-I9 -> 31.315256 | J20: =I20+IF(Source_Data!J$6=Inputs!$B$12,Inputs!$B$7,0)+J7-J9 -> 13.069566 | K20: =J20+IF(Source_Data!K$6=Inputs!$B$12,Inputs!$B$7,0)+K7-K9 -> 11.571736 | L20: =K20+IF(Source_Data!L$6=Inputs!$B$12,Inputs!$B$7,0)+L7-L9 -> 18.269324 | ... BK20: =BJ20+IF(Source_Data!BK$6=Inputs!$B$12,Inputs!$B$7,0)+BK7-BK9 -> 245.44753
A21: S2 pooled cash | D21: =0+IF(Source_Data!D$6=Inputs!$B$12,Inputs!$B$7,0)+D7-D10 -> 8.75 | E21: =D21+IF(Source_Data!E$6=Inputs!$B$12,Inputs!$B$7,0)+E7-E10 -> -2.5 | F21: =E21+IF(Source_Data!F$6=Inputs!$B$12,Inputs!$B$7,0)+F7-F10 -> 1.3892375 | G21: =F21+IF(Source_Data!G$6=Inputs!$B$12,Inputs!$B$7,0)+G7-G10 -> 20.417713 | H21: =G21+IF(Source_Data!H$6=Inputs!$B$12,Inputs!$B$7,0)+H7-H10 -> 21.429719 | I21: =H21+IF(Source_Data!I$6=Inputs!$B$12,Inputs!$B$7,0)+I7-I10 -> 31.315256 | J21: =I21+IF(Source_Data!J$6=Inputs!$B$12,Inputs!$B$7,0)+J7-J10 -> 13.069566 | K21: =J21+IF(Source_Data!K$6=Inputs!$B$12,Inputs!$B$7,0)+K7-K10 -> 11.571736 | L21: =K21+IF(Source_Data!L$6=Inputs!$B$12,Inputs!$B$7,0)+L7-L10 -> 18.269324 | ... BK21: =BJ21+IF(Source_Data!BK$6=Inputs!$B$12,Inputs!$B$7,0)+BK7-BK10 -> 245.44753
A22: S3 pooled cash | D22: =0+IF(Source_Data!D$6=Inputs!$B$12,Inputs!$B$7,0)+D7-D13 -> 8.75 | E22: =D22+IF(Source_Data!E$6=Inputs!$B$12,Inputs!$B$7,0)+E7-E13 -> -2.5 | F22: =E22+IF(Source_Data!F$6=Inputs!$B$12,Inputs!$B$7,0)+F7-F13 -> 1.3892375 | G22: =F22+IF(Source_Data!G$6=Inputs!$B$12,Inputs!$B$7,0)+G7-G13 -> 20.417713 | H22: =G22+IF(Source_Data!H$6=Inputs!$B$12,Inputs!$B$7,0)+H7-H13 -> 21.429719 | I22: =H22+IF(Source_Data!I$6=Inputs!$B$12,Inputs!$B$7,0)+I7-I13 -> 31.315256 | J22: =I22+IF(Source_Data!J$6=Inputs!$B$12,Inputs!$B$7,0)+J7-J13 -> 13.069566 | K22: =J22+IF(Source_Data!K$6=Inputs!$B$12,Inputs!$B$7,0)+K7-K13 -> 11.571736 | L22: =K22+IF(Source_Data!L$6=Inputs!$B$12,Inputs!$B$7,0)+L7-L13 -> 18.269324 | ... BK22: =BJ22+IF(Source_Data!BK$6=Inputs!$B$12,Inputs!$B$7,0)+BK7-BK13 -> 245.44753
A23: S1 coverage: net cash flow / payout | D23: =IF(D9>0,D7/D9,"") | E23: =IF(E9>0,E7/E9,"") | F23: =IF(F9>0,F7/F9,"") | G23: =IF(G9>0,G7/G9,"") | H23: =IF(H9>0,H7/H9,"") | I23: =IF(I9>0,I7/I9,"") | J23: =IF(J9>0,J7/J9,"") | K23: =IF(K9>0,K7/K9,"") | ... BK23: =IF(BK9>0,BK7/BK9,"")
A24: S1 coverage: cash available / payout | D24: =IF(D9>0,(0+IF(Source_Data!D$6=Inputs!$B$12,Inputs!$B$7,0)+D7)/D9,"") | E24: =IF(E9>0,(D20+IF(Source_Data!E$6=Inputs!$B$12,Inputs!$B$7,0)+E7)/E9,"") | F24: =IF(F9>0,(E20+IF(Source_Data!F$6=Inputs!$B$12,Inputs!$B$7,0)+F7)/F9,"") | G24: =IF(G9>0,(F20+IF(Source_Data!G$6=Inputs!$B$12,Inputs!$B$7,0)+G7)/G9,"") | H24: =IF(H9>0,(G20+IF(Source_Data!H$6=Inputs!$B$12,Inputs!$B$7,0)+H7)/H9,"") | I24: =IF(I9>0,(H20+IF(Source_Data!I$6=Inputs!$B$12,Inputs!$B$7,0)+I7)/I9,"") | J24: =IF(J9>0,(I20+IF(Source_Data!J$6=Inputs!$B$12,Inputs!$B$7,0)+J7)/J9,"") | K24: =IF(K9>0,(J20+IF(Source_Data!K$6=Inputs!$B$12,Inputs!$B$7,0)+K7)/K9,"") | L24: =IF(L9>0,(K20+IF(Source_Data!L$6=Inputs!$B$12,Inputs!$B$7,0)+L7)/L9,"") | ... BK24: =IF(BK9>0,(BJ20+IF(Source_Data!BK$6=Inputs!$B$12,Inputs!$B$7,0)+BK7)/BK9,"")
A25: S2 coverage: net cash flow / payout | D25: =IF(D10>0,D7/D10,"") | E25: =IF(E10>0,E7/E10,"") | F25: =IF(F10>0,F7/F10,"") | G25: =IF(G10>0,G7/G10,"") | H25: =IF(H10>0,H7/H10,"") | I25: =IF(I10>0,I7/I10,"") | J25: =IF(J10>0,J7/J10,"") | K25: =IF(K10>0,K7/K10,"") | ... BK25: =IF(BK10>0,BK7/BK10,"")
A26: S2 coverage: cash available / payout | D26: =IF(D10>0,(0+IF(Source_Data!D$6=Inputs!$B$12,Inputs!$B$7,0)+D7)/D10,"") | E26: =IF(E10>0,(D21+IF(Source_Data!E$6=Inputs!$B$12,Inputs!$B$7,0)+E7)/E10,"") | F26: =IF(F10>0,(E21+IF(Source_Data!F$6=Inputs!$B$12,Inputs!$B$7,0)+F7)/F10,"") | G26: =IF(G10>0,(F21+IF(Source_Data!G$6=Inputs!$B$12,Inputs!$B$7,0)+G7)/G10,"") | H26: =IF(H10>0,(G21+IF(Source_Data!H$6=Inputs!$B$12,Inputs!$B$7,0)+H7)/H10,"") | I26: =IF(I10>0,(H21+IF(Source_Data!I$6=Inputs!$B$12,Inputs!$B$7,0)+I7)/I10,"") | J26: =IF(J10>0,(I21+IF(Source_Data!J$6=Inputs!$B$12,Inputs!$B$7,0)+J7)/J10,"") | K26: =IF(K10>0,(J21+IF(Source_Data!K$6=Inputs!$B$12,Inputs!$B$7,0)+K7)/K10,"") | L26: =IF(L10>0,(K21+IF(Source_Data!L$6=Inputs!$B$12,Inputs!$B$7,0)+L7)/L10,"") | ... BK26: =IF(BK10>0,(BJ21+IF(Source_Data!BK$6=Inputs!$B$12,Inputs!$B$7,0)+BK7)/BK10,"")
A27: S3 coverage: net cash flow / payout | D27: =IF(D13>0,D7/D13,"") | E27: =IF(E13>0,E7/E13,"") | F27: =IF(F13>0,F7/F13,"") | G27: =IF(G13>0,G7/G13,"") | H27: =IF(H13>0,H7/H13,"") | I27: =IF(I13>0,I7/I13,"") | J27: =IF(J13>0,J7/J13,"") | K27: =IF(K13>0,K7/K13,"") | ... BK27: =IF(BK13>0,BK7/BK13,"")
A28: S3 coverage: cash available / payout | D28: =IF(D13>0,(0+IF(Source_Data!D$6=Inputs!$B$12,Inputs!$B$7,0)+D7)/D13,"") | E28: =IF(E13>0,(D22+IF(Source_Data!E$6=Inputs!$B$12,Inputs!$B$7,0)+E7)/E13,"") | F28: =IF(F13>0,(E22+IF(Source_Data!F$6=Inputs!$B$12,Inputs!$B$7,0)+F7)/F13,"") | G28: =IF(G13>0,(F22+IF(Source_Data!G$6=Inputs!$B$12,Inputs!$B$7,0)+G7)/G13,"") | H28: =IF(H13>0,(G22+IF(Source_Data!H$6=Inputs!$B$12,Inputs!$B$7,0)+H7)/H13,"") | I28: =IF(I13>0,(H22+IF(Source_Data!I$6=Inputs!$B$12,Inputs!$B$7,0)+I7)/I13,"") | J28: =IF(J13>0,(I22+IF(Source_Data!J$6=Inputs!$B$12,Inputs!$B$7,0)+J7)/J13,"") | K28: =IF(K13>0,(J22+IF(Source_Data!K$6=Inputs!$B$12,Inputs!$B$7,0)+K7)/K13,"") | L28: =IF(L13>0,(K22+IF(Source_Data!L$6=Inputs!$B$12,Inputs!$B$7,0)+L7)/L13,"") | ... BK28: =IF(BK13>0,(BJ22+IF(Source_Data!BK$6=Inputs!$B$12,Inputs!$B$7,0)+BK7)/BK13,"")
A31: Structure comparison (base case) | B31: S1 Fixed multiple | C31: S2 % of collections | D31: S3 Hybrid
A32: Total paid (EGP m) | B32: =SUM(D9:BK9) -> 230 | C32: =SUM(D10:BK10) -> 230 | D32: =SUM(D13:BK13) -> 230
A33: Total multiple | B33: =B32/Inputs!$B$7 -> 2.3 | C33: =C32/Inputs!$B$7 -> 2.3 | D33: =D32/Inputs!$B$7 -> 2.3
A34: Investor IRR | B34: =(1+IRR(D14:BK14,0.05))^4-1 -> 0.26546399 | C34: =(1+IRR(D15:BK15,0.05))^4-1 -> 0.29027663 | D34: =(1+IRR(D16:BK16,0.05))^4-1 -> 0.27835276
A35: Jalour cost of capital | B35: =(1+IRR(D17:BK17,0.05))^4-1 -> 0.26546399 | C35: =(1+IRR(D18:BK18,0.05))^4-1 -> 0.29027663 | D35: =(1+IRR(D19:BK19,0.05))^4-1 -> 0.27835276
A36: NPV to Jalour @ discount rate | B36: =SUMPRODUCT(D17:BK17,Project_CF!$D$15:$BK$15) -> -42.536579 | C36: =SUMPRODUCT(D18:BK18,Project_CF!$D$15:$BK$15) -> -47.47675 | D36: =SUMPRODUCT(D19:BK19,Project_CF!$D$15:$BK$15) -> -45.110927
A37: Lowest quarterly coverage: net cash flow / payout | B37: =MIN(D23:BK23) -> -8.9504782 | C37: =MIN(D25:BK25) -> -9.7298793 | D37: =MIN(D27:BK27) -> -9.8151482
A38: Quarters below threshold (net cash flow basis) | B38: =COUNTIF(D23:BK23,"<"&Inputs!$B$43) -> 9 | C38: =COUNTIF(D25:BK25,"<"&Inputs!$B$43) -> 8 | D38: =COUNTIF(D27:BK27,"<"&Inputs!$B$43) -> 8
A39: Payout quarters | B39: =COUNTIF(D9:BK9,">0") -> 12 | C39: =COUNTIF(D10:BK10,">0") -> 13 | D39: =COUNTIF(D13:BK13,">0") -> 12
A40: Lowest coverage: cash available / payout | B40: =MIN(D24:BK24) -> 2.9584222 | C40: =MIN(D26:BK26) -> 3.4924755 | D40: =MIN(D28:BK28) -> 3.0989222
A41: Quarters below threshold (cash available basis) | B41: =COUNTIF(D24:BK24,"<"&Inputs!$B$43) -> 0 | C41: =COUNTIF(D26:BK26,"<"&Inputs!$B$43) -> 0 | D41: =COUNTIF(D28:BK28,"<"&Inputs!$B$43) -> 0
A42: Lowest pooled cash after ticket and payouts | B42: =MIN(D20:BK20) -> -2.5 | C42: =MIN(D21:BK21) -> -2.5 | D42: =MIN(D22:BK22) -> -2.5
A43: Last payout month | B43: =SUMPRODUCT(MAX((D9:BK9>0)*D5:BK5)) -> 63 | C43: =SUMPRODUCT(MAX((D10:BK10>0)*D5:BK5)) -> 66 | D43: =SUMPRODUCT(MAX((D13:BK13>0)*D5:BK5)) -> 63
...

Sheet Scenarios
A1: Green Square: scenario analysis (live blocks; edit the blue parameters)
A2: Each block recalculates the project, Option A (investor resale at the scenario price and delay) and Option B (fixed payouts) from Source_Data.
A4: Base case
A5: Price factor | B5: 1
A6: Sales delay (quarters) | B6: 0
A7: Cost factor | B7: 1
A8: Collections slip (quarters) | B8: 0
A9: Delivery payments at handover (1 = yes) | B9: 0
A10: Resale start month (Option A) | B10: =Inputs!$B$13+3+3*$B$6 -> 51
A11: Collections before delay and price | D11: =Source_Data!D$7+IF($B$9=1,IF(Source_Data!D$6=Inputs!$B$13,Source_Data!$C$8,0),Source_Data!D$8) -> 0 | E11: =Source_Data!E$7+IF($B$9=1,IF(Source_Data!E$6=Inputs!$B$13,Source_Data!$C$8,0),Source_Data!E$8) -> 0 | F11: =Source_Data!F$7+IF($B$9=1,IF(Source_Data!F$6=Inputs!$B$13,Source_Data!$C$8,0),Source_Data!F$8) -> 15.139238 | G11: =Source_Data!G$7+IF($B$9=1,IF(Source_Data!G$6=Inputs!$B$13,Source_Data!$C$8,0),Source_Data!G$8) -> 30.278475 | H11: =Source_Data!H$7+IF($B$9=1,IF(Source_Data!H$6=Inputs!$B$13,Source_Data!$C$8,0),Source_Data!H$8) -> 46.512006 | I11: =Source_Data!I$7+IF($B$9=1,IF(Source_Data!I$6=Inputs!$B$13,Source_Data!$C$8,0),Source_Data!I$8) -> 62.745537 | J11: =Source_Data!J$7+IF($B$9=1,IF(Source_Data!J$6=Inputs!$B$13,Source_Data!$C$8,0),Source_Data!J$8) -> 62.3657 | K11: =Source_Data!K$7+IF($B$9=1,IF(Source_Data!K$6=Inputs!$B$13,Source_Data!$C$8,0),Source_Data!K$8) -> 63.473559 | ... BK11: =Source_Data!BK$7+IF($B$9=1,IF(Source_Data!BK$6=Inputs!$B$13,Source_Data!$C$8,0),Source_Data!BK$8) -> 0
A12: Collections | D12: =$B$5*IF(Source_Data!D$5-($B$6+$B$8)>=1,INDEX($D$11:$BK$11,1,Source_Data!D$5-($B$6+$B$8)),0) -> 0 | E12: =$B$5*IF(Source_Data!E$5-($B$6+$B$8)>=1,INDEX($D$11:$BK$11,1,Source_Data!E$5-($B$6+$B$8)),0) -> 0 | F12: =$B$5*IF(Source_Data!F$5-($B$6+$B$8)>=1,INDEX($D$11:$BK$11,1,Source_Data!F$5-($B$6+$B$8)),0) -> 15.139238 | G12: =$B$5*IF(Source_Data!G$5-($B$6+$B$8)>=1,INDEX($D$11:$BK$11,1,Source_Data!G$5-($B$6+$B$8)),0) -> 30.278475 | H12: =$B$5*IF(Source_Data!H$5-($B$6+$B$8)>=1,INDEX($D$11:$BK$11,1,Source_Data!H$5-($B$6+$B$8)),0) -> 46.512006 | I12: =$B$5*IF(Source_Data!I$5-($B$6+$B$8)>=1,INDEX($D$11:$BK$11,1,Source_Data!I$5-($B$6+$B$8)),0) -> 62.745537 | J12: =$B$5*IF(Source_Data!J$5-($B$6+$B$8)>=1,INDEX($D$11:$BK$11,1,Source_Data!J$5-($B$6+$B$8)),0) -> 62.3657 | K12: =$B$5*IF(Source_Data!K$5-($B$6+$B$8)>=1,INDEX($D$11:$BK$11,1,Source_Data!K$5-($B$6+$B$8)),0) -> 63.473559 | ... BK12: =$B$5*IF(Source_Data!BK$5-($B$6+$B$8)>=1,INDEX($D$11:$BK$11,1,Source_Data!BK$5-($B$6+$B$8)),0) -> 0
A13: Landlord payments | D13: =Source_Data!D$9+Source_Data!D$10*IF(Source_Data!$C$10=0,0,MAX(0,Inputs!$B$19*Inputs!$B$22*$B$5-Inputs!$B$20)/Source_Data!$C$10) -> 91.25 | E13: =Source_Data!E$9+Source_Data!E$10*IF(Source_Data!$C$10=0,0,MAX(0,Inputs!$B$19*Inputs!$B$22*$B$5-Inputs!$B$20)/Source_Data!$C$10) -> 11.25 | F13: =Source_Data!F$9+Source_Data!F$10*IF(Source_Data!$C$10=0,0,MAX(0,Inputs!$B$19*Inputs!$B$22*$B$5-Inputs!$B$20)/Source_Data!$C$10) -> 11.25 | G13: =Source_Data!G$9+Source_Data!G$10*IF(Source_Data!$C$10=0,0,MAX(0,Inputs!$B$19*Inputs!$B$22*$B$5-Inputs!$B$20)/Source_Data!$C$10) -> 11.25 | H13: =Source_Data!H$9+Source_Data!H$10*IF(Source_Data!$C$10=0,0,MAX(0,Inputs!$B$19*Inputs!$B$22*$B$5-Inputs!$B$20)/Source_Data!$C$10) -> 22.5 | I13: =Source_Data!I$9+Source_Data!I$10*IF(Source_Data!$C$10=0,0,MAX(0,Inputs!$B$19*Inputs!$B$22*$B$5-Inputs!$B$20)/Source_Data!$C$10) -> 22.5 | J13: =Source_Data!J$9+Source_Data!J$10*IF(Source_Data!$C$10=0,0,MAX(0,Inputs!$B$19*Inputs!$B$22*$B$5-Inputs!$B$20)/Source_Data!$C$10) -> 22.5 | K13: =Source_Data!K$9+Source_Data!K$10*IF(Source_Data!$C$10=0,0,MAX(0,Inputs!$B$19*Inputs!$B$22*$B$5-Inputs!$B$20)/Source_Data!$C$10) -> 22.5 | ... BK13: =Source_Data!BK$9+Source_Data!BK$10*IF(Source_Data!$C$10=0,0,MAX(0,Inputs!$B$19*Inputs!$B$22*$B$5-Inputs!$B$20)/Source_Data!$C$10) -> 0
A14: Construction cost | D14: =Source_Data!D$11*$B$7 -> 0 | E14: =Source_Data!E$11*$B$7 -> 0 | F14: =Source_Data!F$11*$B$7 -> 0 | G14: =Source_Data!G$11*$B$7 -> 0 | H14: =Source_Data!H$11*$B$7 -> 20 | I14: =Source_Data!I$11*$B$7 -> 26.4 | J14: =Source_Data!J$11*$B$7 -> 40 | K14: =Source_Data!K$11*$B$7 -> 26.4 | ... BK14: =Source_Data!BK$11*$B$7 -> 0
A15: Sales commission | D15: =$B$5*IF(Source_Data!D$5-$B$6>=1,INDEX(Source_Data!$D$12:$BK$12,1,Source_Data!D$5-$B$6),0) -> 0 | E15: =$B$5*IF(Source_Data!E$5-$B$6>=1,INDEX(Source_Data!$D$12:$BK$12,1,Source_Data!E$5-$B$6),0) -> 0 | F15: =$B$5*IF(Source_Data!F$5-$B$6>=1,INDEX(Source_Data!$D$12:$BK$12,1,Source_Data!F$5-$B$6),0) -> 0 | G15: =$B$5*IF(Source_Data!G$5-$B$6>=1,INDEX(Source_Data!$D$12:$BK$12,1,Source_Data!G$5-$B$6),0) -> 0 | H15: =$B$5*IF(Source_Data!H$5-$B$6>=1,INDEX(Source_Data!$D$12:$BK$12,1,Source_Data!H$5-$B$6),0) -> 0 | I15: =$B$5*IF(Source_Data!I$5-$B$6>=1,INDEX(Source_Data!$D$12:$BK$12,1,Source_Data!I$5-$B$6),0) -> 0 | J15: =$B$5*IF(Source_Data!J$5-$B$6>=1,INDEX(Source_Data!$D$12:$BK$12,1,Source_Data!J$5-$B$6),0) -> 12.11139 | K15: =$B$5*IF(Source_Data!K$5-$B$6>=1,INDEX(Source_Data!$D$12:$BK$12,1,Source_Data!K$5-$B$6),0) -> 12.11139 | ... BK15: =$B$5*IF(Source_Data!BK$5-$B$6>=1,INDEX(Source_Data!$D$12:$BK$12,1,Source_Data!BK$5-$B$6),0) -> 0
A16: SG&A and others | D16: =Source_Data!D$13*$B$7 -> 0 | E16: =Source_Data!E$13*$B$7 -> 0 | F16: =Source_Data!F$13*$B$7 -> 0 | G16: =Source_Data!G$13*$B$7 -> 0 | H16: =Source_Data!H$13*$B$7 -> 3 | I16: =Source_Data!I$13*$B$7 -> 3.96 | J16: =Source_Data!J$13*$B$7 -> 6 | K16: =Source_Data!K$13*$B$7 -> 3.96 | ... BK16: =Source_Data!BK$13*$B$7 -> 0
A17: Net cash flow | D17: =D12-D13-D14-D15-D16 -> -91.25 | E17: =E12-E13-E14-E15-E16 -> -11.25 | F17: =F12-F13-F14-F15-F16 -> 3.8892375 | G17: =G12-G13-G14-G15-G16 -> 19.028475 | H17: =H12-H13-H14-H15-H16 -> 1.0120062 | I17: =I12-I13-I14-I15-I16 -> 9.8855375 | J17: =J12-J13-J14-J15-J16 -> -18.24569 | K17: =K12-K13-K14-K15-K16 -> -1.4978306 | ... BK17: =BK12-BK13-BK14-BK15-BK16 -> 0
A18: Cumulative net cash flow | D18: =D17 -> -91.25 | E18: =D18+E17 -> -102.5 | F18: =E18+F17 -> -98.610763 | G18: =F18+G17 -> -79.582288 | H18: =G18+H17 -> -78.570281 | I18: =H18+I17 -> -68.684744 | J18: =I18+J17 -> -86.930434 | K18: =J18+K17 -> -88.428264 | L18: =K18+L17 -> -81.730676 | ... BK18: =BJ18+BK17 -> 375.44753
